Workbook

Sheet 月別詳細
A1: No. | B1: 商品符号 | C1: ブランド | D1: 商品名称 | E1: 2601 | G1: 2602 | I1: 2603 | K1: 2604 | M1: 2605 | O1: 2606 | Q1: 2607 | S1: 2608 | U1: 2609 | W1: 2610 | Y1: 2611 | AA1: 2612 | AC1: 合計
E2: 数量 | F2: 金額 | G2: 数量 | H2: 金額 | I2: 数量 | J2: 金額 | K2: 数量 | L2: 金額 | M2: 数量 | N2: 金額 | O2: 数量 | P2: 金額 | Q2: 数量 | R2: 金額 | S2: 数量 | T2: 金額 | U2: 数量 | V2: 金額 | W2: 数量 | X2: 金額 | Y2: 数量 | Z2: 金額 | AA2: 数量 | AB2: 金額 | AC2: 数量 | AD2: 金額
A3: 42 | B3: =LEFT(D3,FIND("-",D3)-1) -> MTNN | C3: 雪肌精 | D3: MTNN-ｾｯｷｾｲBR UVﾆｭｳｴｷ | I3: 270 | J3: 432000 | K3: 434 | L3: 694400 | M3: 336 | N3: 537600 | AC3: =E3+G3+I3+K3+M3+O3+Q3+S3+U3+W3+Y3+AA3 -> 1040 | AD3: =F3+H3+J3+L3+N3+P3+R3+T3+V3+X3+Z3+AB3 -> 1664000
A4: 23 | B4: =LEFT(D4,FIND("-",D4)-1) -> MTOE001 | C4: 雪肌精 | D4: MTOE001-ｾｯｷｾｲBBｴｯｾﾝｽ #001 | G4: 461 | H4: 599300 | I4: 30 | J4: 39000 | K4: 1331 | L4: 1730300 | M4: 300 | N4: 390000 | AC4: =E4+G4+I4+K4+M4+O4+Q4+S4+U4+W4+Y4+AA4 -> 2122 | AD4: =F4+H4+J4+L4+N4+P4+R4+T4+V4+X4+Z4+AB4 -> 2758600
A5: 21 | B5: =LEFT(D5,FIND("-",D5)-1) -> MTLD | C5: 雪肌精 | D5: MTLD-SKｽｷﾝｹｱUVｼﾞｪﾙN | E5: 100 | F5: 105000 | G5: 384 | H5: 403200 | I5: 30 | J5: 31500 | K5: 1199 | L5: 1258950 | M5: 200 | N5: 210000 | AC5: =E5+G5+I5+K5+M5+O5+Q5+S5+U5+W5+Y5+AA5 -> 1913 | AD5: =F5+H5+J5+L5+N5+P5+R5+T5+V5+X5+Z5+AB5 -> 2008650
A6: 37 | B6: =LEFT(D6,FIND("-",D6)-1) -> MTLI | C6: 雪肌精 | D6: MTLI-SKｽｷﾝｹｱUVｼﾞｪﾙNA | I6: 300 | J6: 330000 | K6: 530 | L6: 583000 | M6: 200 | N6: 220000 | AC6: =E6+G6+I6+K6+M6+O6+Q6+S6+U6+W6+Y6+AA6 -> 1030 | AD6: =F6+H6+J6+L6+N6+P6+R6+T6+V6+X6+Z6+AB6 -> 1133000
A7: 18 | B7: =LEFT(D7,FIND("-",D7)-1) -> MTLJ | C7: 雪肌精 | D7: MTLJ-SKｽｷﾝｹｱUVﾐﾙｸNA | I7: 645 | J7: 806250 | K7: 1050 | L7: 1312500 | M7: 100 | N7: 125000 | AC7: =E7+G7+I7+K7+M7+O7+Q7+S7+U7+W7+Y7+AA7 -> 1795 | AD7: =F7+H7+J7+L7+N7+P7+R7+T7+V7+X7+Z7+AB7 -> 2243750
A8: 142 | B8: =LEFT(D8,FIND("-",D8)-1) -> MTSC | C8: 雪肌精 | D8: MTSC-ｾｯｷｾｲ ｹｼｮｳｽｲN | E8: 30 | F8: 57000 | G8: 40 | H8: 76000 | K8: 51 | L8: 96900 | M8: 70 | N8: 133000 | AC8: =E8+G8+I8+K8+M8+O8+Q8+S8+U8+W8+Y8+AA8 -> 191 | AD8: =F8+H8+J8+L8+N8+P8+R8+T8+V8+X8+Z8+AB8 -> 362900
A9: 124 | B9: =LEFT(D9,FIND("-",D9)-1) -> MTSE | C9: 雪肌精 | D9: MTSE-ｾｯｷｾｲ ｹｼｮｳｽｲBIG | I9: 82 | J9: 237800 | K9: 112 | L9: 324800 | M9: 30 | N9: 87000 | AC9: =E9+G9+I9+K9+M9+O9+Q9+S9+U9+W9+Y9+AA9 -> 224 | AD9: =F9+H9+J9+L9+N9+P9+R9+T9+V9+X9+Z9+AB9 -> 649600
A10: 289 | B10: =LEFT(D10,FIND("-",D10)-1) -> MTSU | C10: 雪肌精 | D10: MTSU-ｾｯｷｾｲ ｸﾘｰﾑ N | I10: 11 | J10: 23650 | K10: 52 | L10: 111800 | M10: 9 | N10: 19350 | AC10: =E10+G10+I10+K10+M10+O10+Q10+S10+U10+W10+Y10+AA10 -> 72 | AD10: =F10+H10+J10+L10+N10+P10+R10+T10+V10+X10+Z10+AB10 -> 154800
A11: 202 | B11: =LEFT(D11,FIND("-",D11)-1) -> MEWZ | C11: 雪肌精 | D11: MEWZ-SK ｹｼｮｳｽｲｼﾀﾃｾｯｹﾝ | E11: 8 | F11: 8000 | G11: 8 | H11: 8000 | I11: 12 | J11: 12000 | K11: 6 | L11: 6000 | M11: 4 | N11: 4000 | AC11: =E11+G11+I11+K11+M11+O11+Q11+S11+U11+W11+Y11+AA11 -> 38 | AD11: =F11+H11+J11+L11+N11+P11+R11+T11+V11+X11+Z11+AB11 -> 38000
A12: 109 | B12: =LEFT(D12,FIND("-",D12)-1) -> MTAA | C12: 雪肌精 | D12: MTAA-ｾｯｷｾｲﾊｰﾊﾞﾙｼﾞｪﾙ | G12: 99 | H12: 188100 | M12: 3 | N12: 5700 | AC12: =E12+G12+I12+K12+M12+O12+Q12+S12+U12+W12+Y12+AA12 -> 102 | AD12: =F12+H12+J12+L12+N12+P12+R12+T12+V12+X12+Z12+AB12 -> 193800
A13: 17 | B13: =LEFT(D13,FIND("-",D13)-1) -> MTSW | C13: 雪肌精 | D13: MTSW-ｾｯｷｾｲ ｹｼｮｳｽｲN R | E13: 104 | F13: 254800 | G13: 112 | H13: 274400 | I13: 432 | J13: 1058400 | K13: 147 | L13: 360150 | M13: 2 | N13: 4900 | AC13: =E13+G13+I13+K13+M13+O13+Q13+S13+U13+W13+Y13+AA13 -> 797 | AD13: =F13+H13+J13+L13+N13+P13+R13+T13+V13+X13+Z13+AB13 -> 1952650
A14: 395 | B14: =LEFT(D14,FIND("-",D14)-1) -> MWBI405 | C14: 雪肌精 | D14: MWBI405-SKM ﾓﾃﾞﾘﾝｸﾞLFD #405 | E14: 3 | F14: 8250 | K14: 1 | L14: 2750 | M14: -1 | N14: -2750 | AC14: =E14+G14+I14+K14+M14+O14+Q14+S14+U14+W14+Y14+AA14 -> 3 | AD14: =F14+H14+J14+L14+N14+P14+R14+T14+V14+X14+Z14+AB14 -> 8250
A15: 247 | B15: =LEFT(D15,FIND("-",D15)-1) -> MWMY | C15: 雪肌精 | D15: MWMY-SKMｻｲｸﾚｲﾀｰB | E15: 2 | F15: 6600 | G15: 15 | H15: 49500 | K15: 32 | L15: 105600 | M15: -32 | N15: -105600 | AC15: =E15+G15+I15+K15+M15+O15+Q15+S15+U15+W15+Y15+AA15 -> 17 | AD15: =F15+H15+J15+L15+N15+P15+R15+T15+V15+X15+Z15+AB15 -> 56100
A16: 16 | B16: =LEFT(D16,FIND("-",D16)-1) -> MTLE | C16: 雪肌精 | D16: MTLE-SKｽｷﾝｹｱUVﾐﾙｸN | E16: 230 | F16: 276000 | G16: 445 | H16: 534000 | K16: 1096 | L16: 1315200 | AC16: =E16+G16+I16+K16+M16+O16+Q16+S16+U16+W16+Y16+AA16 -> 1771 | AD16: =F16+H16+J16+L16+N16+P16+R16+T16+V16+X16+Z16+AB16 -> 2125200
A17: 68 | B17: =LEFT(D17,FIND("-",D17)-1) -> MTOE002 | C17: 雪肌精 | D17: MTOE002-ｾｯｷｾｲBBｴｯｾﾝｽ #002 | G17: 110 | H17: 143000 | I17: 55 | J17: 71500 | K17: 910 | L17: 1183000 | AC17: =E17+G17+I17+K17+M17+O17+Q17+S17+U17+W17+Y17+AA17 -> 1075 | AD17: =F17+H17+J17+L17+N17+P17+R17+T17+V17+X17+Z17+AB17 -> 1397500
A18: 25 | B18: =LEFT(D18,FIND("-",D18)-1) -> MTCP | C18: 雪肌精 | D18: MTCP-SKCWｼﾞｪﾝﾄﾙｳｫｯｼｭR | E18: 150 | F18: 116250 | G18: 310 | H18: 240250 | K18: 291 | L18: 225525 | AC18: =E18+G18+I18+K18+M18+O18+Q18+S18+U18+W18+Y18+AA18 -> 751 | AD18: =F18+H18+J18+L18+N18+P18+R18+T18+V18+X18+Z18+AB18 -> 582025
A19: 29 | B19: =LEFT(D19,FIND("-",D19)-1) -> MECB002 | C19: 雪肌精 | D19: MECB002-SK ﾎﾜｲﾄBB #002 | E19: 270 | F19: 351000 | G19: 50 | H19: 65000 | I19: 40 | J19: 52000 | K19: 268 | L19: 348400 | AC19: =E19+G19+I19+K19+M19+O19+Q19+S19+U19+W19+Y19+AA19 -> 628 | AD19: =F19+H19+J19+L19+N19+P19+R19+T19+V19+X19+Z19+AB19 -> 816400
A20: 131 | B20: =LEFT(D20,FIND("-",D20)-1) -> MTYO | C20: 雪肌精 | D20: MTYO-SKCWﾋﾟｭｱｺﾝｸSR | E20: 70 | F20: 94500 | I20: 10 | J20: 13500 | K20: 220 | L20: 297000 | AC20: =E20+G20+I20+K20+M20+O20+Q20+S20+U20+W20+Y20+AA20 -> 300 | AD20: =F20+H20+J20+L20+N20+P20+R20+T20+V20+X20+Z20+AB20 -> 405000
A21: 51 | B21: =LEFT(D21,FIND("-",D21)-1) -> MTEI | C21: 雪肌精 | D21: MTEI-SKCWﾅﾁｭﾗﾙﾄﾞﾘｯﾌﾟR | E21: 10 | F21: 14000 | G21: 186 | H21: 260400 | I21: 30 | J21: 42000 | K21: 200 | L21: 280000 | AC21: =E21+G21+I21+K21+M21+O21+Q21+S21+U21+W21+Y21+AA21 -> 426 | AD21: =F21+H21+J21+L21+N21+P21+R21+T21+V21+X21+Z21+AB21 -> 596400
A22: 60 | B22: =LEFT(D22,FIND("-",D22)-1) -> MTEL | C22: 雪肌精 | D22: MTEL-SKCWｽﾑｰｼﾞﾝｸﾞR | E22: 10 | F22: 15000 | G22: 155 | H22: 232500 | I22: 30 | J22: 45000 | K22: 115 | L22: 172500 | AC22: =E22+G22+I22+K22+M22+O22+Q22+S22+U22+W22+Y22+AA22 -> 310 | AD22: =F22+H22+J22+L22+N22+P22+R22+T22+V22+X22+Z22+AB22 -> 465000
A23: 98 | B23: =LEFT(D23,FIND("-",D23)-1) -> MTBD | C23: 雪肌精 | D23: MTBD-SKｴｯｾﾝｽｿｰﾌﾟ | E23: 36 | F23: 25200 | I23: 67 | J23: 46900 | K23: 107 | L23: 74900 | AC23: =E23+G23+I23+K23+M23+O23+Q23+S23+U23+W23+Y23+AA23 -> 210 | AD23: =F23+H23+J23+L23+N23+P23+R23+T23+V23+X23+Z23+AB23 -> 147000
A24: 28 | B24: =LEFT(D24,FIND("-",D24)-1) -> MECB001 | C24: 雪肌精 | D24: MECB001-SK ﾎﾜｲﾄBB #001 | E24: 386 | F24: 501800 | G24: 10 | H24: 13000 | K24: 100 | L24: 130000 | AC24: =E24+G24+I24+K24+M24+O24+Q24+S24+U24+W24+Y24+AA24 -> 496 | AD24: =F24+H24+J24+L24+N24+P24+R24+T24+V24+X24+Z24+AB24 -> 644800
A25: 120 | B25: =LEFT(D25,FIND("-",D25)-1) -> MTSF | C25: 雪肌精 | D25: MTSF-ｾｯｷｾｲ ｹｼｮｳｽｲN TR | E25: 56 | F25: 16240 | I25: 31 | J25: 8990 | K25: 80 | L25: 23200 | AC25: =E25+G25+I25+K25+M25+O25+Q25+S25+U25+W25+Y25+AA25 -> 167 | AD25: =F25+H25+J25+L25+N25+P25+R25+T25+V25+X25+Z25+AB25 -> 48430
A26: 81 | B26: =LEFT(D26,FIND("-",D26)-1) -> MTYP | C26: 雪肌精 | D26: MTYP-SKCWﾘﾌｧｲﾆﾝｸﾞSR | E26: 110 | F26: 159500 | G26: 20 | H26: 29000 | K26: 70 | L26: 101500 | AC26: =E26+G26+I26+K26+M26+O26+Q26+S26+U26+W26+Y26+AA26 -> 200 | AD26: =F26+H26+J26+L26+N26+P26+R26+T26+V26+X26+Z26+AB26 -> 290000
A27: 123 | B27: =LEFT(D27,FIND("-",D27)-1) -> MTSD | C27: 雪肌精 | D27: MTSD-ｾｯｷｾｲ ﾆｭｳｴｷN | E27: 26 | F27: 53300 | G27: 53 | H27: 108650 | I27: 5 | J27: 10250 | K27: 64 | L27: 131200 | AC27: =E27+G27+I27+K27+M27+O27+Q27+S27+U27+W27+Y27+AA27 -> 148 | AD27: =F27+H27+J27+L27+N27+P27+R27+T27+V27+X27+Z27+AB27 -> 303400
A28: 198 | B28: =LEFT(D28,FIND("-",D28)-1) -> MWGP | C28: 雪肌精 | D28: MWGP-SKMｺﾞｰﾙﾃﾞﾝﾏｽｸ | E28: 3 | F28: 8250 | G28: 12 | H28: 33000 | I28: 15 | J28: 41250 | K28: 38 | L28: 104500 | AC28: =E28+G28+I28+K28+M28+O28+Q28+S28+U28+W28+Y28+AA28 -> 68 | AD28: =F28+H28+J28+L28+N28+P28+R28+T28+V28+X28+Z28+AB28 -> 187000
A29: 459 | B29: =LEFT(D29,FIND("-",D29)-1) -> MTKW | C29: 雪肌精 | D29: MTKW-SKCW UVﾄｰﾝｱｯﾌﾟ | K29: 35 | L29: 31500 | AC29: =E29+G29+I29+K29+M29+O29+Q29+S29+U29+W29+Y29+AA29 -> 35 | AD29: =F29+H29+J29+L29+N29+P29+R29+T29+V29+X29+Z29+AB29 -> 31500
A30: 458 | B30: =LEFT(D30,FIND("-",D30)-1) -> MTKV | C30: 雪肌精 | D30: MTKV-SKCW UVﾏｲﾙﾄﾞﾐﾙｸ | K30: 23 | L30: 24150 | AC30: =E30+G30+I30+K30+M30+O30+Q30+S30+U30+W30+Y30+AA30 -> 23 | AD30: =F30+H30+J30+L30+N30+P30+R30+T30+V30+X30+Z30+AB30 -> 24150
A31: 130 | B31: =LEFT(D31,FIND("-",D31)-1) -> MELW | C31: 雪肌精 | D31: MELW-ｾｯｷｾｲﾐﾙｷｨｳｫｯｼｭ | E31: 80 | F31: 120000 | K31: 20 | L31: 30000 | AC31: =E31+G31+I31+K31+M31+O31+Q31+S31+U31+W31+Y31+AA31 -> 100 | AD31: =F31+H31+J31+L31+N31+P31+R31+T31+V31+X31+Z31+AB31 -> 150000
A32: 27 | B32: =LEFT(D32,FIND("-",D32)-1) -> MTNC | C32: 雪肌精 | D32: MTNC-ｾｯｷｾｲｸﾘｰﾑｳｵｯｼｭ | E32: 261 | F32: 261000 | G32: 140 | H32: 140000 | K32: 18 | L32: 18000 | AC32: =E32+G32+I32+K32+M32+O32+Q32+S32+U32+W32+Y32+AA32 -> 419 | AD32: =F32+H32+J32+L32+N32+P32+R32+T32+V32+X32+Z32+AB32 -> 419000
A33: 238 | B33: =LEFT(D33,FIND("-",D33)-1) -> MTPL | C33: 雪肌精 | D33: MTPL-SKCWﾏｲﾙﾄﾞPｾﾗﾑ | E33: 20 | F33: 42000 | K33: 15 | L33: 31500 | AC33: =E33+G33+I33+K33+M33+O33+Q33+S33+U33+W33+Y33+AA33 -> 35 | AD33: =F33+H33+J33+L33+N33+P33+R33+T33+V33+X33+Z33+AB33 -> 73500
A34: 414 | B34: =LEFT(D34,FIND("-",D34)-1) -> MTQF | C34: 雪肌精 | D34: MTQF-SKCW Vｾﾗﾑ | E34: 2 | F34: 8500 | K34: 10 | L34: 42500 | AC34: =E34+G34+I34+K34+M34+O34+Q34+S34+U34+W34+Y34+AA34 -> 12 | AD34: =F34+H34+J34+L34+N34+P34+R34+T34+V34+X34+Z34+AB34 -> 51000
A35: 302 | B35: =LEFT(D35,FIND("-",D35)-1) -> MWFA | C35: 雪肌精 | D35: MWFA-SKMｱｸﾃｨﾛｰｼｮﾝ | G35: 2 | H35: 5500 | I35: 8 | J35: 22000 | K35: 3 | L35: 8250 | AC35: =E35+G35+I35+K35+M35+O35+Q35+S35+U35+W35+Y35+AA35 -> 13 | AD35: =F35+H35+J35+L35+N35+P35+R35+T35+V35+X35+Z35+AB35 -> 35750
A36: 415 | B36: =LEFT(D36,FIND("-",D36)-1) -> MWAF | C36: 雪肌精 | D36: MWAF-SKMｱﾙﾃｨﾒｲﾄｴﾏﾙｼﾞｮ | G36: 2 | H36: 11000 | K36: 3 | L36: 16500 | AC36: =E36+G36+I36+K36+M36+O36+Q36+S36+U36+W36+Y36+AA36 -> 5 | AD36: =F36+H36+J36+L36+N36+P36+R36+T36+V36+X36+Z36+AB36 -> 27500
A37: 61 | B37: =LEFT(D37,FIND("-",D37)-1) -> MTSX | C37: 雪肌精 | D37: MTSX-ｾｯｷｾｲ ﾆｭｳｴｷN R | E37: 42 | F37: 71400 | G37: 120 | H37: 204000 | I37: 33 | J37: 56100 | K37: 2 | L37: 3400 | AC37: =E37+G37+I37+K37+M37+O37+Q37+S37+U37+W37+Y37+AA37 -> 197 | AD37: =F37+H37+J37+L37+N37+P37+R37+T37+V37+X37+Z37+AB37 -> 334900
A38: 132 | B38: =LEFT(D38,FIND("-",D38)-1) -> MTEA | C38: 雪肌精 | D38: MTEA-SKｱｲｸﾘｰﾑN | E38: 9 | F38: 22500 | G38: 55 | H38: 137500 | I38: 12 | J38: 30000 | K38: 1 | L38: 2500 | AC38: =E38+G38+I38+K38+M38+O38+Q38+S38+U38+W38+Y38+AA38 -> 77 | AD38: =F38+H38+J38+L38+N38+P38+R38+T38+V38+X38+Z38+AB38 -> 192500
A39: 417 | B39: =LEFT(D39,FIND("-",D39)-1) -> MWAJ | C39: 雪肌精 | D39: MWAJ-SKM UL Eｸﾘｰﾑ | G39: 2 | H39: 13200 | K39: 1 | L39: 6600 | AC39: =E39+G39+I39+K39+M39+O39+Q39+S39+U39+W39+Y39+AA39 -> 3 | AD39: =F39+H39+J39+L39+N39+P39+R39+T39+V39+X39+Z39+AB39 -> 19800
A40: 154 | B40: =LEFT(D40,FIND("-",D40)-1) -> MTOL | C40: 雪肌精 | D40: MTOL-ｾｯｷｾｲ ｸﾘｰﾑｳｫｯｼｭN | G40: 48 | H40: 55200 | I40: 10 | J40: 11500 | AC40: =E40+G40+I40+K40+M40+O40+Q40+S40+U40+W40+Y40+AA40 -> 58 | AD40: =F40+H40+J40+L40+N40+P40+R40+T40+V40+X40+Z40+AB40 -> 66700
...

Sheet ブランド別
A1: 1月 | G1: 年間トータル
A2: ブランド | B2: 数量 | C2: 構成比 | D2: 金額 | E2: 構成比 | G2: ブランド | H2: 数量 | I2: 構成比 | J2: 金額 | K2: 構成比
A3: DECORTE | B3: =SUMIF(月別詳細!C:C,ブランド別!A3:A3,月別詳細!E:E) -> 10331 | C3: =B3/$B$8 -> 0.61166371 | D3: =SUMIF(月別詳細!C:C,A3,月別詳細!F:F) -> 28853275 | E3: =D3/$D$8 -> 0.67918338 | G3: DECORTE | H3: =SUMIF(月別詳細!C:C,G3,月別詳細!AC:AC) -> 67857 | I3: =H3/$H$8 -> 0.46249949 | J3: =SUMIF(月別詳細!C:C,G3,月別詳細!AD:AD) -> 203774505 | K3: =J3/$J$8 -> 0.62984921
A4: 雪肌精 | B4: =SUMIF(月別詳細!C:C,ブランド別!A4:A4,月別詳細!E:E) -> 2093 | C4: =B4/$B$8 -> 0.12391948 | D4: =SUMIF(月別詳細!C:C,A4,月別詳細!F:F) -> 2707040 | E4: =D4/$D$8 -> 0.063721591 | G4: 雪肌精 | H4: =SUMIF(月別詳細!C:C,G4,月別詳細!AC:AC) -> 17078 | I4: =H4/$H$8 -> 0.11640017 | J4: =SUMIF(月別詳細!C:C,G4,月別詳細!AD:AD) -> 23043435 | K4: =J4/$J$8 -> 0.071225246
A5: JILLSTUART | B5: =SUMIF(月別詳細!C:C,ブランド別!A5:A5,月別詳細!E:E) -> 1663 | C5: =B5/$B$8 -> 0.098460628 | D5: =SUMIF(月別詳細!C:C,A5,月別詳細!F:F) -> 2603019 | E5: =D5/$D$8 -> 0.061273019 | G5: JILLSTUART | H5: =SUMIF(月別詳細!C:C,G5,月別詳細!AC:AC) -> 16162 | I5: =H5/$H$8 -> 0.1101569 | J5: =SUMIF(月別詳細!C:C,G5,月別詳細!AD:AD) -> 30664233 | K5: =J5/$J$8 -> 0.094780468
A6: ONE BY KOSE | B6: =SUMIF(月別詳細!C:C,ブランド別!A6:A6,月別詳細!E:E) -> 2803 | C6: =B6/$B$8 -> 0.16595619 | D6: =SUMIF(月別詳細!C:C,A6,月別詳細!F:F) -> 8318970 | E6: =D6/$D$8 -> 0.19582201 | G6: ONE BY KOSE | H6: =SUMIF(月別詳細!C:C,G6,月別詳細!AC:AC) -> 25096 | I6: =H6/$H$8 -> 0.17104922 | J6: =SUMIF(月別詳細!C:C,G6,月別詳細!AD:AD) -> 51372695 | K6: =J6/$J$8 -> 0.15878852
A7: MKM | B7: =SUMIF(月別詳細!C:C,ブランド別!A7:A7,月別詳細!E:E) -> 0 | C7: =B7/$B$8 -> 0 | D7: =SUMIF(月別詳細!C:C,A7,月別詳細!F:F) -> 0 | E7: =D7/$D$8 -> 0 | G7: MKM | H7: =SUMIF(月別詳細!C:C,G7,月別詳細!AC:AC) -> 20525 | I7: =H7/$H$8 -> 0.13989422 | J7: =SUMIF(月別詳細!C:C,G7,月別詳細!AD:AD) -> 14674165 | K7: =J7/$J$8 -> 0.045356563
A8: 合計 | B8: =SUM(B3:B7) -> 16890 | C8: =B8/$B$8 -> 1 | D8: =SUM(D3:D7) -> 42482304 | E8: =D8/$D$8 -> 1 | G8: 合計 | H8: =SUM(H3:H7) -> 146718 | I8: =H8/$H$8 -> 1 | J8: =SUM(J3:J7) -> 323529033 | K8: =J8/$J$8 -> 1
A10: 2月
A11: ブランド | B11: 数量 | C11: 構成比 | D11: 金額 | E11: 構成比
A12: DECORTE | B12: =SUMIF(月別詳細!C:C,ブランド別!A12:A12,月別詳細!G:G) -> 13412 | C12: =B12/B$17 -> 0.61500367 | D12: =SUMIF(月別詳細!C:C,A12,月別詳細!H:H) -> 38406610 | E12: =D12/D$17 -> 0.69189757
A13: 雪肌精 | B13: =SUMIF(月別詳細!C:C,ブランド別!A13:A13,月別詳細!G:G) -> 2953 | C13: =B13/B$17 -> 0.13540902 | D13: =SUMIF(月別詳細!C:C,A13,月別詳細!H:H) -> 4040330 | E13: =D13/D$17 -> 0.072786807
A14: JILLSTUART | B14: =SUMIF(月別詳細!C:C,ブランド別!A14:A14,月別詳細!G:G) -> 2631 | C14: =B14/B$17 -> 0.1206438 | D14: =SUMIF(月別詳細!C:C,A14,月別詳細!H:H) -> 4720968 | E14: =D14/D$17 -> 0.085048545
A15: ONE BY KOSE | B15: =SUMIF(月別詳細!C:C,ブランド別!A15:A15,月別詳細!G:G) -> 2812 | C15: =B15/B$17 -> 0.12894351 | D15: =SUMIF(月別詳細!C:C,A15,月別詳細!H:H) -> 8341190 | E15: =D15/D$17 -> 0.15026708
A16: MKM | B16: =SUMIF(月別詳細!C:C,ブランド別!A16:A16,月別詳細!G:G) -> 0 | C16: =B16/B$17 -> 0 | D16: =SUMIF(月別詳細!C:C,A16,月別詳細!H:H) -> 0 | E16: =D16/D$17 -> 0
A17: 合計 | B17: =SUM(B12:B16) -> 21808 | C17: =B17/B$17 -> 1 | D17: =SUM(D12:D16) -> 55509098 | E17: =D17/D$17 -> 1
A19: ３月
A20: ブランド | B20: 数量 | C20: 構成比 | D20: 金額 | E20: 構成比
A21: DECORTE | B21: =SUMIF(月別詳細!C:C,ブランド別!A21:A21,月別詳細!I:I) -> 12880 | C21: =B21/B$26 -> 0.55793806 | D21: =SUMIF(月別詳細!C:C,A21,月別詳細!J:J) -> 37704645 | E21: =D21/D$26 -> 0.66937795
A22: 雪肌精 | B22: =SUMIF(月別詳細!C:C,ブランド別!A22:A22,月別詳細!I:I) -> 2176 | C22: =B22/B$26 -> 0.094260342 | D22: =SUMIF(月別詳細!C:C,A22,月別詳細!J:J) -> 3478890 | E22: =D22/D$26 -> 0.061761416
A23: JILLSTUART | B23: =SUMIF(月別詳細!C:C,ブランド別!A23:A23,月別詳細!I:I) -> 2830 | C23: =B23/B$26 -> 0.12259043 | D23: =SUMIF(月別詳細!C:C,A23,月別詳細!J:J) -> 5666256 | E23: =D23/D$26 -> 0.10059415
A24: ONE BY KOSE | B24: =SUMIF(月別詳細!C:C,ブランド別!A24:A24,月別詳細!I:I) -> 5194 | C24: =B24/B$26 -> 0.22499459 | D24: =SUMIF(月別詳細!C:C,A24,月別詳細!J:J) -> 9475730 | E24: =D24/D$26 -> 0.16822449
A25: MKM | B25: =SUMIF(月別詳細!C:C,ブランド別!A25:A25,月別詳細!I:I) -> 5 | C25: =B25/B$26 -> 0.00021659086 | D25: =SUMIF(月別詳細!C:C,A25,月別詳細!J:J) -> 2365 | E25: =D25/D$26 -> 4.1986309e-05
A26: 合計 | B26: =SUM(B21:B25) -> 23085 | C26: =B26/B$26 -> 1 | D26: =SUM(D21:D25) -> 56327886 | E26: =D26/D$26 -> 1
A28: 4月
A29: ブランド | B29: 数量 | C29: 構成比 | D29: 金額 | E29: 構成比
A30: DECORTE | B30: =SUMIF(月別詳細!C:C,ブランド別!A30:A30,月別詳細!K:K) -> 11619 | C30: =B30/B$26 -> 0.50331384 | D30: =SUMIF(月別詳細!C:C,A30,月別詳細!L:L) -> 34526085 | E30: =D30/D$26 -> 0.61294835
A31: 雪肌精 | B31: =SUMIF(月別詳細!C:C,ブランド別!A31:A31,月別詳細!K:K) -> 8635 | C31: =B31/B$26 -> 0.37405241 | D31: =SUMIF(月別詳細!C:C,A31,月別詳細!L:L) -> 11188975 | E31: =D31/D$26 -> 0.19864007
A32: JILLSTUART | B32: =SUMIF(月別詳細!C:C,ブランド別!A32:A32,月別詳細!K:K) -> 4391 | C32: =B32/B$26 -> 0.19021009 | D32: =SUMIF(月別詳細!C:C,A32,月別詳細!L:L) -> 9222315 | E32: =D32/D$26 -> 0.16372557
A33: ONE BY KOSE | B33: =SUMIF(月別詳細!C:C,ブランド別!A33:A33,月別詳細!K:K) -> 5327 | C33: =B33/B$26 -> 0.2307559 | D33: =SUMIF(月別詳細!C:C,A33,月別詳細!L:L) -> 9713605 | E33: =D33/D$26 -> 0.17244753
A34: MKM | B34: =SUMIF(月別詳細!C:C,ブランド別!A34:A34,月別詳細!K:K) -> 20520 | C34: =B34/B$26 -> 0.88888889 | D34: =SUMIF(月別詳細!C:C,A34,月別詳細!L:L) -> 14671800 | E34: =D34/D$26 -> 0.26047134
A35: 合計 | B35: =SUM(B30:B34) -> 50492 | C35: =B35/B$26 -> 2.1872211 | D35: =SUM(D30:D34) -> 79322780 | E35: =D35/D$26 -> 1.4082329
A37: 5月
A38: ブランド | B38: 数量 | C38: 構成比 | D38: 金額 | E38: 構成比
A39: DECORTE | B39: =SUMIF(月別詳細!C:C,ブランド別!A39:A39,月別詳細!M:M) -> 19615 | C39: =B39/B$26 -> 0.84968594 | D39: =SUMIF(月別詳細!C:C,A39,月別詳細!N:N) -> 64283890 | E39: =D39/D$26 -> 1.1412445
A40: 雪肌精 | B40: =SUMIF(月別詳細!C:C,ブランド別!A40:A40,月別詳細!M:M) -> 1221 | C40: =B40/B$26 -> 0.052891488 | D40: =SUMIF(月別詳細!C:C,A40,月別詳細!N:N) -> 1628200 | E40: =D40/D$26 -> 0.028905754
A41: JILLSTUART | B41: =SUMIF(月別詳細!C:C,ブランド別!A41:A41,月別詳細!M:M) -> 4647 | C41: =B41/B$26 -> 0.20129955 | D41: =SUMIF(月別詳細!C:C,A41,月別詳細!N:N) -> 8451675 | E41: =D41/D$26 -> 0.15004424
A42: ONE BY KOSE | B42: =SUMIF(月別詳細!C:C,ブランド別!A42:A42,月別詳細!M:M) -> 8960 | C42: =B42/B$26 -> 0.38813082 | D42: =SUMIF(月別詳細!C:C,A42,月別詳細!N:N) -> 15523200 | E42: =D42/D$26 -> 0.27558641
A43: MKM | B43: =SUMIF(月別詳細!C:C,ブランド別!A43:A43,月別詳細!M:M) -> 0 | C43: =B43/B$26 -> 0 | D43: =SUMIF(月別詳細!C:C,A43,月別詳細!N:N) -> 0 | E43: =D43/D$26 -> 0
A44: 合計 | B44: =SUM(B39:B43) -> 34443 | C44: =B44/B$26 -> 1.4920078 | D44: =SUM(D39:D43) -> 89886965 | E44: =D44/D$26 -> 1.5957809
...

Sheet ブランド別TOP10
A1: 1月 | G1: 2月 | M1: ３月 | S1: 4月 | Y1: 5月
A2: CD | G2: CD | M2: CD | S2: CD | Y2: CD
A3: No. | B3: 商品符号 | C3: 商品名称 | D3: 合計 | G3: No. | H3: 商品符号 | I3: 商品名称 | J3: 合計 | M3: No. | N3: 商品符号 | O3: 商品名称 | P3: 合計 | S3: No. | T3: 商品符号 | U3: 商品名称 | V3: 合計 | Y3: No. | Z3: 商品符号 | AA3: 商品名称 | AB3: 合計
D4: 数量 | E4: 金額 | J4: 数量 | K4: 金額 | P4: 数量 | Q4: 金額 | V4: 数量 | W4: 金額 | AB4: 数量 | AC4: 金額
A5: 1 | B5: =LEFT(C5,FIND("-",C5)-1) -> JQHQ | C5: JQHQ-AQﾌﾞｰｽﾃｨﾝｸﾞﾍｱｾﾗﾑ | D5: 999 | E5: 2912085 | G5: 1 | H5: =LEFT(I5,FIND("-",I5)-1) -> JQHQ | I5: JQHQ-AQﾌﾞｰｽﾃｨﾝｸﾞﾍｱｾﾗﾑ | J5: 1703 | K5: 4964245 | M5: 1 | N5: =LEFT(O5,FIND("-",O5)-1) -> JENE | O5: JENE-CDﾛｰｼﾞｰﾌﾟﾗｲﾏｰ | P5: 2782 | Q5: 4896320 | S5: 1 | T5: =LEFT(U5,FIND("-",U5)-1) -> JQHQ | U5: JQHQ-AQﾌﾞｰｽﾃｨﾝｸﾞﾍｱｾﾗﾑ | V5: 999 | W5: 2912085 | Y5: 1 | Z5: JEGP003 | AA5: JEGP003-CDｽｷﾝSｱｲﾊﾟﾚｯﾄ #003 | AB5: 2650 | AC5: 10202500
A6: 2 | B6: =LEFT(C6,FIND("-",C6)-1) -> JQHR | C6: JQHR-AQ Bﾍｱｾﾗﾑ ﾚﾌｨﾙ | D6: 988 | E6: 2608320 | G6: 2 | H6: =LEFT(I6,FIND("-",I6)-1) -> JETR | I6: JETR-CDﾛｰｼﾞｰﾌﾟﾗｲﾏｰ+ | J6: 830 | K6: 2054250 | M6: 2 | N6: =LEFT(O6,FIND("-",O6)-1) -> JQHQ | O6: JQHQ-AQﾌﾞｰｽﾃｨﾝｸﾞﾍｱｾﾗﾑ | P6: 999 | Q6: 2912085 | S6: 2 | T6: =LEFT(U6,FIND("-",U6)-1) -> JEGP001 | U6: JEGP001-CDｽｷﾝSｱｲﾊﾟﾚｯﾄ #001 | V6: 739 | W6: 2845150 | Y6: 2 | Z6: JQHQ | AA6: JQHQ-AQﾌﾞｰｽﾃｨﾝｸﾞﾍｱｾﾗﾑ | AB6: 1998 | AC6: 5824170
A7: 3 | B7: =LEFT(C7,FIND("-",C7)-1) -> JETR | C7: JETR-CDﾛｰｼﾞｰﾌﾟﾗｲﾏｰ+ | D7: 855 | E7: 2116125 | G7: 3 | H7: =LEFT(I7,FIND("-",I7)-1) -> JQHR | I7: JQHR-AQ Bﾍｱｾﾗﾑ ﾚﾌｨﾙ | J7: 750 | K7: 1980000 | M7: 3 | N7: =LEFT(O7,FIND("-",O7)-1) -> JVAI | O7: JVAI-CD ﾘﾎﾟｿｰﾑｾﾗﾑ30 | P7: 833 | Q7: 3665200 | S7: 3 | T7: =LEFT(U7,FIND("-",U7)-1) -> JEFC000 | U7: JEFC000-CDﾄｰﾝPﾊﾟﾚｯﾄ #000 | V7: 662 | W7: 1711270 | Y7: 3 | Z7: JENE | AA7: JENE-CDﾛｰｼﾞｰﾌﾟﾗｲﾏｰ | AB7: 880 | AC7: 1548800
A8: 4 | B8: =LEFT(C8,FIND("-",C8)-1) -> JENE | C8: JENE-CDﾛｰｼﾞｰﾌﾟﾗｲﾏｰ | D8: 700 | E8: 1232000 | G8: 4 | H8: =LEFT(I8,FIND("-",I8)-1) -> JENE | I8: JENE-CDﾛｰｼﾞｰﾌﾟﾗｲﾏｰ | J8: 740 | K8: 1302400 | M8: 4 | N8: =LEFT(O8,FIND("-",O8)-1) -> JEFC001 | O8: JEFC001-CDﾄｰﾝPﾊﾟﾚｯﾄ #001 | P8: 580 | Q8: 1499300 | S8: 4 | T8: =LEFT(U8,FIND("-",U8)-1) -> JQHR | U8: JQHR-AQ Bﾍｱｾﾗﾑ ﾚﾌｨﾙ | V8: 521 | W8: 1375440 | Y8: 4 | Z8: JEFT | AA8: JEFT-CDﾃﾞｲﾐｽﾄS&P | AB8: 856 | AC8: 1506560
A9: 5 | B9: =LEFT(C9,FIND("-",C9)-1) -> JCFC301 | C9: JCFC301-MX ｶﾊﾞﾘﾝｸﾞFD #301 | D9: 666 | E9: 1831500 | G9: 5 | H9: =LEFT(I9,FIND("-",I9)-1) -> JVAI | I9: JVAI-CD ﾘﾎﾟｿｰﾑｾﾗﾑ30 | J9: 426 | K9: 1874400 | M9: 5 | N9: =LEFT(O9,FIND("-",O9)-1) -> JQRO | O9: JQRO-CD23AQｹｱﾅﾋﾞﾖｳｴｷ | P9: 521 | Q9: 2865500 | S9: 5 | T9: =LEFT(U9,FIND("-",U9)-1) -> JKFC | U9: JKFC-CD HC ﾔｸﾖｳﾛｰｼｮﾝ | V9: 491 | W9: 1485275 | Y9: 5 | Z9: JQHO | AA9: JQHO-AQｽﾑｰｽｼｬﾝﾌﾟｰ600 | AB9: 755 | AC9: 2574550
A10: 6 | B10: =LEFT(C10,FIND("-",C10)-1) -> JVAI | C10: JVAI-CD ﾘﾎﾟｿｰﾑｾﾗﾑ30 | D10: 570 | E10: 2508000 | G10: 6 | H10: =LEFT(I10,FIND("-",I10)-1) -> JQRO | I10: JQRO-CD23AQｹｱﾅﾋﾞﾖｳｴｷ | J10: 419 | K10: 2304500 | M10: 6 | N10: =LEFT(O10,FIND("-",O10)-1) -> JVXC | O10: JVXC-CD ﾕｰｽﾊﾟﾜｰｴｯｾﾝｽ | P10: 426 | Q10: 3514500 | S10: 6 | T10: =LEFT(U10,FIND("-",U10)-1) -> JKFT | U10: JKFT-CD HCﾌﾞﾗｲﾄﾛｰｼｮﾝ | V10: 464 | W10: 1582240 | Y10: 6 | Z10: JQHV | AA10: JQHV-AQｽﾑｰｽｺﾝﾃﾞ600 | AB10: 700 | AC10: 2579500
A11: 7 | B11: =LEFT(C11,FIND("-",C11)-1) -> JQRO | C11: JQRO-CD23AQｹｱﾅﾋﾞﾖｳｴｷ | D11: 500 | E11: 2750000 | G11: 7 | H11: =LEFT(I11,FIND("-",I11)-1) -> JEFC000 | I11: JEFC000-CDﾄｰﾝPﾊﾟﾚｯﾄ #000 | J11: 387 | K11: 1000395 | M11: 7 | N11: =LEFT(O11,FIND("-",O11)-1) -> JQHR | O11: JQHR-AQ Bﾍｱｾﾗﾑ ﾚﾌｨﾙ | P11: 403 | Q11: 1063920 | S11: 7 | T11: =LEFT(U11,FIND("-",U11)-1) -> JCFC301 | U11: JCFC301-MX ｶﾊﾞﾘﾝｸﾞFD #301 | V11: 445 | W11: 1223750 | Y11: 7 | Z11: JVXC | AA11: JVXC-CD ﾕｰｽﾊﾟﾜｰｴｯｾﾝｽ | AB11: 616 | AC11: 5082000
A12: 8 | B12: =LEFT(C12,FIND("-",C12)-1) -> JEFC000 | C12: JEFC000-CDﾄｰﾝPﾊﾟﾚｯﾄ #000 | D12: 467 | E12: 1207195 | G12: 8 | H12: =LEFT(I12,FIND("-",I12)-1) -> JEGG013 | I12: JEGG013-CDｱｲｼﾞｪﾑｽｷﾝSｸﾞﾛｳ#013 | J12: 387 | K12: 638550 | M12: 8 | N12: =LEFT(O12,FIND("-",O12)-1) -> JETR | O12: JETR-CDﾛｰｼﾞｰﾌﾟﾗｲﾏｰ+ | P12: 372 | Q12: 920700 | S12: 8 | T12: =LEFT(U12,FIND("-",U12)-1) -> JKFU | U12: JKFU-CD HCﾌﾞﾗｲﾄｿﾌﾅｰ | V12: 387 | W12: 1319670 | Y12: 8 | Z12: JEGP010 | AA12: JEGP010-CDｽｷﾝSｱｲﾊﾟﾚｯﾄ #010 | AB12: 590 | AC12: 2271500
A13: 9 | B13: =LEFT(C13,FIND("-",C13)-1) -> JEYP | C13: JEYP-CDｾﾞﾝｳｪｱPFDｹｰｽ | D13: 354 | E13: 292050 | G13: 9 | H13: =LEFT(I13,FIND("-",I13)-1) -> JELK001 | I13: JELK001-CDﾙｰｼﾞｭﾃｨﾝﾄ #001 | J13: 319 | K13: 877250 | M13: 9 | N13: =LEFT(O13,FIND("-",O13)-1) -> JCFC301 | O13: JCFC301-MX ｶﾊﾞﾘﾝｸﾞFD #301 | P13: 228 | Q13: 627000 | S13: 9 | T13: =LEFT(U13,FIND("-",U13)-1) -> JELK003 | U13: JELK003-CDﾙｰｼﾞｭﾃｨﾝﾄ #003 | V13: 376 | W13: 1034000 | Y13: 9 | Z13: JCFC301 | AA13: JCFC301-MX ｶﾊﾞﾘﾝｸﾞFD #301 | AB13: 550 | AC13: 1512500
A14: 10 | B14: =LEFT(C14,FIND("-",C14)-1) -> JEFC001 | C14: JEFC001-CDﾄｰﾝPﾊﾟﾚｯﾄ #001 | D14: 333 | E14: 860805 | G14: 10 | H14: =LEFT(I14,FIND("-",I14)-1) -> JEGH022 | I14: JEGH022-CDｱｲｼﾞｪﾑｽｷﾝSﾏｯﾄ #022 | J14: 315 | K14: 519750 | M14: 10 | N14: =LEFT(O14,FIND("-",O14)-1) -> JEGG013 | O14: JEGG013-CDｱｲｼﾞｪﾑｽｷﾝSｸﾞﾛｳ#013 | P14: 217 | Q14: 358050 | S14: 10 | T14: =LEFT(U14,FIND("-",U14)-1) -> JEGP003 | U14: JEGP003-CDｽｷﾝSｱｲﾊﾟﾚｯﾄ #003 | V14: 300 | W14: 1155000 | Y14: 10 | Z14: JVAR | AA14: JVAR-CD ﾘﾎﾟｿｰﾑｾﾗﾑ75R | AB14: 536 | AC14: 4422000
A16: SＥＫ | G16: SＥＫ | M16: SＥＫ | S16: SＥＫ | Y16: SＥＫ
A17: No. | B17: 商品符号 | C17: 商品名称 | D17: 合計 | G17: No. | H17: 商品符号 | I17: 商品名称 | J17: 合計 | M17: No. | N17: 商品符号 | O17: 商品名称 | P17: 合計 | S17: No. | T17: 商品符号 | U17: 商品名称 | V17: 合計 | Y17: No. | Z17: 商品符号 | AA17: 商品名称 | AB17: 合計
D18: 数量 | E18: 金額 | J18: 数量 | K18: 金額 | P18: 数量 | Q18: 金額 | V18: 数量 | W18: 金額 | AB18: 数量 | AC18: 金額
A19: 1 | B19: =LEFT(C19,FIND("-",C19)-1) -> MECB001 | C19: MECB001-SK ﾎﾜｲﾄBB #001 | D19: 386 | E19: 501800 | G19: 1 | H19: =LEFT(I19,FIND("-",I19)-1) -> MTOE001 | I19: MTOE001-ｾｯｷｾｲBBｴｯｾﾝｽ #001 | J19: 461 | K19: 599300 | M19: 1 | N19: =LEFT(O19,FIND("-",O19)-1) -> MTLJ | O19: MTLJ-SKｽｷﾝｹｱUVﾐﾙｸNA | P19: 645 | Q19: 806250 | S19: 1 | T19: =LEFT(U19,FIND("-",U19)-1) -> MTOE001 | U19: MTOE001-ｾｯｷｾｲBBｴｯｾﾝｽ #001 | V19: 1331 | W19: 1730300 | Y19: 1 | Z19: MTNN | AA19: MTNN-ｾｯｷｾｲBR UVﾆｭｳｴｷ | AB19: 336 | AC19: 537600
A20: 2 | B20: =LEFT(C20,FIND("-",C20)-1) -> MECB002 | C20: MECB002-SK ﾎﾜｲﾄBB #002 | D20: 270 | E20: 351000 | G20: 2 | H20: =LEFT(I20,FIND("-",I20)-1) -> MTLE | I20: MTLE-SKｽｷﾝｹｱUVﾐﾙｸN | J20: 445 | K20: 534000 | M20: 2 | N20: =LEFT(O20,FIND("-",O20)-1) -> MTSW | O20: MTSW-ｾｯｷｾｲ ｹｼｮｳｽｲN R | P20: 432 | Q20: 1058400 | S20: 2 | T20: =LEFT(U20,FIND("-",U20)-1) -> MTLD | U20: MTLD-SKｽｷﾝｹｱUVｼﾞｪﾙN | V20: 1199 | W20: 1258950 | Y20: 2 | Z20: MTOE001 | AA20: MTOE001-ｾｯｷｾｲBBｴｯｾﾝｽ #001 | AB20: 300 | AC20: 390000
A21: 3 | B21: =LEFT(C21,FIND("-",C21)-1) -> MTNC | C21: MTNC-ｾｯｷｾｲｸﾘｰﾑｳｵｯｼｭ | D21: 261 | E21: 261000 | G21: 3 | H21: =LEFT(I21,FIND("-",I21)-1) -> MTLD | I21: MTLD-SKｽｷﾝｹｱUVｼﾞｪﾙN | J21: 384 | K21: 403200 | M21: 3 | N21: =LEFT(O21,FIND("-",O21)-1) -> MTLI | O21: MTLI-SKｽｷﾝｹｱUVｼﾞｪﾙNA | P21: 300 | Q21: 330000 | S21: 3 | T21: =LEFT(U21,FIND("-",U21)-1) -> MTLE | U21: MTLE-SKｽｷﾝｹｱUVﾐﾙｸN | V21: 1096 | W21: 1315200 | Y21: 3 | Z21: MTLD | AA21: MTLD-SKｽｷﾝｹｱUVｼﾞｪﾙN | AB21: 200 | AC21: 210000
A22: 4 | B22: =LEFT(C22,FIND("-",C22)-1) -> MTLE | C22: MTLE-SKｽｷﾝｹｱUVﾐﾙｸN | D22: 230 | E22: 276000 | G22: 4 | H22: =LEFT(I22,FIND("-",I22)-1) -> MTCP | I22: MTCP-SKCWｼﾞｪﾝﾄﾙｳｫｯｼｭR | J22: 310 | K22: 240250 | M22: 4 | N22: =LEFT(O22,FIND("-",O22)-1) -> MTNN | O22: MTNN-ｾｯｷｾｲBR UVﾆｭｳｴｷ | P22: 270 | Q22: 432000 | S22: 4 | T22: =LEFT(U22,FIND("-",U22)-1) -> MTLJ | U22: MTLJ-SKｽｷﾝｹｱUVﾐﾙｸNA | V22: 1050 | W22: 1312500 | Y22: 4 | Z22: MTLI | AA22: MTLI-SKｽｷﾝｹｱUVｼﾞｪﾙNA | AB22: 200 | AC22: 220000
A23: 5 | B23: =LEFT(C23,FIND("-",C23)-1) -> MTCP | C23: MTCP-SKCWｼﾞｪﾝﾄﾙｳｫｯｼｭR | D23: 150 | E23: 116250 | G23: 5 | H23: =LEFT(I23,FIND("-",I23)-1) -> MTEI | I23: MTEI-SKCWﾅﾁｭﾗﾙﾄﾞﾘｯﾌﾟR | J23: 186 | K23: 260400 | M23: 5 | N23: =LEFT(O23,FIND("-",O23)-1) -> MTSE | O23: MTSE-ｾｯｷｾｲ ｹｼｮｳｽｲBIG | P23: 82 | Q23: 237800 | S23: 5 | T23: =LEFT(U23,FIND("-",U23)-1) -> MTOE002 | U23: MTOE002-ｾｯｷｾｲBBｴｯｾﾝｽ #002 | V23: 910 | W23: 1183000 | Y23: 5 | Z23: MTLJ | AA23: MTLJ-SKｽｷﾝｹｱUVﾐﾙｸNA | AB23: 100 | AC23: 125000
A24: 6 | B24: =LEFT(C24,FIND("-",C24)-1) -> MTYP | C24: MTYP-SKCWﾘﾌｧｲﾆﾝｸﾞSR | D24: 110 | E24: 159500 | G24: 6 | H24: =LEFT(I24,FIND("-",I24)-1) -> MTEL | I24: MTEL-SKCWｽﾑｰｼﾞﾝｸﾞR | J24: 155 | K24: 232500 | M24: 6 | N24: =LEFT(O24,FIND("-",O24)-1) -> MTBD | O24: MTBD-SKｴｯｾﾝｽｿｰﾌﾟ | P24: 67 | Q24: 46900 | S24: 6 | T24: =LEFT(U24,FIND("-",U24)-1) -> MTLI | U24: MTLI-SKｽｷﾝｹｱUVｼﾞｪﾙNA | V24: 530 | W24: 583000 | Y24: 6 | Z24: MTSC | AA24: MTSC-ｾｯｷｾｲ ｹｼｮｳｽｲN | AB24: 70 | AC24: 133000
A25: 7 | B25: =LEFT(C25,FIND("-",C25)-1) -> MTSW | C25: MTSW-ｾｯｷｾｲ ｹｼｮｳｽｲN R | D25: 104 | E25: 254800 | G25: 7 | H25: =LEFT(I25,FIND("-",I25)-1) -> MTNC | I25: MTNC-ｾｯｷｾｲｸﾘｰﾑｳｵｯｼｭ | J25: 140 | K25: 140000 | M25: 7 | N25: =LEFT(O25,FIND("-",O25)-1) -> MTOE002 | O25: MTOE002-ｾｯｷｾｲBBｴｯｾﾝｽ #002 | P25: 55 | Q25: 71500 | S25: 7 | T25: =LEFT(U25,FIND("-",U25)-1) -> MTNN | U25: MTNN-ｾｯｷｾｲBR UVﾆｭｳｴｷ | V25: 434 | W25: 694400 | Y25: 7 | Z25: MTSE | AA25: MTSE-ｾｯｷｾｲ ｹｼｮｳｽｲBIG | AB25: 30 | AC25: 87000
A26: 8 | B26: =LEFT(C26,FIND("-",C26)-1) -> MTLD | C26: MTLD-SKｽｷﾝｹｱUVｼﾞｪﾙN | D26: 100 | E26: 105000 | G26: 8 | H26: =LEFT(I26,FIND("-",I26)-1) -> MTSX | I26: MTSX-ｾｯｷｾｲ ﾆｭｳｴｷN R | J26: 120 | K26: 204000 | M26: 8 | N26: =LEFT(O26,FIND("-",O26)-1) -> MECB002 | O26: MECB002-SK ﾎﾜｲﾄBB #002 | P26: 40 | Q26: 52000 | S26: 8 | T26: =LEFT(U26,FIND("-",U26)-1) -> MTCP | U26: MTCP-SKCWｼﾞｪﾝﾄﾙｳｫｯｼｭR | V26: 291 | W26: 225525 | Y26: 8 | Z26: MTSU | AA26: MTSU-ｾｯｷｾｲ ｸﾘｰﾑ N | AB26: 9 | AC26: 19350
A27: 9 | B27: =LEFT(C27,FIND("-",C27)-1) -> MELW | C27: MELW-ｾｯｷｾｲﾐﾙｷｨｳｫｯｼｭ | D27: 80 | E27: 120000 | G27: 9 | H27: =LEFT(I27,FIND("-",I27)-1) -> MTSW | I27: MTSW-ｾｯｷｾｲ ｹｼｮｳｽｲN R | J27: 112 | K27: 274400 | M27: 9 | N27: =LEFT(O27,FIND("-",O27)-1) -> MTSX | O27: MTSX-ｾｯｷｾｲ ﾆｭｳｴｷN R | P27: 33 | Q27: 56100 | S27: 9 | T27: =LEFT(U27,FIND("-",U27)-1) -> MECB002 | U27: MECB002-SK ﾎﾜｲﾄBB #002 | V27: 268 | W27: 348400 | Y27: 9 | Z27: MEWZ | AA27: MEWZ-SK ｹｼｮｳｽｲｼﾀﾃｾｯｹﾝ | AB27: 4 | AC27: 4000
A28: 10 | B28: =LEFT(C28,FIND("-",C28)-1) -> MTYO | C28: MTYO-SKCWﾋﾟｭｱｺﾝｸSR | D28: 70 | E28: 94500 | G28: 10 | H28: =LEFT(I28,FIND("-",I28)-1) -> MTOE002 | I28: MTOE002-ｾｯｷｾｲBBｴｯｾﾝｽ #002 | J28: 110 | K28: 143000 | M28: 10 | N28: =LEFT(O28,FIND("-",O28)-1) -> MTSF | O28: MTSF-ｾｯｷｾｲ ｹｼｮｳｽｲN TR | P28: 31 | Q28: 8990 | S28: 10 | T28: =LEFT(U28,FIND("-",U28)-1) -> MTYO | U28: MTYO-SKCWﾋﾟｭｱｺﾝｸSR | V28: 220 | W28: 297000 | Y28: 10 | Z28: MTAA | AA28: MTAA-ｾｯｷｾｲﾊｰﾊﾞﾙｼﾞｪﾙ | AB28: 3 | AC28: 5700
A30: ＪＳ | G30: ＪＳ | M30: ＪＳ | S30: ＪＳ | Y30: ＪＳ
A31: No. | B31: 商品符号 | C31: 商品名称 | D31: 合計 | G31: No. | H31: 商品符号 | I31: 商品名称 | J31: 合計 | M31: No. | N31: 商品符号 | O31: 商品名称 | P31: 合計 | S31: No. | T31: 商品符号 | U31: 商品名称 | V31: 合計 | Y31: No. | Z31: 商品符号 | AA31: 商品名称 | AB31: 合計
D32: 数量 | E32: 金額 | J32: 数量 | K32: 金額 | P32: 数量 | Q32: 金額 | V32: 数量 | W32: 金額 | AB32: 数量 | AC32: 金額
A33: 1 | B33: =LEFT(C33,FIND("-",C33)-1) -> SINO002 | C33: SINO002-JS ｱﾛﾏﾃｨｯｸﾈｲﾙｵｲﾙ#002 | D33: 485 | E33: 552900 | G33: 1 | H33: =LEFT(I33,FIND("-",I33)-1) -> SINO001 | I33: SINO001-JS ｱﾛﾏﾃｨｯｸﾈｲﾙｵｲﾙ#001 | J33: 351 | K33: 400140 | M33: 1 | N33: =LEFT(O33,FIND("-",O33)-1) -> SINO001 | O33: SINO001-JS ｱﾛﾏﾃｨｯｸﾈｲﾙｵｲﾙ#001 | P33: 232 | Q33: 264480 | S33: 1 | T33: =LEFT(U33,FIND("-",U33)-1) -> SHLP001 | U33: SHLP001-JS ｸﾞﾛｳｼﾌｫﾝﾙｰｽP #001 | V33: 1150 | W33: 3146400 | Y33: 1 | Z33: SIUR | AA33: SIUR-JSWFﾍｯﾄﾞｸﾚﾝｽﾞ | AB33: 320 | AC33: 638400
A34: 2 | B34: =LEFT(C34,FIND("-",C34)-1) -> SINO001 | C34: SINO001-JS ｱﾛﾏﾃｨｯｸﾈｲﾙｵｲﾙ#001 | D34: 331 | E34: 377340 | G34: 2 | H34: =LEFT(I34,FIND("-",I34)-1) -> SITA | I34: SITA-JS Wｵｰﾄﾞﾄﾜﾚ | J34: 210 | K34: 478800 | M34: 2 | N34: =LEFT(O34,FIND("-",O34)-1) -> SITA | O34: SITA-JS Wｵｰﾄﾞﾄﾜﾚ | P34: 210 | Q34: 478800 | S34: 2 | T34: =LEFT(U34,FIND("-",U34)-1) -> SIUR | U34: SIUR-JSWFﾍｯﾄﾞｸﾚﾝｽﾞ | V34: 636 | W34: 1268820 | Y34: 2 | Z34: SHBG004 | AA34: SHBG004-JS SB26ﾏｲﾘｯﾌﾟｽ #004 | AB34: 300 | AC34: 547200
A35: 3 | B35: =LEFT(C35,FIND("-",C35)-1) -> SIOA001 | C35: SIOA001-JS ｲﾙﾐﾈｲﾃｨﾝｸﾞP #001 | D35: 130 | E35: 259350 | G35: 3 | H35: =LEFT(I35,FIND("-",I35)-1) -> SHSG | I35: SHSG-JSSAﾍｱｵｲﾙD | J35: 201 | K35: 389538 | M35: 3 | N35: =LEFT(O35,FIND("-",O35)-1) -> SHBA003 | O35: SHBA003-JS ｸﾁｭｰﾙﾐｯｸｽB #003 | P35: 204 | Q35: 523260 | S35: 3 | T35: =LEFT(U35,FIND("-",U35)-1) -> STMY | U35: STMY-JS ｺﾝﾊﾟｸﾄﾐﾗｰ2 | V35: 330 | W35: 470250 | Y35: 3 | Z35: SHBJ | AA35: SHBJ-JS SB F&BﾊﾟｳﾀﾞｰN | AB35: 300 | AC35: 940500
A36: 4 | B36: =LEFT(C36,FIND("-",C36)-1) -> SJPK001 | C36: SJPK001-JS ﾌﾞﾙｰﾑﾐｯｸｽBC #001 | D36: 100 | E36: 239400 | G36: 4 | H36: =LEFT(I36,FIND("-",I36)-1) -> SHSC | I36: SHSC-JSSAUVﾌﾟﾛﾃｸﾀｰ | J36: 200 | K36: 387600 | M36: 4 | N36: =LEFT(O36,FIND("-",O36)-1) -> SHLP003 | O36: SHLP003-JS ｸﾞﾛｳｼﾌｫﾝﾙｰｽP #003 | P36: 171 | Q36: 467856 | S36: 4 | T36: =LEFT(U36,FIND("-",U36)-1) -> SHLP003 | U36: SHLP003-JS ｸﾞﾛｳｼﾌｫﾝﾙｰｽP #003 | V36: 279 | W36: 763344 | Y36: 4 | Z36: SIEI001 | AA36: SIEI001-JS ﾄﾞﾚｽﾄﾞﾌﾞﾙｰﾑE #001 | AB36: 278 | AC36: 950760
A37: 5 | B37: =LEFT(C37,FIND("-",C37)-1) -> SJFG | C37: SJFG-JS CBﾊﾝﾄﾞ | D37: 92 | E37: 125856 | G37: 5 | H37: =LEFT(I37,FIND("-",I37)-1) -> SHSF103 | I37: SHSF103-JSSAﾐｯｸｽﾊｲﾗｲﾄ #103 | J37: 200 | K37: 478800 | M37: 5 | N37: =LEFT(O37,FIND("-",O37)-1) -> SJPN | O37: SJPN-JS ﾁｰｸｶﾗｰﾌﾞﾗｼ | P37: 167 | Q37: 190380 | S37: 5 | T37: =LEFT(U37,FIND("-",U37)-1) -> SINO002 | U37: SINO002-JS ｱﾛﾏﾃｨｯｸﾈｲﾙｵｲﾙ#002 | V37: 251 | W37: 286140 | Y37: 5 | Z37: SIOT | AA37: SIOT-JS WFﾊﾝﾄﾞｸﾘｰﾑ | AB37: 237 | AC37: 189126
A38: 6 | B38: =LEFT(C38,FIND("-",C38)-1) -> SJPN | C38: SJPN-JS ﾁｰｸｶﾗｰﾌﾞﾗｼ | D38: 73 | E38: 83220 | G38: 6 | H38: =LEFT(I38,FIND("-",I38)-1) -> SINO002 | I38: SINO002-JS ｱﾛﾏﾃｨｯｸﾈｲﾙｵｲﾙ#002 | J38: 175 | K38: 199500 | M38: 6 | N38: =LEFT(O38,FIND("-",O38)-1) -> SHLP002 | O38: SHLP002-JS ｸﾞﾛｳｼﾌｫﾝﾙｰｽP #002 | P38: 150 | Q38: 410400 | S38: 6 | T38: =LEFT(U38,FIND("-",U38)-1) -> SIHF | U38: SIHF-JS ﾍｱﾌﾞﾗｼ | V38: 202 | W38: 414504 | Y38: 6 | Z38: STMY | AA38: STMY-JS ｺﾝﾊﾟｸﾄﾐﾗｰ2 | AB38: 235 | AC38: 334875
A39: 7 | B39: =LEFT(C39,FIND("-",C39)-1) -> SJFW | C39: SJFW-JS CBﾍｱﾐｽﾄ | D39: 61 | E39: 125172 | G39: 7 | H39: =LEFT(I39,FIND("-",I39)-1) -> SHSB | I39: SHSB-JS SA26 ﾊﾝﾄﾞｸﾘｰﾑ | J39: 150 | K39: 205200 | M39: 7 | N39: =LEFT(O39,FIND("-",O39)-1) -> SHLP004 | O39: SHLP004-JS ｸﾞﾛｳｼﾌｫﾝﾙｰｽP #004 | P39: 127 | Q39: 347472 | S39: 7 | T39: =LEFT(U39,FIND("-",U39)-1) -> SINO001 | U39: SINO001-JS ｱﾛﾏﾃｨｯｸﾈｲﾙｵｲﾙ#001 | V39: 200 | W39: 228000 | Y39: 7 | Z39: SINO001 | AA39: SINO001-JS ｱﾛﾏﾃｨｯｸﾈｲﾙｵｲﾙ#001 | AB39: 210 | AC39: 239400
A40: 8 | B40: =LEFT(C40,FIND("-",C40)-1) -> STFR | C40: STFR-JS ｸﾘｽﾀﾙﾌﾞﾙｰﾑ30 | D40: 60 | E40: 194940 | G40: 8 | H40: =LEFT(I40,FIND("-",I40)-1) -> SIDT | I40: SIDT-JS WFｼｬﾝﾌﾟｰ | J40: 116 | K40: 211584 | M40: 8 | N40: =LEFT(O40,FIND("-",O40)-1) -> SIDU | O40: SIDU-JS WFﾄﾘｰﾄﾒﾝﾄ | P40: 113 | Q40: 206112 | S40: 8 | T40: =LEFT(U40,FIND("-",U40)-1) -> SIOA001 | U40: SIOA001-JS ｲﾙﾐﾈｲﾃｨﾝｸﾞP #001 | V40: 150 | W40: 299250 | Y40: 8 | Z40: SHBE | AA40: SHBE-JS SB26ﾊﾝﾄﾞｴｯｾﾝｽ | AB40: 200 | AC40: 273600
A41: 9 | B41: =LEFT(C41,FIND("-",C41)-1) -> SIHF | C41: SIHF-JS ﾍｱﾌﾞﾗｼ | D41: 50 | E41: 102600 | G41: 9 | H41: =LEFT(I41,FIND("-",I41)-1) -> SIUR | I41: SIUR-JSWFﾍｯﾄﾞｸﾚﾝｽﾞ | J41: 111 | K41: 221445 | M41: 9 | N41: =LEFT(O41,FIND("-",O41)-1) -> SHBA002 | O41: SHBA002-JS ｸﾁｭｰﾙﾐｯｸｽB #002 | P41: 106 | Q41: 271890 | S41: 9 | T41: =LEFT(U41,FIND("-",U41)-1) -> SIOA002 | U41: SIOA002-JS ｲﾙﾐﾈｲﾃｨﾝｸﾞP #002 | V41: 133 | W41: 265335 | Y41: 9 | Z41: SHBI | AA41: SHBI-JSSB ﾍｯﾄﾞｸﾚﾝｽﾞN | AB41: 200 | AC41: 444600
A42: 10 | B42: =LEFT(C42,FIND("-",C42)-1) -> SJPK027 | C42: SJPK027-JS ﾌﾞﾙｰﾑﾐｯｸｽBC #027 | D42: 34 | E42: 81396 | G42: 10 | H42: =LEFT(I42,FIND("-",I42)-1) -> SHSH | I42: SHSH-JSSAﾎﾞﾃﾞｨｸﾘｰﾑ | J42: 100 | K42: 307800 | M42: 10 | N42: =LEFT(O42,FIND("-",O42)-1) -> SIDT | O42: SIDT-JS WFｼｬﾝﾌﾟｰ | P42: 104 | Q42: 189696 | S42: 10 | T42: =LEFT(U42,FIND("-",U42)-1) -> SIOT | U42: SIOT-JS WFﾊﾝﾄﾞｸﾘｰﾑ | V42: 115 | W42: 91770 | Y42: 10 | Z42: SHBK101 | AA42: SHBK101-JS ｲﾙﾐﾈｲﾃｨﾝｸﾞSPB#101 | AB42: 200 | AC42: 399000
...
