Workbook

Sheet 2025累計
A1: No. | B1: JANコード | C1: 商品符号 | D1: ブランド | E1: 商品名称 | F1: 2501 | H1: 2502 | J1: 2503 | L1: 2504 | N1: 2505 | P1: 2506 | R1: 2507 | T1: 2508 | V1: 2509 | X1: 2510 | Z1: 2511 | AB1: 2512 | AD1: 合計 | AG1: 商品符号
F2: 数量 | G2: 金額 | H2: 数量 | I2: 金額 | J2: 数量 | K2: 金額 | L2: 数量 | M2: 金額 | N2: 数量 | O2: 金額 | P2: 数量 | Q2: 金額 | R2: 数量 | S2: 金額 | T2: 数量 | U2: 金額 | V2: 数量 | W2: 金額 | X2: 数量 | Y2: 金額 | Z2: 数量 | AA2: 金額 | AB2: 数量 | AC2: 金額 | AD2: 数量 | AE2: 金額
A3: 1 | B3: 4971710576306 | C3: DLEA | D3: MKM | E3: MAKE KEEP MIST EX + | F3: 2020 | G3: 1333200 | H3: 2944 | I3: 1631520 | J3: 8316 | K3: 5488560 | L3: 12276 | M3: 8102160 | N3: 20201 | O3: 13332660 | P3: 13848 | Q3: 9139680 | R3: 31222 | S3: 20606520 | T3: 26000 | U3: 17160000 | V3: 64352 | W3: 42472320 | AD3: =F3+H3+J3+L3+N3+P3+R3+T3+V3+X3+Z3+AB3 -> 181179 | AE3: =G3+I3+K3+M3+O3+Q3+S3+U3+W3+Y3+AA3+AC3 -> 119266620 | AG3: DLEA
A4: 2 | B4: 4971710565065 | C4: MUSC | D4: ONE BY KOSE | E4: ONE BY KOSE SERUM SHIELD | F4: 3342 | G4: 9190500 | H4: 3836 | I4: 5714500 | J4: 926 | K4: 2546500 | L4: 2212 | M4: 6083000 | N4: 5987 | O4: 16464250 | P4: 1120 | Q4: 3080000 | R4: 2598 | S4: 7144500 | T4: 1700 | U4: 4675000 | V4: 16456 | W4: 45254000 | AD4: =F4+H4+J4+L4+N4+P4+R4+T4+V4+X4+Z4+AB4 -> 38177 | AE4: =G4+I4+K4+M4+O4+Q4+S4+U4+W4+Y4+AA4+AC4 -> 100152250 | AG4: MUSC
A5: 3 | B5: 4971710574852 | C5: MUCI | D5: ONE BY KOSE | E5: ONE BY KOSE PORE CLEAR OIL（Refill） | F5: 610 | G5: 503250 | H5: 1724 | I5: 740850 | J5: 478 | K5: 394350 | L5: 2550 | M5: 2103750 | N5: 4650 | O5: 3836250 | P5: 360 | Q5: 297000 | R5: 4106 | S5: 3387450 | T5: 3695 | U5: 3048375 | V5: 16985 | W5: 14012625 | AD5: =F5+H5+J5+L5+N5+P5+R5+T5+V5+X5+Z5+AB5 -> 35158 | AE5: =G5+I5+K5+M5+O5+Q5+S5+U5+W5+Y5+AA5+AC5 -> 28323900 | AG5: MUCI
A6: 4 | B6: 4971710598711 | C6: DLFP | D6: MKM | E6: MAKE KEEP POWDER ＥＸ | P6: 1152 | Q6: 798336 | R6: 7714 | S6: 5345802 | T6: 11620 | U6: 8052660 | V6: 2976 | W6: 2062368 | AB6: 96 | AC6: 66528 | AD6: =F6+H6+J6+L6+N6+P6+R6+T6+V6+X6+Z6+AB6 -> 23558 | AE6: =G6+I6+K6+M6+O6+Q6+S6+U6+W6+Y6+AA6+AC6 -> 16325694 | AG6: DLIB
A7: 5 | B7: 4971710511505 | C7: DLIB | D7: CCS | E7: CURL KEEP MAGIC | F7: 2800 | G7: 1386000 | H7: 6000 | I7: 1485000 | L7: 2000 | M7: 990000 | N7: 50 | O7: 24750 | R7: 3550 | S7: 1757250 | T7: 2000 | U7: 990000 | V7: 5000 | W7: 2475000 | AD7: =F7+H7+J7+L7+N7+P7+R7+T7+V7+X7+Z7+AB7 -> 21400 | AE7: =G7+I7+K7+M7+O7+Q7+S7+U7+W7+Y7+AA7+AC7 -> 9108000 | AG7: DLFP
A8: 6 | B8: 4971710580044 | C8: DLCE | D8: MKM | E8: MAKE KEEP PRIMER COOL | N8: 60 | O8: 39600 | P8: 1240 | Q8: 818400 | R8: 4000 | S8: 2640000 | T8: 2500 | U8: 1650000 | AD8: =F8+H8+J8+L8+N8+P8+R8+T8+V8+X8+Z8+AB8 -> 7800 | AE8: =G8+I8+K8+M8+O8+Q8+S8+U8+W8+Y8+AA8+AC8 -> 5148000 | AG8: DLCH
A9: 7 | B9: 4971710590500 | C9: DLCH | D9: MKM | E9: MAKE KEEP MIST EX + SAKURA CHERRY | L9: 3600 | M9: 2376000 | N9: 3000 | O9: 1980000 | R9: 100 | S9: 66000 | AD9: =F9+H9+J9+L9+N9+P9+R9+T9+V9+X9+Z9+AB9 -> 6700 | AE9: =G9+I9+K9+M9+O9+Q9+S9+U9+W9+Y9+AA9+AC9 -> 4422000 | AG9: DLCC
A10: 8 | B10: 4971710579291 | C10: DLCC | D10: MKM | E10: MAKE KEEP MIST EX + COOL | N10: 5712 | O10: 3769920 | P10: 744 | Q10: 491040 | AD10: =F10+H10+J10+L10+N10+P10+R10+T10+V10+X10+Z10+AB10 -> 6456 | AE10: =G10+I10+K10+M10+O10+Q10+S10+U10+W10+Y10+AA10+AC10 -> 4260960 | AG10: YNRE001
A11: 9 | B11: 4971710551006 | C11: YNRE001 | D11: VISEE | E11: VISEE ESSENCE LIP PLUMPER SP001 | F11: 1296 | G11: 926640 | H11: 1252 | I11: 447590 | J11: 842 | K11: 602030 | L11: 36 | M11: 25740 | N11: 518 | O11: 370370 | P11: 72 | Q11: 51480 | R11: 354 | S11: 253110 | T11: 600 | U11: 429000 | V11: 1974 | W11: 1411410 | AD11: =F11+H11+J11+L11+N11+P11+R11+T11+V11+X11+Z11+AB11 -> 6944 | AE11: =G11+I11+K11+M11+O11+Q11+S11+U11+W11+Y11+AA11+AC11 -> 4517370 | AG11: DLCE
A12: 10 | B12: 4971710595789 | C12: MUCF | D12: ONE BY KOSE | E12: ONE BY KOSE PORE CLEAR SCRUB WASH | N12: 748 | O12: 740520 | R12: 1150 | S12: 1138500 | V12: 3800 | W12: 3762000 | AD12: =F12+H12+J12+L12+N12+P12+R12+T12+V12+X12+Z12+AB12 -> 5698 | AE12: =G12+I12+K12+M12+O12+Q12+S12+U12+W12+Y12+AA12+AC12 -> 5641020 | AG12: YNCF
A13: 11 | B13: 4971710571837 | C13: YNRE300 | D13: VISEE | E13: VISEE ESSENCE LIP PLUMPER BE300 | F13: 920 | G13: 657800 | H13: 1656 | I13: 592020 | J13: 742 | K13: 530530 | L13: 24 | M13: 17160 | P13: 50 | Q13: 35750 | R13: 12 | S13: 8580 | T13: 42 | U13: 30030 | V13: 798 | W13: 570570 | AB13: 555 | AC13: 396825 | AD13: =F13+H13+J13+L13+N13+P13+R13+T13+V13+X13+Z13+AB13 -> 4799 | AE13: =G13+I13+K13+M13+O13+Q13+S13+U13+W13+Y13+AA13+AC13 -> 2839265 | AG13: YNRE300
A14: 12 | B14: 4971710580600 | C14: MTSW | D14: SEKKISEI | E14: SEKKISEI BRIGHTENING ESSENCE LOTION | N14: 660 | O14: 1706100 | R14: 302 | S14: 780670 | T14: 858 | U14: 2217930 | V14: 1510 | W14: 3903350 | AB14: 620 | AC14: 1670900 | AD14: =F14+H14+J14+L14+N14+P14+R14+T14+V14+X14+Z14+AB14 -> 3950 | AE14: =G14+I14+K14+M14+O14+Q14+S14+U14+W14+Y14+AA14+AC14 -> 10278950 | AG14: DLCJ
A15: 13 | B15: 4971710590524 | C15: DLCJ | D15: MKM | E15: MAKE KEEP POWDER SAKURA CHERRY | L15: 356 | M15: 234960 | N15: 2700 | O15: 1782000 | R15: 700 | S15: 462000 | AD15: =F15+H15+J15+L15+N15+P15+R15+T15+V15+X15+Z15+AB15 -> 3756 | AE15: =G15+I15+K15+M15+O15+Q15+S15+U15+W15+Y15+AA15+AC15 -> 2478960 | AG15: MUCH
A16: 14 | B16: 4971710577341 | C16: MUXA | D16: ONE BY KOSE | E16: ONE BY KOSE SERUM VEIL DEEP REPAIR | F16: 388 | G16: 1067000 | H16: 406 | I16: 574750 | J16: 198 | K16: 544500 | L16: 80 | M16: 220000 | N16: 774 | O16: 2128500 | P16: 54 | Q16: 148500 | R16: 44 | S16: 121000 | T16: 250 | U16: 687500 | V16: 678 | W16: 1864500 | AB16: 480 | AC16: 1425600 | AD16: =F16+H16+J16+L16+N16+P16+R16+T16+V16+X16+Z16+AB16 -> 3352 | AE16: =G16+I16+K16+M16+O16+Q16+S16+U16+W16+Y16+AA16+AC16 -> 8781850 | AG16: DLEB
A17: 15 | B17: 4971710546071 | C17: MUZU | D17: ONE BY KOSE | E17: ONE BY KOSE DEEP HYDRATOR | F17: 488 | G17: 778360 | H17: 272 | I17: 236060 | J17: 154 | K17: 245630 | L17: 122 | M17: 194590 | N17: 600 | O17: 957000 | P17: 30 | Q17: 47850 | R17: 6 | S17: 9570 | T17: 290 | U17: 462550 | V17: 952 | W17: 1518440 | AB17: 240 | AC17: 382800 | AD17: =F17+H17+J17+L17+N17+P17+R17+T17+V17+X17+Z17+AB17 -> 3154 | AE17: =G17+I17+K17+M17+O17+Q17+S17+U17+W17+Y17+AA17+AC17 -> 4832850 | AG17: YNXX006
A18: 16 | B18: 4971710580396 | C18: MUXD | D18: ONE BY KOSE | E18: ONE BY KOSE SERUM VEIL DEEP REPAIR | F18: 320 | G18: 1460800 | H18: 464 | I18: 1168640 | J18: 310 | K18: 1415150 | L18: 120 | M18: 547800 | N18: 531 | O18: 2424015 | P18: 80 | Q18: 365200 | R18: 6 | S18: 27390 | T18: 200 | U18: 913000 | V18: 1102 | W18: 5030630 | AB18: 48 | AC18: 237600 | AD18: =F18+H18+J18+L18+N18+P18+R18+T18+V18+X18+Z18+AB18 -> 3181 | AE18: =G18+I18+K18+M18+O18+Q18+S18+U18+W18+Y18+AA18+AC18 -> 13590225 | AG18: MUCF
A19: 17 | B19: 4971710539189 | C19: YNCF | D19: VISEE | E19: VISEE RED TRICK EYE CONCEALER | F19: 1329 | G19: 804045 | H19: 904 | I19: 273460 | J19: 302 | K19: 182710 | L19: 24 | M19: 14520 | N19: 802 | O19: 485210 | P19: 53 | Q19: 32065 | AD19: =F19+H19+J19+L19+N19+P19+R19+T19+V19+X19+Z19+AB19 -> 3414 | AE19: =G19+I19+K19+M19+O19+Q19+S19+U19+W19+Y19+AA19+AC19 -> 1792010 | AG19: DLEP
A20: 18 | B20: 4971710576573 | C20: DLEB | D20: MKM | E20: MAKE KEEP MIST EX +＜35mL＞ | F20: 882 | G20: 388080 | H20: 232 | I20: 51040 | J20: 11 | K20: 4840 | L20: 502 | M20: 220880 | N20: 28 | O20: 12320 | P20: 168 | Q20: 73920 | R20: 152 | S20: 66880 | T20: 192 | U20: 84480 | V20: 810 | W20: 356400 | AB20: 83 | AC20: 39259 | AD20: =F20+H20+J20+L20+N20+P20+R20+T20+V20+X20+Z20+AB20 -> 3060 | AE20: =G20+I20+K20+M20+O20+Q20+S20+U20+W20+Y20+AA20+AC20 -> 1298099 | AG20: MUXA
A21: 19 | B21: 4971710588163 | C21: DLSC | D21: CCS | E21: SUPER UV PROTECTOR | L21: 32 | M21: 22880 | P21: 122 | Q21: 87230 | R21: 200 | S21: 143000 | T21: 20 | U21: 14300 | V21: 2483 | W21: 1775345 | AB21: 30 | AC21: 21450 | AD21: =F21+H21+J21+L21+N21+P21+R21+T21+V21+X21+Z21+AB21 -> 2887 | AE21: =G21+I21+K21+M21+O21+Q21+S21+U21+W21+Y21+AA21+AC21 -> 2064205 | AG21: =VLOOKUP(AF21,[1]OBK!$E:$F,2,0) -> 0
A22: 20 | B22: 4971710595543 | C22: YNXX006 | D22: VISEE | E22: VISEE W MOOD EYES BL-6 | H22: 1080 | I22: 415800 | J22: 400 | K22: 308000 | L22: 490 | M22: 377300 | N22: 365 | O22: 281050 | P22: 358 | Q22: 275660 | R22: 90 | S22: 69300 | T22: 50 | U22: 38500 | V22: 210 | W22: 161700 | AB22: 120 | AC22: 92400 | AD22: =F22+H22+J22+L22+N22+P22+R22+T22+V22+X22+Z22+AB22 -> 3163 | AE22: =G22+I22+K22+M22+O22+Q22+S22+U22+W22+Y22+AA22+AC22 -> 2019710 | AG22: MUXD
A23: 21 | B23: 4971710576641 | C23: MUPE | D23: ONE BY KOSE | E23: ONE BY KOSE CLEAR PEEL SERUM | F23: 130 | G23: 235950 | H23: 124 | I23: 123420 | J23: 74 | K23: 134310 | L23: 135 | M23: 245025 | N23: 634 | O23: 1150710 | P23: 80 | Q23: 145200 | R23: 2 | S23: 3630 | T23: 126 | U23: 228690 | V23: 1282 | W23: 2326830 | AD23: =F23+H23+J23+L23+N23+P23+R23+T23+V23+X23+Z23+AB23 -> 2587 | AE23: =G23+I23+K23+M23+O23+Q23+S23+U23+W23+Y23+AA23+AC23 -> 4593765 | AG23: YNYK005
A24: 22 | B24: 4971710549812 | C24: MSYN | D24: VISEE | E24: ONE BY KOSE MELANOSHOT W | F24: 120 | G24: 455400 | H24: 192 | I24: 409860 | J24: 139 | K24: 527505 | L24: 170 | M24: 645150 | N24: 157 | O24: 595815 | P24: 104 | Q24: 394680 | R24: 190 | S24: 721050 | T24: 260 | U24: 986700 | V24: 1196 | W24: 4538820 | AD24: =F24+H24+J24+L24+N24+P24+R24+T24+V24+X24+Z24+AB24 -> 2528 | AE24: =G24+I24+K24+M24+O24+Q24+S24+U24+W24+Y24+AA24+AC24 -> 9274980 | AG24: MUPE
A25: 23 | B25: 4971710580372 | C25: MUXC | D25: ONE BY KOSE | E25: ONE BY KOSE SERUM VEIL DEEP REPAIR | F25: 320 | G25: 844800 | H25: 266 | I25: 359040 | J25: 68 | K25: 179520 | L25: 50 | M25: 132000 | P25: 628 | Q25: 1657920 | R25: 68 | S25: 179520 | T25: 120 | U25: 316800 | V25: 848 | W25: 2238720 | AB25: 60 | AC25: 171600 | AD25: =F25+H25+J25+L25+N25+P25+R25+T25+V25+X25+Z25+AB25 -> 2428 | AE25: =G25+I25+K25+M25+O25+Q25+S25+U25+W25+Y25+AA25+AC25 -> 6079920 | AG25: DXPO000
A26: 24 | B26: 4971710557787 | C26: DXPO000 | D26: FASIO | E26: FASIO PORE SMOOTH PRIMER 00 | F26: 224 | G26: 110880 | H26: 12 | I26: 2970 | J26: 150 | K26: 74250 | L26: 282 | M26: 139590 | N26: 150 | O26: 74250 | P26: 62 | Q26: 30690 | R26: 226 | S26: 111870 | T26: 302 | U26: 149490 | V26: 548 | W26: 271260 | AB26: 312 | AC26: 154440 | AD26: =F26+H26+J26+L26+N26+P26+R26+T26+V26+X26+Z26+AB26 -> 2268 | AE26: =G26+I26+K26+M26+O26+Q26+S26+U26+W26+Y26+AA26+AC26 -> 1119690 | AG26: MUXC
A27: 25 | B27: 4971710549782 | C27: MSYJ | D27: ONE BY KOSE | E27: ONE BY KOSE MELANOSHOT W | F27: 230 | G27: 670450 | H27: 100 | I27: 145750 | J27: 118 | K27: 343970 | L27: 100 | M27: 291500 | N27: 60 | O27: 174900 | P27: 88 | Q27: 256520 | R27: 197 | S27: 574255 | T27: 235 | U27: 685025 | V27: 1171 | W27: 3413465 | AD27: =F27+H27+J27+L27+N27+P27+R27+T27+V27+X27+Z27+AB27 -> 2299 | AE27: =G27+I27+K27+M27+O27+Q27+S27+U27+W27+Y27+AA27+AC27 -> 6555835 | AG27: MUPD
A28: 26 | B28: 4971710522839 | C28: DLID | D28: CCS | E28: CURL KEEP MAGIC ESSENCE REMOVER | F28: 120 | G28: 52800 | J28: 160 | K28: 70400 | L28: 200 | M28: 88000 | R28: 300 | S28: 132000 | T28: 300 | U28: 132000 | V28: 1100 | W28: 484000 | AD28: =F28+H28+J28+L28+N28+P28+R28+T28+V28+X28+Z28+AB28 -> 2180 | AE28: =G28+I28+K28+M28+O28+Q28+S28+U28+W28+Y28+AA28+AC28 -> 959200 | AG28: YNGC001
A29: 27 | B29: 4971710592955 | C29: YNGC001 | D29: VISEE | E29: VISEE COLOR DUO TRICK CONCEALER 01 | F29: 65 | G29: 39325 | H29: 650 | I29: 196625 | J29: 39 | K29: 23595 | L29: 341 | M29: 206305 | N29: 32 | O29: 19360 | R29: 436 | S29: 263780 | T29: 30 | U29: 18150 | AB29: 786 | AC29: 475530 | AD29: =F29+H29+J29+L29+N29+P29+R29+T29+V29+X29+Z29+AB29 -> 2379 | AE29: =G29+I29+K29+M29+O29+Q29+S29+U29+W29+Y29+AA29+AC29 -> 1242670 | AG29: MSYN
A30: 28 | B30: 4971710573992 | C30: MTSE | D30: SEKKISEI | E30: SEKKISEI BRIGHTENING ESSENCE LOTION | N30: 237 | O30: 703890 | P30: 20 | Q30: 59400 | R30: 150 | S30: 445500 | T30: 635 | U30: 1885950 | V30: 903 | W30: 2681910 | AB30: 79 | AC30: 252010 | AD30: =F30+H30+J30+L30+N30+P30+R30+T30+V30+X30+Z30+AB30 -> 2024 | AE30: =G30+I30+K30+M30+O30+Q30+S30+U30+W30+Y30+AA30+AC30 -> 6028660 | AG30: MUWI
A31: 29 | B31: 4971710573855 | C31: MTSC | D31: SEKKISEI | E31: SEKKISEI BRIGHTENING ESSENCE LOTION | N31: 270 | O31: 519750 | R31: 162 | S31: 311850 | T31: 372 | U31: 716100 | V31: 915 | W31: 1761375 | AB31: 129 | AC31: 269610 | AD31: =F31+H31+J31+L31+N31+P31+R31+T31+V31+X31+Z31+AB31 -> 1848 | AE31: =G31+I31+K31+M31+O31+Q31+S31+U31+W31+Y31+AA31+AC31 -> 3578685 | AG31: MSYJ
A32: 30 | B32: 4971710576634 | C32: MUPD | D32: ONE BY KOSE | E32: ONE BY KOSE CLEAR PEEL SERUM | F32: 195 | G32: 375375 | H32: 152 | I32: 157850 | J32: 6 | K32: 11550 | L32: 70 | M32: 134750 | N32: 597 | O32: 1149225 | P32: 18 | Q32: 34650 | R32: 16 | S32: 30800 | T32: 120 | U32: 231000 | V32: 656 | W32: 1262800 | AB32: 61 | AC32: 117425 | AD32: =F32+H32+J32+L32+N32+P32+R32+T32+V32+X32+Z32+AB32 -> 1891 | AE32: =G32+I32+K32+M32+O32+Q32+S32+U32+W32+Y32+AA32+AC32 -> 3505425 | AG32: YNBX
A33: 31 | B33: 4971710571868 | C33: MTSD | D33: SEKKISEI | E33: SEKKISEI BRIGHTENING EMULSION | N33: 274 | O33: 572660 | P33: 20 | Q33: 41800 | R33: 6 | S33: 12540 | T33: 600 | U33: 1254000 | V33: 683 | W33: 1427470 | AB33: 205 | AC33: 462275 | AD33: =F33+H33+J33+L33+N33+P33+R33+T33+V33+X33+Z33+AB33 -> 1788 | AE33: =G33+I33+K33+M33+O33+Q33+S33+U33+W33+Y33+AA33+AC33 -> 3770745 | AG33: MSYK
A34: 32 | B34: 4971710561395 | C34: MUCH | D34: ONE BY KOSE | E34: ONE BY KOSE PORE CLEAR OIL | F34: 394 | G34: 390060 | H34: 480 | I34: 249480 | J34: 250 | K34: 247500 | L34: 676 | M34: 669240 | P34: 131 | Q34: 129690 | T34: 6 | U34: 5940 | V34: 6 | W34: 5940 | AD34: =F34+H34+J34+L34+N34+P34+R34+T34+V34+X34+Z34+AB34 -> 1943 | AE34: =G34+I34+K34+M34+O34+Q34+S34+U34+W34+Y34+AA34+AC34 -> 1697850 | AG34: DLID
A35: 33 | B35: 4971710568899 | C35: MUWI | D35: ONE BY KOSE | E35: ONE BY KOSE WRINKLE DOUBLE REPAIR | F35: 30 | G35: 44550 | H35: 156 | I35: 124740 | J35: 112 | K35: 166320 | L35: 46 | M35: 68310 | N35: 626 | O35: 929610 | P35: 60 | Q35: 89100 | R35: 2 | S35: 2970 | T35: 48 | U35: 71280 | V35: 646 | W35: 959310 | AB35: 100 | AC35: 148500 | AD35: =F35+H35+J35+L35+N35+P35+R35+T35+V35+X35+Z35+AB35 -> 1826 | AE35: =G35+I35+K35+M35+O35+Q35+S35+U35+W35+Y35+AA35+AC35 -> 2604690 | AG35: DXJC002
A36: 34 | B36: 4971710549805 | C36: MSYK | D36: ONE BY KOSE | E36: ONE BY KOSE MELANOSHOT W | F36: 317 | G36: 871750 | H36: 124 | I36: 203500 | J36: 70 | K36: 192500 | L36: 30 | M36: 82500 | N36: 311 | O36: 855250 | P36: 6 | Q36: 16500 | R36: 47 | S36: 129250 | V36: 649 | W36: 1784750 | AD36: =F36+H36+J36+L36+N36+P36+R36+T36+V36+X36+Z36+AB36 -> 1554 | AE36: =G36+I36+K36+M36+O36+Q36+S36+U36+W36+Y36+AA36+AC36 -> 4136000 | AG36: YNST300
A37: 35 | B37: 4971710581928 | C37: MTSX | D37: SEKKISEI | E37: SEKKISEI BRIGHTENING EMULSION | N37: 462 | O37: 813120 | P37: 20 | Q37: 35200 | R37: 12 | S37: 21120 | T37: 320 | U37: 563200 | V37: 508 | W37: 894080 | AB37: 177 | AC37: 330990 | AD37: =F37+H37+J37+L37+N37+P37+R37+T37+V37+X37+Z37+AB37 -> 1499 | AE37: =G37+I37+K37+M37+O37+Q37+S37+U37+W37+Y37+AA37+AC37 -> 2657710 | AG37: =VLOOKUP(AF37,[2]SEK!$E:$F,2,0) -> 0
A38: 36 | B38: 4971710556827 | C38: YNFB001 | D38: VISEE | E38: VISEE GLOW BALM FOUNDATION 01 | F38: 65 | G38: 64350 | H38: 204 | I38: 100980 | J38: 230 | K38: 227700 | L38: 30 | M38: 29700 | N38: 62 | O38: 61380 | P38: 9 | Q38: 8910 | R38: 4 | S38: 3960 | T38: 60 | U38: 59400 | V38: 475 | W38: 470250 | AB38: 154 | AC38: 152460 | AD38: =F38+H38+J38+L38+N38+P38+R38+T38+V38+X38+Z38+AB38 -> 1293 | AE38: =G38+I38+K38+M38+O38+Q38+S38+U38+W38+Y38+AA38+AC38 -> 1179090 | AG38: YNFB001
A39: 37 | B39: 4971710524055 | C39: YNBX | D39: VISEE | E39: VISEE EYEBROW ENHANCER | F39: 291 | G39: 176055 | H39: 244 | I39: 73810 | J39: 250 | K39: 151250 | L39: 6 | M39: 3630 | N39: 40 | O39: 24200 | P39: 100 | Q39: 60500 | R39: 40 | S39: 24200 | T39: 100 | U39: 60500 | V39: 200 | W39: 121000 | AB39: 140 | AC39: 84700 | AD39: =F39+H39+J39+L39+N39+P39+R39+T39+V39+X39+Z39+AB39 -> 1411 | AE39: =G39+I39+K39+M39+O39+Q39+S39+U39+W39+Y39+AA39+AC39 -> 779845 | AG39: =VLOOKUP(AF39,[1]OBK!$E:$F,2,0) -> 0
A40: 38 | B40: 4971710595529 | C40: YNXX004 | D40: VISEE | E40: VISEE W MOOD EYES OR-4 | H40: 58 | I40: 22330 | J40: 136 | K40: 104720 | L40: 174 | M40: 133980 | N40: 165 | O40: 127050 | P40: 242 | Q40: 186340 | R40: 194 | S40: 149380 | V40: 206 | W40: 158620 | AB40: 126 | AC40: 97020 | AD40: =F40+H40+J40+L40+N40+P40+R40+T40+V40+X40+Z40+AB40 -> 1301 | AE40: =G40+I40+K40+M40+O40+Q40+S40+U40+W40+Y40+AA40+AC40 -> 979440 | AG40: YNXX004
...

Sheet 2407から
A1: No. | B1: JANコード | C1: 商品符号 | D1: ブランド | E1: 商品名称 | F1: 2407 | H1: 2408 | J1: 2409 | L1: 2410 | N1: 2411 | P1: 2412 | R1: 2501 | T1: 2502 | V1: 2503 | X1: 2504 | Z1: 2505 | AB1: 2506 | AD1: 2507 | AF1: 2508 | AH1: 2509 | AJ1: 2510 | AL1: 2511 | AN1: 2512 | AP1: 合計
F2: 数量 | G2: 金額 | H2: 数量 | I2: 金額 | J2: 数量 | K2: 金額 | L2: 数量 | M2: 金額 | N2: 数量 | O2: 金額 | P2: 数量 | Q2: 金額 | R2: 数量 | S2: 金額 | T2: 数量 | U2: 金額 | V2: 数量 | W2: 金額 | X2: 数量 | Y2: 金額 | Z2: 数量 | AA2: 金額 | AB2: 数量 | AC2: 金額 | AD2: 数量 | AE2: 金額 | AF2: 数量 | AG2: 金額 | AH2: 数量 | AI2: 金額 | AJ2: 数量 | AK2: 金額 | AL2: 数量 | AM2: 金額 | AN2: 数量 | AO2: 金額 | AP2: 数量 | AQ2: 金額
A3: 1 | B3: 4971710576306 | C3: DLEA | D3: MAKE KEEP | E3: MAKE KEEP MIST EX + | F3: 0 | G3: 0 | H3: 130 | I3: 85800 | J3: 40 | K3: 26400 | L3: 142 | M3: 93720 | N3: 318 | O3: 209880 | P3: 0 | Q3: 0 | R3: 2020 | S3: 1333200 | T3: 2944 | U3: 1631520 | V3: 8316 | W3: 5488560 | X3: 12276 | Y3: 8102160 | Z3: 20201 | AA3: 13332660 | AB3: 13848 | AC3: 9139680 | AD3: 31222 | AE3: 20606520 | AF3: 26000 | AG3: 17160000 | AH3: 64352 | AI3: 42472320 | AP3: =F3+H3+J3+L3+N3+P3+R3+T3+V3+X3+Z3+AB3+AD3+AF3+AH3+AJ3+AL3+AN3 -> 181809 | AQ3: =G3+I3+K3+M3+O3+Q3+S3+U3+W3+Y3+AA3+AC3+AE3+AG3+AI3+AK3+AM3+AO3 -> 119682420
A4: 2 | B4: 4971710565065 | C4: MUSC | D4: ONE BY KOSE | E4: ONE BY KOSE SERUM SHIELD | F4: 40 | G4: 110000 | H4: 165 | I4: 453750 | J4: 30 | K4: 82500 | L4: 190 | M4: 522500 | N4: 903 | O4: 2483250 | P4: 1120 | Q4: 3080000 | R4: 3342 | S4: 9190500 | T4: 3836 | U4: 5714500 | V4: 926 | W4: 2546500 | X4: 2212 | Y4: 6083000 | Z4: 5987 | AA4: 16464250 | AB4: 1120 | AC4: 3080000 | AD4: 2598 | AE4: 7144500 | AF4: 1700 | AG4: 4675000 | AH4: 16456 | AI4: 45254000 | AP4: =F4+H4+J4+L4+N4+P4+R4+T4+V4+X4+Z4+AB4+AD4+AF4+AH4+AJ4+AL4+AN4 -> 40625 | AQ4: =G4+I4+K4+M4+O4+Q4+S4+U4+W4+Y4+AA4+AC4+AE4+AG4+AI4+AK4+AM4+AO4 -> 106884250
A5: 3 | B5: 4971710574852 | C5: MUCI | D5: ONE BY KOSE | E5: ONE BY KOSE PORE CLEAR OIL（Refill） | F5: 0 | G5: 0 | H5: 60 | I5: 49500 | J5: 0 | K5: 0 | L5: 45 | M5: 37125 | N5: 320 | O5: 264000 | P5: 680 | Q5: 561000 | R5: 610 | S5: 503250 | T5: 1724 | U5: 740850 | V5: 478 | W5: 394350 | X5: 2550 | Y5: 2103750 | Z5: 4650 | AA5: 3836250 | AB5: 360 | AC5: 297000 | AD5: 4106 | AE5: 3387450 | AF5: 3695 | AG5: 3048375 | AH5: 16985 | AI5: 14012625 | AP5: =F5+H5+J5+L5+N5+P5+R5+T5+V5+X5+Z5+AB5+AD5+AF5+AH5+AJ5+AL5+AN5 -> 36263 | AQ5: =G5+I5+K5+M5+O5+Q5+S5+U5+W5+Y5+AA5+AC5+AE5+AG5+AI5+AK5+AM5+AO5 -> 29235525
A6: 4 | B6: 4971710598711 | C6: DLFP | D6: MAKE KEEP | E6: MAKE KEEP POWDER ＥＸ | F6: 0 | G6: 0 | H6: 0 | I6: 0 | J6: 0 | K6: 0 | L6: 0 | M6: 0 | N6: 0 | O6: 0 | P6: 0 | Q6: 0 | AB6: 1152 | AC6: 798336 | AD6: 7714 | AE6: 5345802 | AF6: 11620 | AG6: 8052660 | AH6: 2976 | AI6: 2062368 | AN6: 96 | AO6: 66528 | AP6: =F6+H6+J6+L6+N6+P6+R6+T6+V6+X6+Z6+AB6+AD6+AF6+AH6+AJ6+AL6+AN6 -> 23558 | AQ6: =G6+I6+K6+M6+O6+Q6+S6+U6+W6+Y6+AA6+AC6+AE6+AG6+AI6+AK6+AM6+AO6 -> 16325694
A7: 5 | B7: 4971710511505 | C7: DLIB | D7: その他CCS | E7: CURL KEEP MAGIC | F7: 0 | G7: 0 | H7: 10 | I7: 4950 | J7: 30 | K7: 14850 | L7: 0 | M7: 0 | N7: 360 | O7: 178200 | P7: 0 | Q7: 0 | R7: 2800 | S7: 1386000 | T7: 6000 | U7: 1485000 | X7: 2000 | Y7: 990000 | Z7: 50 | AA7: 24750 | AD7: 3550 | AE7: 1757250 | AF7: 2000 | AG7: 990000 | AH7: 5000 | AI7: 2475000 | AP7: =F7+H7+J7+L7+N7+P7+R7+T7+V7+X7+Z7+AB7+AD7+AF7+AH7+AJ7+AL7+AN7 -> 21800 | AQ7: =G7+I7+K7+M7+O7+Q7+S7+U7+W7+Y7+AA7+AC7+AE7+AG7+AI7+AK7+AM7+AO7 -> 9306000
A8: 9 | B8: 4971710551006 | C8: YNRE001 | D8: VISEE | E8: VISEE ESSENCE LIP PLUMPER SP001 | F8: 1510 | G8: 1079650 | H8: 54 | I8: 38610 | J8: 24 | K8: 17160 | L8: 66 | M8: 47190 | N8: 810 | O8: 579150 | P8: 90 | Q8: 64350 | R8: 1296 | S8: 926640 | T8: 1252 | U8: 447590 | V8: 842 | W8: 602030 | X8: 36 | Y8: 25740 | Z8: 518 | AA8: 370370 | AB8: 72 | AC8: 51480 | AD8: 354 | AE8: 253110 | AF8: 600 | AG8: 429000 | AH8: 1974 | AI8: 1411410 | AP8: =F8+H8+J8+L8+N8+P8+R8+T8+V8+X8+Z8+AB8+AD8+AF8+AH8+AJ8+AL8+AN8 -> 9498 | AQ8: =G8+I8+K8+M8+O8+Q8+S8+U8+W8+Y8+AA8+AC8+AE8+AG8+AI8+AK8+AM8+AO8 -> 6343480
A9: 6 | B9: 4971710580044 | C9: DLCE | D9: MAKE KEEP | E9: MAKE KEEP PRIMER COOL | F9: 0 | G9: 0 | H9: 15 | I9: 9900 | J9: 0 | K9: 0 | L9: 0 | M9: 0 | N9: 0 | O9: 0 | P9: 0 | Q9: 0 | Z9: 60 | AA9: 39600 | AB9: 1240 | AC9: 818400 | AD9: 4000 | AE9: 2640000 | AF9: 2500 | AG9: 1650000 | AP9: =F9+H9+J9+L9+N9+P9+R9+T9+V9+X9+Z9+AB9+AD9+AF9+AH9+AJ9+AL9+AN9 -> 7815 | AQ9: =G9+I9+K9+M9+O9+Q9+S9+U9+W9+Y9+AA9+AC9+AE9+AG9+AI9+AK9+AM9+AO9 -> 5157900
A10: 7 | B10: 4971710590500 | C10: DLCH | D10: MAKE KEEP | E10: MAKE KEEP MIST EX + SAKURA CHERRY | F10: 0 | G10: 0 | H10: 0 | I10: 0 | J10: 0 | K10: 0 | L10: 0 | M10: 0 | N10: 0 | O10: 0 | P10: 0 | Q10: 0 | X10: 3600 | Y10: 2376000 | Z10: 3000 | AA10: 1980000 | AD10: 100 | AE10: 66000 | AP10: =F10+H10+J10+L10+N10+P10+R10+T10+V10+X10+Z10+AB10+AD10+AF10+AH10+AJ10+AL10+AN10 -> 6700 | AQ10: =G10+I10+K10+M10+O10+Q10+S10+U10+W10+Y10+AA10+AC10+AE10+AG10+AI10+AK10+AM10+AO10 -> 4422000
A11: 8 | B11: 4971710579291 | C11: DLCC | D11: MAKE KEEP | E11: MAKE KEEP MIST EX + COOL | F11: 0 | G11: 0 | H11: 0 | I11: 0 | J11: 0 | K11: 0 | L11: 0 | M11: 0 | N11: 0 | O11: 0 | P11: 0 | Q11: 0 | Z11: 5712 | AA11: 3769920 | AB11: 744 | AC11: 491040 | AP11: =F11+H11+J11+L11+N11+P11+R11+T11+V11+X11+Z11+AB11+AD11+AF11+AH11+AJ11+AL11+AN11 -> 6456 | AQ11: =G11+I11+K11+M11+O11+Q11+S11+U11+W11+Y11+AA11+AC11+AE11+AG11+AI11+AK11+AM11+AO11 -> 4260960
A12: 11 | B12: 4971710571837 | C12: YNRE300 | D12: VISEE | E12: VISEE ESSENCE LIP PLUMPER BE300 | F12: 510 | G12: 364650 | H12: 34 | I12: 24310 | J12: 24 | K12: 17160 | L12: 461 | M12: 329615 | N12: 270 | O12: 193050 | P12: 190 | Q12: 135850 | R12: 920 | S12: 657800 | T12: 1656 | U12: 592020 | V12: 742 | W12: 530530 | X12: 24 | Y12: 17160 | AB12: 50 | AC12: 35750 | AD12: 12 | AE12: 8580 | AF12: 42 | AG12: 30030 | AH12: 798 | AI12: 570570 | AN12: 555 | AO12: 396825 | AP12: =F12+H12+J12+L12+N12+P12+R12+T12+V12+X12+Z12+AB12+AD12+AF12+AH12+AJ12+AL12+AN12 -> 6288 | AQ12: =G12+I12+K12+M12+O12+Q12+S12+U12+W12+Y12+AA12+AC12+AE12+AG12+AI12+AK12+AM12+AO12 -> 3903900
A13: 10 | B13: 4971710595789 | C13: MUCF | D13: ONE BY KOSE | E13: ONE BY KOSE PORE CLEAR SCRUB WASH | F13: 0 | G13: 0 | H13: 0 | I13: 0 | J13: 0 | K13: 0 | L13: 0 | M13: 0 | N13: 0 | O13: 0 | P13: 0 | Q13: 0 | Z13: 748 | AA13: 740520 | AD13: 1150 | AE13: 1138500 | AH13: 3800 | AI13: 3762000 | AP13: =F13+H13+J13+L13+N13+P13+R13+T13+V13+X13+Z13+AB13+AD13+AF13+AH13+AJ13+AL13+AN13 -> 5698 | AQ13: =G13+I13+K13+M13+O13+Q13+S13+U13+W13+Y13+AA13+AC13+AE13+AG13+AI13+AK13+AM13+AO13 -> 5641020
A14: 17 | B14: 4971710539189 | C14: YNCF | D14: VISEE | E14: VISEE RED TRICK EYE CONCEALER | F14: 730 | G14: 441650 | H14: 299 | I14: 180895 | J14: 24 | K14: 14520 | L14: 12 | M14: 7260 | N14: 390 | O14: 235950 | P14: 235 | Q14: 142175 | R14: 1329 | S14: 804045 | T14: 904 | U14: 273460 | V14: 302 | W14: 182710 | X14: 24 | Y14: 14520 | Z14: 802 | AA14: 485210 | AB14: 53 | AC14: 32065 | AP14: =F14+H14+J14+L14+N14+P14+R14+T14+V14+X14+Z14+AB14+AD14+AF14+AH14+AJ14+AL14+AN14 -> 5104 | AQ14: =G14+I14+K14+M14+O14+Q14+S14+U14+W14+Y14+AA14+AC14+AE14+AG14+AI14+AK14+AM14+AO14 -> 2814460
A15: 12 | B15: 4971710580600 | C15: MTSW | D15: SEKKISEI | E15: SEKKISEI BRIGHTENING ESSENCE LOTION | F15: 0 | G15: 0 | H15: 0 | I15: 0 | J15: 0 | K15: 0 | L15: 0 | M15: 0 | N15: 0 | O15: 0 | P15: 0 | Q15: 0 | Z15: 660 | AA15: 1706100 | AD15: 302 | AE15: 780670 | AF15: 858 | AG15: 2217930 | AH15: 1510 | AI15: 3903350 | AN15: 620 | AO15: 1670900 | AP15: =F15+H15+J15+L15+N15+P15+R15+T15+V15+X15+Z15+AB15+AD15+AF15+AH15+AJ15+AL15+AN15 -> 3950 | AQ15: =G15+I15+K15+M15+O15+Q15+S15+U15+W15+Y15+AA15+AC15+AE15+AG15+AI15+AK15+AM15+AO15 -> 10278950
A16: 13 | B16: 4971710590524 | C16: DLCJ | D16: MAKE KEEP | E16: MAKE KEEP POWDER SAKURA CHERRY | F16: 0 | G16: 0 | H16: 0 | I16: 0 | J16: 0 | K16: 0 | L16: 0 | M16: 0 | N16: 0 | O16: 0 | P16: 0 | Q16: 0 | X16: 356 | Y16: 234960 | Z16: 2700 | AA16: 1782000 | AD16: 700 | AE16: 462000 | AP16: =F16+H16+J16+L16+N16+P16+R16+T16+V16+X16+Z16+AB16+AD16+AF16+AH16+AJ16+AL16+AN16 -> 3756 | AQ16: =G16+I16+K16+M16+O16+Q16+S16+U16+W16+Y16+AA16+AC16+AE16+AG16+AI16+AK16+AM16+AO16 -> 2478960
A17: 18 | B17: 4971710576573 | C17: DLEB | D17: MAKE KEEP | E17: MAKE KEEP MIST EX +＜35mL＞ | F17: 0 | G17: 0 | H17: 375 | I17: 165000 | J17: 30 | K17: 13200 | L17: 0 | M17: 0 | N17: 72 | O17: 31680 | P17: 10 | Q17: 4400 | R17: 882 | S17: 388080 | T17: 232 | U17: 51040 | V17: 11 | W17: 4840 | X17: 502 | Y17: 220880 | Z17: 28 | AA17: 12320 | AB17: 168 | AC17: 73920 | AD17: 152 | AE17: 66880 | AF17: 192 | AG17: 84480 | AH17: 810 | AI17: 356400 | AN17: 83 | AO17: 39259 | AP17: =F17+H17+J17+L17+N17+P17+R17+T17+V17+X17+Z17+AB17+AD17+AF17+AH17+AJ17+AL17+AN17 -> 3547 | AQ17: =G17+I17+K17+M17+O17+Q17+S17+U17+W17+Y17+AA17+AC17+AE17+AG17+AI17+AK17+AM17+AO17 -> 1512379
A18: 14 | B18: 4971710577341 | C18: MUXA | D18: ONE BY KOSE | E18: ONE BY KOSE SERUM VEIL DEEP REPAIR | F18: 0 | G18: 0 | H18: 0 | I18: 0 | J18: 10 | K18: 27500 | L18: 5 | M18: 13750 | N18: 30 | O18: 82500 | P18: 0 | Q18: 0 | R18: 388 | S18: 1067000 | T18: 406 | U18: 574750 | V18: 198 | W18: 544500 | X18: 80 | Y18: 220000 | Z18: 774 | AA18: 2128500 | AB18: 54 | AC18: 148500 | AD18: 44 | AE18: 121000 | AF18: 250 | AG18: 687500 | AH18: 678 | AI18: 1864500 | AN18: 480 | AO18: 1425600 | AP18: =F18+H18+J18+L18+N18+P18+R18+T18+V18+X18+Z18+AB18+AD18+AF18+AH18+AJ18+AL18+AN18 -> 3397 | AQ18: =G18+I18+K18+M18+O18+Q18+S18+U18+W18+Y18+AA18+AC18+AE18+AG18+AI18+AK18+AM18+AO18 -> 8905600
A19: 15 | B19: 4971710546071 | C19: MUZU | D19: ONE BY KOSE | E19: ONE BY KOSE DEEP HYDRATOR | F19: 0 | G19: 0 | H19: 40 | I19: 63800 | J19: 0 | K19: 0 | L19: 50 | M19: 79750 | N19: 30 | O19: 47850 | P19: 102 | Q19: 162690 | R19: 488 | S19: 778360 | T19: 272 | U19: 236060 | V19: 154 | W19: 245630 | X19: 122 | Y19: 194590 | Z19: 600 | AA19: 957000 | AB19: 30 | AC19: 47850 | AD19: 6 | AE19: 9570 | AF19: 290 | AG19: 462550 | AH19: 952 | AI19: 1518440 | AN19: 240 | AO19: 382800 | AP19: =F19+H19+J19+L19+N19+P19+R19+T19+V19+X19+Z19+AB19+AD19+AF19+AH19+AJ19+AL19+AN19 -> 3376 | AQ19: =G19+I19+K19+M19+O19+Q19+S19+U19+W19+Y19+AA19+AC19+AE19+AG19+AI19+AK19+AM19+AO19 -> 5186940
A20: 16 | B20: 4971710580396 | C20: MUXD | D20: ONE BY KOSE | E20: ONE BY KOSE SERUM VEIL DEEP REPAIR | F20: 0 | G20: 0 | H20: 20 | I20: 91300 | J20: 10 | K20: 45650 | L20: 35 | M20: 159775 | N20: 30 | O20: 136950 | P20: 0 | Q20: 0 | R20: 320 | S20: 1460800 | T20: 464 | U20: 1168640 | V20: 310 | W20: 1415150 | X20: 120 | Y20: 547800 | Z20: 531 | AA20: 2424015 | AB20: 80 | AC20: 365200 | AD20: 6 | AE20: 27390 | AF20: 200 | AG20: 913000 | AH20: 1102 | AI20: 5030630 | AN20: 48 | AO20: 237600 | AP20: =F20+H20+J20+L20+N20+P20+R20+T20+V20+X20+Z20+AB20+AD20+AF20+AH20+AJ20+AL20+AN20 -> 3276 | AQ20: =G20+I20+K20+M20+O20+Q20+S20+U20+W20+Y20+AA20+AC20+AE20+AG20+AI20+AK20+AM20+AO20 -> 14023900
A21: 20 | B21: 4971710595543 | C21: YNXX006 | D21: VISEE | E21: VISEE W MOOD EYES BL-6 | F21: 0 | G21: 0 | H21: 0 | I21: 0 | J21: 0 | K21: 0 | L21: 0 | M21: 0 | N21: 0 | O21: 0 | P21: 0 | Q21: 0 | T21: 1080 | U21: 415800 | V21: 400 | W21: 308000 | X21: 490 | Y21: 377300 | Z21: 365 | AA21: 281050 | AB21: 358 | AC21: 275660 | AD21: 90 | AE21: 69300 | AF21: 50 | AG21: 38500 | AH21: 210 | AI21: 161700 | AN21: 120 | AO21: 92400 | AP21: =F21+H21+J21+L21+N21+P21+R21+T21+V21+X21+Z21+AB21+AD21+AF21+AH21+AJ21+AL21+AN21 -> 3163 | AQ21: =G21+I21+K21+M21+O21+Q21+S21+U21+W21+Y21+AA21+AC21+AE21+AG21+AI21+AK21+AM21+AO21 -> 2019710
A22: 19 | B22: 4971710588163 | C22: DLSC | D22: その他CCS | E22: SUPER UV PROTECTOR | F22: 0 | G22: 0 | H22: 0 | I22: 0 | J22: 0 | K22: 0 | L22: 0 | M22: 0 | N22: 0 | O22: 0 | P22: 0 | Q22: 0 | X22: 32 | Y22: 22880 | AB22: 122 | AC22: 87230 | AD22: 200 | AE22: 143000 | AF22: 20 | AG22: 14300 | AH22: 2483 | AI22: 1775345 | AN22: 30 | AO22: 21450 | AP22: =F22+H22+J22+L22+N22+P22+R22+T22+V22+X22+Z22+AB22+AD22+AF22+AH22+AJ22+AL22+AN22 -> 2887 | AQ22: =G22+I22+K22+M22+O22+Q22+S22+U22+W22+Y22+AA22+AC22+AE22+AG22+AI22+AK22+AM22+AO22 -> 2064205
A23: 21 | B23: 4971710576641 | C23: MUPE | D23: ONE BY KOSE | E23: ONE BY KOSE CLEAR PEEL SERUM | F23: 20 | G23: 36300 | H23: 45 | I23: 81675 | J23: 40 | K23: 72600 | L23: 25 | M23: 45375 | N23: 100 | O23: 181500 | P23: 48 | Q23: 87120 | R23: 130 | S23: 235950 | T23: 124 | U23: 123420 | V23: 74 | W23: 134310 | X23: 135 | Y23: 245025 | Z23: 634 | AA23: 1150710 | AB23: 80 | AC23: 145200 | AD23: 2 | AE23: 3630 | AF23: 126 | AG23: 228690 | AH23: 1282 | AI23: 2326830 | AP23: =F23+H23+J23+L23+N23+P23+R23+T23+V23+X23+Z23+AB23+AD23+AF23+AH23+AJ23+AL23+AN23 -> 2865 | AQ23: =G23+I23+K23+M23+O23+Q23+S23+U23+W23+Y23+AA23+AC23+AE23+AG23+AI23+AK23+AM23+AO23 -> 5098335
A24: 22 | B24: 4971710549812 | C24: MSYN | D24: VISEE | E24: ONE BY KOSE MELANOSHOT W | F24: 20 | G24: 75900 | H24: 0 | I24: 0 | J24: 50 | K24: 189750 | L24: 30 | M24: 113850 | N24: 20 | O24: 75900 | P24: 126 | Q24: 478170 | R24: 120 | S24: 455400 | T24: 192 | U24: 409860 | V24: 139 | W24: 527505 | X24: 170 | Y24: 645150 | Z24: 157 | AA24: 595815 | AB24: 104 | AC24: 394680 | AD24: 190 | AE24: 721050 | AF24: 260 | AG24: 986700 | AH24: 1196 | AI24: 4538820 | AP24: =F24+H24+J24+L24+N24+P24+R24+T24+V24+X24+Z24+AB24+AD24+AF24+AH24+AJ24+AL24+AN24 -> 2774 | AQ24: =G24+I24+K24+M24+O24+Q24+S24+U24+W24+Y24+AA24+AC24+AE24+AG24+AI24+AK24+AM24+AO24 -> 10208550
A25: 25 | B25: 4971710549782 | C25: MSYJ | D25: ONE BY KOSE | E25: ONE BY KOSE MELANOSHOT W | F25: 30 | G25: 87450 | H25: 60 | I25: 174900 | J25: 25 | K25: 72875 | L25: 30 | M25: 87450 | N25: 42 | O25: 122430 | P25: 78 | Q25: 227370 | R25: 230 | S25: 670450 | T25: 100 | U25: 145750 | V25: 118 | W25: 343970 | X25: 100 | Y25: 291500 | Z25: 60 | AA25: 174900 | AB25: 88 | AC25: 256520 | AD25: 197 | AE25: 574255 | AF25: 235 | AG25: 685025 | AH25: 1171 | AI25: 3413465 | AP25: =F25+H25+J25+L25+N25+P25+R25+T25+V25+X25+Z25+AB25+AD25+AF25+AH25+AJ25+AL25+AN25 -> 2564 | AQ25: =G25+I25+K25+M25+O25+Q25+S25+U25+W25+Y25+AA25+AC25+AE25+AG25+AI25+AK25+AM25+AO25 -> 7328310
A26: 24 | B26: 4971710557787 | C26: DXPO000 | D26: FASIO | E26: FASIO PORE SMOOTH PRIMER 00 | F26: 0 | G26: 0 | H26: 30 | I26: 14850 | J26: 30 | K26: 14850 | L26: 20 | M26: 9900 | N26: 86 | O26: 42570 | P26: 100 | Q26: 49500 | R26: 224 | S26: 110880 | T26: 12 | U26: 2970 | V26: 150 | W26: 74250 | X26: 282 | Y26: 139590 | Z26: 150 | AA26: 74250 | AB26: 62 | AC26: 30690 | AD26: 226 | AE26: 111870 | AF26: 302 | AG26: 149490 | AH26: 548 | AI26: 271260 | AN26: 312 | AO26: 154440 | AP26: =F26+H26+J26+L26+N26+P26+R26+T26+V26+X26+Z26+AB26+AD26+AF26+AH26+AJ26+AL26+AN26 -> 2534 | AQ26: =G26+I26+K26+M26+O26+Q26+S26+U26+W26+Y26+AA26+AC26+AE26+AG26+AI26+AK26+AM26+AO26 -> 1251360
A27: 32 | B27: 4971710561395 | C27: MUCH | D27: ONE BY KOSE | E27: ONE BY KOSE PORE CLEAR OIL | F27: 20 | G27: 19800 | H27: 300 | I27: 297000 | J27: 40 | K27: 39600 | L27: 120 | M27: 118800 | N27: 50 | O27: 49500 | P27: 60 | Q27: 59400 | R27: 394 | S27: 390060 | T27: 480 | U27: 249480 | V27: 250 | W27: 247500 | X27: 676 | Y27: 669240 | AB27: 131 | AC27: 129690 | AF27: 6 | AG27: 5940 | AH27: 6 | AI27: 5940 | AP27: =F27+H27+J27+L27+N27+P27+R27+T27+V27+X27+Z27+AB27+AD27+AF27+AH27+AJ27+AL27+AN27 -> 2533 | AQ27: =G27+I27+K27+M27+O27+Q27+S27+U27+W27+Y27+AA27+AC27+AE27+AG27+AI27+AK27+AM27+AO27 -> 2281950
A28: 23 | B28: 4971710580372 | C28: MUXC | D28: ONE BY KOSE | E28: ONE BY KOSE SERUM VEIL DEEP REPAIR | F28: 0 | G28: 0 | H28: 0 | I28: 0 | J28: 10 | K28: 26400 | L28: 5 | M28: 13200 | N28: 10 | O28: 26400 | P28: 0 | Q28: 0 | R28: 320 | S28: 844800 | T28: 266 | U28: 359040 | V28: 68 | W28: 179520 | X28: 50 | Y28: 132000 | AB28: 628 | AC28: 1657920 | AD28: 68 | AE28: 179520 | AF28: 120 | AG28: 316800 | AH28: 848 | AI28: 2238720 | AN28: 60 | AO28: 171600 | AP28: =F28+H28+J28+L28+N28+P28+R28+T28+V28+X28+Z28+AB28+AD28+AF28+AH28+AJ28+AL28+AN28 -> 2453 | AQ28: =G28+I28+K28+M28+O28+Q28+S28+U28+W28+Y28+AA28+AC28+AE28+AG28+AI28+AK28+AM28+AO28 -> 6145920
A29: 26 | B29: 4971710522839 | C29: DLID | D29: その他CCS | E29: CURL KEEP MAGIC ESSENCE REMOVER | F29: 0 | G29: 0 | H29: 35 | I29: 15400 | J29: 0 | K29: 0 | L29: 0 | M29: 0 | N29: 216 | O29: 95040 | P29: 0 | Q29: 0 | R29: 120 | S29: 52800 | V29: 160 | W29: 70400 | X29: 200 | Y29: 88000 | AD29: 300 | AE29: 132000 | AF29: 300 | AG29: 132000 | AH29: 1100 | AI29: 484000 | AP29: =F29+H29+J29+L29+N29+P29+R29+T29+V29+X29+Z29+AB29+AD29+AF29+AH29+AJ29+AL29+AN29 -> 2431 | AQ29: =G29+I29+K29+M29+O29+Q29+S29+U29+W29+Y29+AA29+AC29+AE29+AG29+AI29+AK29+AM29+AO29 -> 1069640
A30: 27 | B30: 4971710592955 | C30: YNGC001 | D30: VISEE | E30: VISEE COLOR DUO TRICK CONCEALER 01 | F30: 0 | G30: 0 | H30: 0 | I30: 0 | J30: 0 | K30: 0 | L30: 0 | M30: 0 | N30: 0 | O30: 0 | P30: 0 | Q30: 0 | R30: 65 | S30: 39325 | T30: 650 | U30: 196625 | V30: 39 | W30: 23595 | X30: 341 | Y30: 206305 | Z30: 32 | AA30: 19360 | AD30: 436 | AE30: 263780 | AF30: 30 | AG30: 18150 | AN30: 786 | AO30: 475530 | AP30: =F30+H30+J30+L30+N30+P30+R30+T30+V30+X30+Z30+AB30+AD30+AF30+AH30+AJ30+AL30+AN30 -> 2379 | AQ30: =G30+I30+K30+M30+O30+Q30+S30+U30+W30+Y30+AA30+AC30+AE30+AG30+AI30+AK30+AM30+AO30 -> 1242670
A31: 30 | B31: 4971710576634 | C31: MUPD | D31: ONE BY KOSE | E31: ONE BY KOSE CLEAR PEEL SERUM | F31: 30 | G31: 57750 | H31: 60 | I31: 115500 | J31: 145 | K31: 279125 | L31: 11 | M31: 21175 | N31: 50 | O31: 96250 | P31: 5 | Q31: 9625 | R31: 195 | S31: 375375 | T31: 152 | U31: 157850 | V31: 6 | W31: 11550 | X31: 70 | Y31: 134750 | Z31: 597 | AA31: 1149225 | AB31: 18 | AC31: 34650 | AD31: 16 | AE31: 30800 | AF31: 120 | AG31: 231000 | AH31: 656 | AI31: 1262800 | AN31: 61 | AO31: 117425 | AP31: =F31+H31+J31+L31+N31+P31+R31+T31+V31+X31+Z31+AB31+AD31+AF31+AH31+AJ31+AL31+AN31 -> 2192 | AQ31: =G31+I31+K31+M31+O31+Q31+S31+U31+W31+Y31+AA31+AC31+AE31+AG31+AI31+AK31+AM31+AO31 -> 4084850
A32: 28 | B32: 4971710573992 | C32: MTSE | D32: SEKKISEI | E32: SEKKISEI BRIGHTENING ESSENCE LOTION | F32: 0 | G32: 0 | H32: 0 | I32: 0 | J32: 0 | K32: 0 | L32: 0 | M32: 0 | N32: 0 | O32: 0 | P32: 0 | Q32: 0 | Z32: 237 | AA32: 703890 | AB32: 20 | AC32: 59400 | AD32: 150 | AE32: 445500 | AF32: 635 | AG32: 1885950 | AH32: 903 | AI32: 2681910 | AN32: 79 | AO32: 252010 | AP32: =F32+H32+J32+L32+N32+P32+R32+T32+V32+X32+Z32+AB32+AD32+AF32+AH32+AJ32+AL32+AN32 -> 2024 | AQ32: =G32+I32+K32+M32+O32+Q32+S32+U32+W32+Y32+AA32+AC32+AE32+AG32+AI32+AK32+AM32+AO32 -> 6028660
A33: 58 | B33: 4971710556766 | C33: DLEP | D33: MAKE KEEP | E33: MAKE KEEP POWDER | F33: 0 | G33: 0 | H33: 335 | I33: 221100 | J33: 115 | K33: 75900 | L33: 32 | M33: 21120 | N33: 572 | O33: 377520 | P33: 120 | Q33: 79200 | R33: 410 | S33: 270600 | T33: 276 | U33: 91080 | V33: 18 | W33: 11880 | X33: 120 | Y33: 79200 | AP33: =F33+H33+J33+L33+N33+P33+R33+T33+V33+X33+Z33+AB33+AD33+AF33+AH33+AJ33+AL33+AN33 -> 1998 | AQ33: =G33+I33+K33+M33+O33+Q33+S33+U33+W33+Y33+AA33+AC33+AE33+AG33+AI33+AK33+AM33+AO33 -> 1227600
A34: 33 | B34: 4971710568899 | C34: MUWI | D34: ONE BY KOSE | E34: ONE BY KOSE WRINKLE DOUBLE REPAIR | F34: 20 | G34: 29700 | H34: 10 | I34: 14850 | J34: 10 | K34: 14850 | L34: 5 | M34: 7425 | N34: 115 | O34: 170775 | P34: 0 | Q34: 0 | R34: 30 | S34: 44550 | T34: 156 | U34: 124740 | V34: 112 | W34: 166320 | X34: 46 | Y34: 68310 | Z34: 626 | AA34: 929610 | AB34: 60 | AC34: 89100 | AD34: 2 | AE34: 2970 | AF34: 48 | AG34: 71280 | AH34: 646 | AI34: 959310 | AN34: 100 | AO34: 148500 | AP34: =F34+H34+J34+L34+N34+P34+R34+T34+V34+X34+Z34+AB34+AD34+AF34+AH34+AJ34+AL34+AN34 -> 1986 | AQ34: =G34+I34+K34+M34+O34+Q34+S34+U34+W34+Y34+AA34+AC34+AE34+AG34+AI34+AK34+AM34+AO34 -> 2842290
A35: 29 | B35: 4971710573855 | C35: MTSC | D35: SEKKISEI | E35: SEKKISEI BRIGHTENING ESSENCE LOTION | F35: 0 | G35: 0 | H35: 0 | I35: 0 | J35: 0 | K35: 0 | L35: 0 | M35: 0 | N35: 0 | O35: 0 | P35: 0 | Q35: 0 | Z35: 270 | AA35: 519750 | AD35: 162 | AE35: 311850 | AF35: 372 | AG35: 716100 | AH35: 915 | AI35: 1761375 | AN35: 129 | AO35: 269610 | AP35: =F35+H35+J35+L35+N35+P35+R35+T35+V35+X35+Z35+AB35+AD35+AF35+AH35+AJ35+AL35+AN35 -> 1848 | AQ35: =G35+I35+K35+M35+O35+Q35+S35+U35+W35+Y35+AA35+AC35+AE35+AG35+AI35+AK35+AM35+AO35 -> 3578685
A36: 31 | B36: 4971710571868 | C36: MTSD | D36: SEKKISEI | E36: SEKKISEI BRIGHTENING EMULSION | F36: 0 | G36: 0 | H36: 0 | I36: 0 | J36: 0 | K36: 0 | L36: 0 | M36: 0 | N36: 0 | O36: 0 | P36: 0 | Q36: 0 | Z36: 274 | AA36: 572660 | AB36: 20 | AC36: 41800 | AD36: 6 | AE36: 12540 | AF36: 600 | AG36: 1254000 | AH36: 683 | AI36: 1427470 | AN36: 205 | AO36: 462275 | AP36: =F36+H36+J36+L36+N36+P36+R36+T36+V36+X36+Z36+AB36+AD36+AF36+AH36+AJ36+AL36+AN36 -> 1788 | AQ36: =G36+I36+K36+M36+O36+Q36+S36+U36+W36+Y36+AA36+AC36+AE36+AG36+AI36+AK36+AM36+AO36 -> 3770745
A37: 34 | B37: 4971710549805 | C37: MSYK | D37: ONE BY KOSE | E37: ONE BY KOSE MELANOSHOT W | F37: 0 | G37: 0 | H37: 70 | I37: 192500 | J37: 20 | K37: 55000 | L37: 25 | M37: 68750 | N37: 25 | O37: 68750 | P37: 72 | Q37: 198000 | R37: 317 | S37: 871750 | T37: 124 | U37: 203500 | V37: 70 | W37: 192500 | X37: 30 | Y37: 82500 | Z37: 311 | AA37: 855250 | AB37: 6 | AC37: 16500 | AD37: 47 | AE37: 129250 | AH37: 649 | AI37: 1784750 | AP37: =F37+H37+J37+L37+N37+P37+R37+T37+V37+X37+Z37+AB37+AD37+AF37+AH37+AJ37+AL37+AN37 -> 1766 | AQ37: =G37+I37+K37+M37+O37+Q37+S37+U37+W37+Y37+AA37+AC37+AE37+AG37+AI37+AK37+AM37+AO37 -> 4719000
A38: 40 | B38: 4971710571790 | C38: YNGV002 | D38: VISEE | E38: VISEE NUANCE DEWY CREATOR BE-2 | F38: 0 | G38: 0 | H38: 24 | I38: 15840 | J38: 24 | K38: 15840 | L38: 162 | M38: 106920 | N38: 0 | O38: 0 | P38: 25 | Q38: 16500 | R38: 15 | S38: 9900 | T38: 624 | U38: 205920 | V38: 150 | W38: 99000 | X38: 138 | Y38: 91080 | AD38: 8 | AE38: 5280 | AH38: 556 | AI38: 366960 | AN38: 24 | AO38: 15840 | AP38: =F38+H38+J38+L38+N38+P38+R38+T38+V38+X38+Z38+AB38+AD38+AF38+AH38+AJ38+AL38+AN38 -> 1750 | AQ38: =G38+I38+K38+M38+O38+Q38+S38+U38+W38+Y38+AA38+AC38+AE38+AG38+AI38+AK38+AM38+AO38 -> 949080
A39: 39 | B39: 4971710556865 | C39: YNST300 | D39: VISEE | E39: VISEE SHADE TRICK BR300 | F39: 80 | G39: 70400 | H39: 35 | I39: 30800 | J39: 21 | K39: 18480 | L39: 50 | M39: 44000 | N39: 67 | O39: 58960 | P39: 0 | Q39: 0 | R39: 172 | S39: 151360 | T39: 456 | U39: 200640 | V39: 60 | W39: 52800 | X39: 68 | Y39: 59840 | Z39: 72 | AA39: 63360 | AB39: 15 | AC39: 13200 | AD39: 108 | AE39: 95040 | AF39: 20 | AG39: 17600 | AH39: 312 | AI39: 274560 | AN39: 180 | AO39: 158400 | AP39: =F39+H39+J39+L39+N39+P39+R39+T39+V39+X39+Z39+AB39+AD39+AF39+AH39+AJ39+AL39+AN39 -> 1716 | AQ39: =G39+I39+K39+M39+O39+Q39+S39+U39+W39+Y39+AA39+AC39+AE39+AG39+AI39+AK39+AM39+AO39 -> 1309440
A40: 36 | B40: 4971710556827 | C40: YNFB001 | D40: VISEE | E40: VISEE GLOW BALM FOUNDATION 01 | F40: 0 | G40: 0 | H40: 0 | I40: 0 | J40: 95 | K40: 94050 | L40: 130 | M40: 128700 | N40: 60 | O40: 59400 | P40: 75 | Q40: 74250 | R40: 65 | S40: 64350 | T40: 204 | U40: 100980 | V40: 230 | W40: 227700 | X40: 30 | Y40: 29700 | Z40: 62 | AA40: 61380 | AB40: 9 | AC40: 8910 | AD40: 4 | AE40: 3960 | AF40: 60 | AG40: 59400 | AH40: 475 | AI40: 470250 | AN40: 154 | AO40: 152460 | AP40: =F40+H40+J40+L40+N40+P40+R40+T40+V40+X40+Z40+AB40+AD40+AF40+AH40+AJ40+AL40+AN40 -> 1653 | AQ40: =G40+I40+K40+M40+O40+Q40+S40+U40+W40+Y40+AA40+AC40+AE40+AG40+AI40+AK40+AM40+AO40 -> 1535490
...

Sheet 金額
A1: No. | B1: JANコード | C1: 商品符号 | D1: ブランド | E1: 商品名称 | F1: 2407 | G1: 2408 | H1: 2409 | I1: 2410 | J1: 2411 | K1: 2412 | L1: 2501 | M1: 2502 | N1: 2503 | O1: 2504 | P1: 2505 | Q1: 2506 | R1: 2507 | S1: 2508 | T1: 2509 | U1: 2510 | V1: 2511 | W1: 2512
F2: 金額 | G2: 金額 | H2: 金額 | I2: 金額 | J2: 金額 | K2: 金額 | L2: 金額 | M2: 金額 | N2: 金額 | O2: 金額 | P2: 金額 | Q2: 金額 | R2: 金額 | S2: 金額 | T2: 金額 | U2: 金額 | V2: 金額 | W2: 金額
A3: 1 | B3: 4971710576306 | C3: DLEA | D3: MAKE KEEP | E3: MAKE KEEP MIST EX + | F3: 0 | G3: 85800 | H3: 26400 | I3: 93720 | J3: 209880 | K3: 0 | L3: 1333200 | M3: 1631520 | N3: 5488560 | O3: 8102160 | P3: 13332660 | Q3: 9139680 | R3: 20606520 | S3: 17160000 | T3: 42472320
A4: 2 | B4: 4971710565065 | C4: MUSC | D4: ONE BY KOSE | E4: ONE BY KOSE SERUM SHIELD | F4: 110000 | G4: 453750 | H4: 82500 | I4: 522500 | J4: 2483250 | K4: 3080000 | L4: 9190500 | M4: 5714500 | N4: 2546500 | O4: 6083000 | P4: 16464250 | Q4: 3080000 | R4: 7144500 | S4: 4675000 | T4: 45254000
A5: 3 | B5: 4971710574852 | C5: MUCI | D5: ONE BY KOSE | E5: ONE BY KOSE PORE CLEAR OIL（Refill） | F5: 0 | G5: 49500 | H5: 0 | I5: 37125 | J5: 264000 | K5: 561000 | L5: 503250 | M5: 740850 | N5: 394350 | O5: 2103750 | P5: 3836250 | Q5: 297000 | R5: 3387450 | S5: 3048375 | T5: 14012625
A6: 4 | B6: 4971710598711 | C6: DLFP | D6: MAKE KEEP | E6: MAKE KEEP POWDER ＥＸ | F6: 0 | G6: 0 | H6: 0 | I6: 0 | J6: 0 | K6: 0 | Q6: 798336 | R6: 5345802 | S6: 8052660 | T6: 2062368 | W6: 66528
A7: 5 | B7: 4971710511505 | C7: DLIB | D7: その他CCS | E7: CURL KEEP MAGIC | F7: 0 | G7: 4950 | H7: 14850 | I7: 0 | J7: 178200 | K7: 0 | L7: 1386000 | M7: 1485000 | O7: 990000 | P7: 24750 | R7: 1757250 | S7: 990000 | T7: 2475000
A8: 6 | B8: 4971710580044 | C8: DLCE | D8: MAKE KEEP | E8: MAKE KEEP PRIMER COOL | F8: 0 | G8: 9900 | H8: 0 | I8: 0 | J8: 0 | K8: 0 | P8: 39600 | Q8: 818400 | R8: 2640000 | S8: 1650000
A9: 7 | B9: 4971710590500 | C9: DLCH | D9: MAKE KEEP | E9: MAKE KEEP MIST EX + SAKURA CHERRY | F9: 0 | G9: 0 | H9: 0 | I9: 0 | J9: 0 | K9: 0 | O9: 2376000 | P9: 1980000 | R9: 66000
A10: 8 | B10: 4971710579291 | C10: DLCC | D10: MAKE KEEP | E10: MAKE KEEP MIST EX + COOL | F10: 0 | G10: 0 | H10: 0 | I10: 0 | J10: 0 | K10: 0 | P10: 3769920 | Q10: 491040
A11: 9 | B11: 4971710551006 | C11: YNRE001 | D11: VISEE | E11: VISEE ESSENCE LIP PLUMPER SP001 | F11: 1079650 | G11: 38610 | H11: 17160 | I11: 47190 | J11: 579150 | K11: 64350 | L11: 926640 | M11: 447590 | N11: 602030 | O11: 25740 | P11: 370370 | Q11: 51480 | R11: 253110 | S11: 429000 | T11: 1411410
A12: 10 | B12: 4971710595789 | C12: MUCF | D12: ONE BY KOSE | E12: ONE BY KOSE PORE CLEAR SCRUB WASH | F12: 0 | G12: 0 | H12: 0 | I12: 0 | J12: 0 | K12: 0 | P12: 740520 | R12: 1138500 | T12: 3762000
A13: 11 | B13: 4971710571837 | C13: YNRE300 | D13: VISEE | E13: VISEE ESSENCE LIP PLUMPER BE300 | F13: 364650 | G13: 24310 | H13: 17160 | I13: 329615 | J13: 193050 | K13: 135850 | L13: 657800 | M13: 592020 | N13: 530530 | O13: 17160 | Q13: 35750 | R13: 8580 | S13: 30030 | T13: 570570 | W13: 396825
A14: 12 | B14: 4971710580600 | C14: MTSW | D14: SEKKISEI | E14: SEKKISEI BRIGHTENING ESSENCE LOTION | F14: 0 | G14: 0 | H14: 0 | I14: 0 | J14: 0 | K14: 0 | P14: 1706100 | R14: 780670 | S14: 2217930 | T14: 3903350 | W14: 1670900
A15: 13 | B15: 4971710590524 | C15: DLCJ | D15: MAKE KEEP | E15: MAKE KEEP POWDER SAKURA CHERRY | F15: 0 | G15: 0 | H15: 0 | I15: 0 | J15: 0 | K15: 0 | O15: 234960 | P15: 1782000 | R15: 462000
A16: 14 | B16: 4971710577341 | C16: MUXA | D16: ONE BY KOSE | E16: ONE BY KOSE SERUM VEIL DEEP REPAIR | F16: 0 | G16: 0 | H16: 27500 | I16: 13750 | J16: 82500 | K16: 0 | L16: 1067000 | M16: 574750 | N16: 544500 | O16: 220000 | P16: 2128500 | Q16: 148500 | R16: 121000 | S16: 687500 | T16: 1864500 | W16: 1425600
A17: 15 | B17: 4971710546071 | C17: MUZU | D17: ONE BY KOSE | E17: ONE BY KOSE DEEP HYDRATOR | F17: 0 | G17: 63800 | H17: 0 | I17: 79750 | J17: 47850 | K17: 162690 | L17: 778360 | M17: 236060 | N17: 245630 | O17: 194590 | P17: 957000 | Q17: 47850 | R17: 9570 | S17: 462550 | T17: 1518440 | W17: 382800
A18: 16 | B18: 4971710580396 | C18: MUXD | D18: ONE BY KOSE | E18: ONE BY KOSE SERUM VEIL DEEP REPAIR | F18: 0 | G18: 91300 | H18: 45650 | I18: 159775 | J18: 136950 | K18: 0 | L18: 1460800 | M18: 1168640 | N18: 1415150 | O18: 547800 | P18: 2424015 | Q18: 365200 | R18: 27390 | S18: 913000 | T18: 5030630 | W18: 237600
A19: 17 | B19: 4971710539189 | C19: YNCF | D19: VISEE | E19: VISEE RED TRICK EYE CONCEALER | F19: 441650 | G19: 180895 | H19: 14520 | I19: 7260 | J19: 235950 | K19: 142175 | L19: 804045 | M19: 273460 | N19: 182710 | O19: 14520 | P19: 485210 | Q19: 32065
A20: 18 | B20: 4971710576573 | C20: DLEB | D20: MAKE KEEP | E20: MAKE KEEP MIST EX +＜35mL＞ | F20: 0 | G20: 165000 | H20: 13200 | I20: 0 | J20: 31680 | K20: 4400 | L20: 388080 | M20: 51040 | N20: 4840 | O20: 220880 | P20: 12320 | Q20: 73920 | R20: 66880 | S20: 84480 | T20: 356400 | W20: 39259
A21: 19 | B21: 4971710588163 | C21: DLSC | D21: その他CCS | E21: SUPER UV PROTECTOR | F21: 0 | G21: 0 | H21: 0 | I21: 0 | J21: 0 | K21: 0 | O21: 22880 | Q21: 87230 | R21: 143000 | S21: 14300 | T21: 1775345 | W21: 21450
A22: 20 | B22: 4971710595543 | C22: YNXX006 | D22: VISEE | E22: VISEE W MOOD EYES BL-6 | F22: 0 | G22: 0 | H22: 0 | I22: 0 | J22: 0 | K22: 0 | M22: 415800 | N22: 308000 | O22: 377300 | P22: 281050 | Q22: 275660 | R22: 69300 | S22: 38500 | T22: 161700 | W22: 92400
A23: 21 | B23: 4971710576641 | C23: MUPE | D23: ONE BY KOSE | E23: ONE BY KOSE CLEAR PEEL SERUM | F23: 36300 | G23: 81675 | H23: 72600 | I23: 45375 | J23: 181500 | K23: 87120 | L23: 235950 | M23: 123420 | N23: 134310 | O23: 245025 | P23: 1150710 | Q23: 145200 | R23: 3630 | S23: 228690 | T23: 2326830
A24: 22 | B24: 4971710549812 | C24: MSYN | D24: VISEE | E24: ONE BY KOSE MELANOSHOT W | F24: 75900 | G24: 0 | H24: 189750 | I24: 113850 | J24: 75900 | K24: 478170 | L24: 455400 | M24: 409860 | N24: 527505 | O24: 645150 | P24: 595815 | Q24: 394680 | R24: 721050 | S24: 986700 | T24: 4538820
A25: 23 | B25: 4971710580372 | C25: MUXC | D25: ONE BY KOSE | E25: ONE BY KOSE SERUM VEIL DEEP REPAIR | F25: 0 | G25: 0 | H25: 26400 | I25: 13200 | J25: 26400 | K25: 0 | L25: 844800 | M25: 359040 | N25: 179520 | O25: 132000 | Q25: 1657920 | R25: 179520 | S25: 316800 | T25: 2238720 | W25: 171600
A26: 24 | B26: 4971710557787 | C26: DXPO000 | D26: FASIO | E26: FASIO PORE SMOOTH PRIMER 00 | F26: 0 | G26: 14850 | H26: 14850 | I26: 9900 | J26: 42570 | K26: 49500 | L26: 110880 | M26: 2970 | N26: 74250 | O26: 139590 | P26: 74250 | Q26: 30690 | R26: 111870 | S26: 149490 | T26: 271260 | W26: 154440
A27: 25 | B27: 4971710549782 | C27: MSYJ | D27: ONE BY KOSE | E27: ONE BY KOSE MELANOSHOT W | F27: 87450 | G27: 174900 | H27: 72875 | I27: 87450 | J27: 122430 | K27: 227370 | L27: 670450 | M27: 145750 | N27: 343970 | O27: 291500 | P27: 174900 | Q27: 256520 | R27: 574255 | S27: 685025 | T27: 3413465
A28: 26 | B28: 4971710522839 | C28: DLID | D28: その他CCS | E28: CURL KEEP MAGIC ESSENCE REMOVER | F28: 0 | G28: 15400 | H28: 0 | I28: 0 | J28: 95040 | K28: 0 | L28: 52800 | N28: 70400 | O28: 88000 | R28: 132000 | S28: 132000 | T28: 484000
A29: 27 | B29: 4971710592955 | C29: YNGC001 | D29: VISEE | E29: VISEE COLOR DUO TRICK CONCEALER 01 | F29: 0 | G29: 0 | H29: 0 | I29: 0 | J29: 0 | K29: 0 | L29: 39325 | M29: 196625 | N29: 23595 | O29: 206305 | P29: 19360 | R29: 263780 | S29: 18150 | W29: 475530
A30: 28 | B30: 4971710573992 | C30: MTSE | D30: SEKKISEI | E30: SEKKISEI BRIGHTENING ESSENCE LOTION | F30: 0 | G30: 0 | H30: 0 | I30: 0 | J30: 0 | K30: 0 | P30: 703890 | Q30: 59400 | R30: 445500 | S30: 1885950 | T30: 2681910 | W30: 252010
A31: 29 | B31: 4971710573855 | C31: MTSC | D31: SEKKISEI | E31: SEKKISEI BRIGHTENING ESSENCE LOTION | F31: 0 | G31: 0 | H31: 0 | I31: 0 | J31: 0 | K31: 0 | P31: 519750 | R31: 311850 | S31: 716100 | T31: 1761375 | W31: 269610
A32: 30 | B32: 4971710576634 | C32: MUPD | D32: ONE BY KOSE | E32: ONE BY KOSE CLEAR PEEL SERUM | F32: 57750 | G32: 115500 | H32: 279125 | I32: 21175 | J32: 96250 | K32: 9625 | L32: 375375 | M32: 157850 | N32: 11550 | O32: 134750 | P32: 1149225 | Q32: 34650 | R32: 30800 | S32: 231000 | T32: 1262800 | W32: 117425
A33: 31 | B33: 4971710571868 | C33: MTSD | D33: SEKKISEI | E33: SEKKISEI BRIGHTENING EMULSION | F33: 0 | G33: 0 | H33: 0 | I33: 0 | J33: 0 | K33: 0 | P33: 572660 | Q33: 41800 | R33: 12540 | S33: 1254000 | T33: 1427470 | W33: 462275
A34: 32 | B34: 4971710561395 | C34: MUCH | D34: ONE BY KOSE | E34: ONE BY KOSE PORE CLEAR OIL | F34: 19800 | G34: 297000 | H34: 39600 | I34: 118800 | J34: 49500 | K34: 59400 | L34: 390060 | M34: 249480 | N34: 247500 | O34: 669240 | Q34: 129690 | S34: 5940 | T34: 5940
A35: 33 | B35: 4971710568899 | C35: MUWI | D35: ONE BY KOSE | E35: ONE BY KOSE WRINKLE DOUBLE REPAIR | F35: 29700 | G35: 14850 | H35: 14850 | I35: 7425 | J35: 170775 | K35: 0 | L35: 44550 | M35: 124740 | N35: 166320 | O35: 68310 | P35: 929610 | Q35: 89100 | R35: 2970 | S35: 71280 | T35: 959310 | W35: 148500
A36: 34 | B36: 4971710549805 | C36: MSYK | D36: ONE BY KOSE | E36: ONE BY KOSE MELANOSHOT W | F36: 0 | G36: 192500 | H36: 55000 | I36: 68750 | J36: 68750 | K36: 198000 | L36: 871750 | M36: 203500 | N36: 192500 | O36: 82500 | P36: 855250 | Q36: 16500 | R36: 129250 | T36: 1784750
A37: 35 | B37: 4971710581928 | C37: MTSX | D37: SEKKISEI | E37: SEKKISEI BRIGHTENING EMULSION | F37: 0 | G37: 0 | H37: 0 | I37: 0 | J37: 0 | K37: 0 | P37: 813120 | Q37: 35200 | R37: 21120 | S37: 563200 | T37: 894080 | W37: 330990
A38: 36 | B38: 4971710556827 | C38: YNFB001 | D38: VISEE | E38: VISEE GLOW BALM FOUNDATION 01 | F38: 0 | G38: 0 | H38: 94050 | I38: 128700 | J38: 59400 | K38: 74250 | L38: 64350 | M38: 100980 | N38: 227700 | O38: 29700 | P38: 61380 | Q38: 8910 | R38: 3960 | S38: 59400 | T38: 470250 | W38: 152460
A39: 37 | B39: 4971710524055 | C39: YNBX | D39: VISEE | E39: VISEE EYEBROW ENHANCER | F39: 0 | G39: 0 | H39: 0 | I39: 60500 | J39: 9075 | K39: 72600 | L39: 176055 | M39: 73810 | N39: 151250 | O39: 3630 | P39: 24200 | Q39: 60500 | R39: 24200 | S39: 60500 | T39: 121000 | W39: 84700
A40: 38 | B40: 4971710595529 | C40: YNXX004 | D40: VISEE | E40: VISEE W MOOD EYES OR-4 | F40: 0 | G40: 0 | H40: 0 | I40: 0 | J40: 0 | K40: 0 | M40: 22330 | N40: 104720 | O40: 133980 | P40: 127050 | Q40: 186340 | R40: 149380 | T40: 158620 | W40: 97020
...

Sheet ブランド別売上推移
T1: 単位：千円
A2: ブランド | B2: 2024 | H2: 2025 | T2: 合計
B3: 7月 | C3: 8月 | D3: 9月 | E3: 10月 | F3: 11月 | G3: 12月 | H3: 1月 | I3: 2月 | J3: 3月 | K3: 4月 | L3: 5月 | M3: 6月 | N3: 7月 | O3: 8月 | P3: 9月 | Q3: 10月 | R3: 11月 | S3: 12月 | T3: 金額 | U3: 構成比
A4: MAKE KEEP | B4: =SUMIF(金額!D:F,$A4,金額!F:F)/1000 -> 0 | C4: =SUMIF(金額!$D:G,$A4,金額!G:G)/1000 -> 501.6 | D4: =SUMIF(金額!$D:H,$A4,金額!H:H)/1000 -> 128.7 | E4: =SUMIF(金額!$D:I,$A4,金額!I:I)/1000 -> 120.34 | F4: =SUMIF(金額!$D:J,$A4,金額!J:J)/1000 -> 729.96 | G4: =SUMIF(金額!$D:K,$A4,金額!K:K)/1000 -> 126.5 | H4: =SUMIF(金額!$D:L,$A4,金額!L:L)/1000 -> 2071.08 | I4: =SUMIF(金額!$D:M,$A4,金額!M:M)/1000 -> 1773.64 | J4: =SUMIF(金額!$D:N,$A4,金額!N:N)/1000 -> 5663.68 | K4: =SUMIF(金額!$D:O,$A4,金額!O:O)/1000 -> 11066 | L4: =SUMIF(金額!$D:P,$A4,金額!P:P)/1000 -> 21080.84 | M4: =SUMIF(金額!$D:Q,$A4,金額!Q:Q)/1000 -> 11346.076 | N4: =SUMIF(金額!$D:R,$A4,金額!R:R)/1000 -> 29216.902 | O4: =SUMIF(金額!$D:S,$A4,金額!S:S)/1000 -> 26968.58 | P4: =SUMIF(金額!$D:T,$A4,金額!T:T)/1000 -> 44998.908 | Q4: =SUMIF(金額!$D:U,$A4,金額!U:U)/1000 -> 0 | R4: =SUMIF(金額!$D:V,$A4,金額!V:V)/1000 -> 0 | S4: =SUMIF(金額!$D:W,$A4,金額!W:W)/1000 -> 237.787 | T4: =SUM(B4:S4) -> 156030.59 | U4: =T4/$T$11 -> 0.30955273
A5: その他CCS | B5: =SUMIF(金額!D:F,A5,金額!F:F)/1000 -> 0 | C5: =SUMIF(金額!$D:G,$A5,金額!G:G)/1000 -> 53.35 | D5: =SUMIF(金額!$D:H,$A5,金額!H:H)/1000 -> 25.85 | E5: =SUMIF(金額!$D:I,$A5,金額!I:I)/1000 -> 0 | F5: =SUMIF(金額!$D:J,$A5,金額!J:J)/1000 -> 284.24 | G5: =SUMIF(金額!$D:K,$A5,金額!K:K)/1000 -> 16.5 | H5: =SUMIF(金額!$D:L,$A5,金額!L:L)/1000 -> 1515.8 | I5: =SUMIF(金額!$D:M,$A5,金額!M:M)/1000 -> 1485 | J5: =SUMIF(金額!$D:N,$A5,金額!N:N)/1000 -> 70.4 | K5: =SUMIF(金額!$D:O,$A5,金額!O:O)/1000 -> 1100.88 | L5: =SUMIF(金額!$D:P,$A5,金額!P:P)/1000 -> 24.75 | M5: =SUMIF(金額!$D:Q,$A5,金額!Q:Q)/1000 -> 87.23 | N5: =SUMIF(金額!$D:R,$A5,金額!R:R)/1000 -> 2032.25 | O5: =SUMIF(金額!$D:S,$A5,金額!S:S)/1000 -> 1136.3 | P5: =SUMIF(金額!$D:T,$A5,金額!T:T)/1000 -> 4734.345 | Q5: =SUMIF(金額!$D:U,$A5,金額!U:U)/1000 -> 0 | R5: =SUMIF(金額!$D:V,$A5,金額!V:V)/1000 -> 0 | S5: =SUMIF(金額!$D:W,$A5,金額!W:W)/1000 -> 21.45 | T5: =SUM(B5:S5) -> 12588.345 | U5: =T5/$T$11 -> 0.024974311
A6: FASIO | B6: =SUMIF(金額!D:F,A6,金額!F:F)/1000 -> 73.48 | C6: =SUMIF(金額!$D:G,$A6,金額!G:G)/1000 -> 418.78 | D6: =SUMIF(金額!$D:H,$A6,金額!H:H)/1000 -> 279.895 | E6: =SUMIF(金額!$D:I,$A6,金額!I:I)/1000 -> 564.44 | F6: =SUMIF(金額!$D:J,$A6,金額!J:J)/1000 -> 956.005 | G6: =SUMIF(金額!$D:K,$A6,金額!K:K)/1000 -> 308.15 | H6: =SUMIF(金額!$D:L,$A6,金額!L:L)/1000 -> 1944.557 | I6: =SUMIF(金額!$D:M,$A6,金額!M:M)/1000 -> 243.153 | J6: =SUMIF(金額!$D:N,$A6,金額!N:N)/1000 -> 420.932 | K6: =SUMIF(金額!$D:O,$A6,金額!O:O)/1000 -> 955.094 | L6: =SUMIF(金額!$D:P,$A6,金額!P:P)/1000 -> 1416.264 | M6: =SUMIF(金額!$D:Q,$A6,金額!Q:Q)/1000 -> 230.406 | N6: =SUMIF(金額!$D:R,$A6,金額!R:R)/1000 -> 1344.808 | O6: =SUMIF(金額!$D:S,$A6,金額!S:S)/1000 -> 1050.964 | P6: =SUMIF(金額!$D:T,$A6,金額!T:T)/1000 -> 1141.974 | Q6: =SUMIF(金額!$D:U,$A6,金額!U:U)/1000 -> 0 | R6: =SUMIF(金額!$D:V,$A6,金額!V:V)/1000 -> 0 | S6: =SUMIF(金額!$D:W,$A6,金額!W:W)/1000 -> 1785.166 | T6: =SUM(B6:S6) -> 13134.068 | U6: =T6/$T$11 -> 0.026056984
A7: ONE BY KOSE | B7: =SUMIF(金額!D:F,A7,金額!F:F)/1000 -> 452.1 | C7: =SUMIF(金額!$D:G,$A7,金額!G:G)/1000 -> 1771.275 | D7: =SUMIF(金額!$D:H,$A7,金額!H:H)/1000 -> 763.4 | E7: =SUMIF(金額!$D:I,$A7,金額!I:I)/1000 -> 1588.4 | F7: =SUMIF(金額!$D:J,$A7,金額!J:J)/1000 -> 4290.055 | G7: =SUMIF(金額!$D:K,$A7,金額!K:K)/1000 -> 5379.495 | H7: =SUMIF(金額!$D:L,$A7,金額!L:L)/1000 -> 18711.055 | I7: =SUMIF(金額!$D:M,$A7,金額!M:M)/1000 -> 10823.56 | J7: =SUMIF(金額!$D:N,$A7,金額!N:N)/1000 -> 7069.26 | K7: =SUMIF(金額!$D:O,$A7,金額!O:O)/1000 -> 11290.015 | L7: =SUMIF(金額!$D:P,$A7,金額!P:P)/1000 -> 33670.065 | M7: =SUMIF(金額!$D:Q,$A7,金額!Q:Q)/1000 -> 6478.01 | N7: =SUMIF(金額!$D:R,$A7,金額!R:R)/1000 -> 13014.375 | O7: =SUMIF(金額!$D:S,$A7,金額!S:S)/1000 -> 11533.06 | P7: =SUMIF(金額!$D:T,$A7,金額!T:T)/1000 -> 90481.27 | Q7: =SUMIF(金額!$D:U,$A7,金額!U:U)/1000 -> 0 | R7: =SUMIF(金額!$D:V,$A7,金額!V:V)/1000 -> 0 | S7: =SUMIF(金額!$D:W,$A7,金額!W:W)/1000 -> 4150.74 | T7: =SUM(B7:S7) -> 221466.13 | U7: =T7/$T$11 -> 0.43937183
A8: SEKKISEI | B8: =SUMIF(金額!D:F,A8,金額!F:F)/1000 -> 0 | C8: =SUMIF(金額!$D:G,$A8,金額!G:G)/1000 -> 0 | D8: =SUMIF(金額!$D:H,$A8,金額!H:H)/1000 -> 0 | E8: =SUMIF(金額!$D:I,$A8,金額!I:I)/1000 -> 0 | F8: =SUMIF(金額!$D:J,$A8,金額!J:J)/1000 -> 0 | G8: =SUMIF(金額!$D:K,$A8,金額!K:K)/1000 -> 0 | H8: =SUMIF(金額!$D:L,$A8,金額!L:L)/1000 -> 0 | I8: =SUMIF(金額!$D:M,$A8,金額!M:M)/1000 -> 0 | J8: =SUMIF(金額!$D:N,$A8,金額!N:N)/1000 -> 0 | K8: =SUMIF(金額!$D:O,$A8,金額!O:O)/1000 -> 0 | L8: =SUMIF(金額!$D:P,$A8,金額!P:P)/1000 -> 6288.425 | M8: =SUMIF(金額!$D:Q,$A8,金額!Q:Q)/1000 -> 136.4 | N8: =SUMIF(金額!$D:R,$A8,金額!R:R)/1000 -> 1681.68 | O8: =SUMIF(金額!$D:S,$A8,金額!S:S)/1000 -> 6664.68 | P8: =SUMIF(金額!$D:T,$A8,金額!T:T)/1000 -> 12432.31 | Q8: =SUMIF(金額!$D:U,$A8,金額!U:U)/1000 -> 0 | R8: =SUMIF(金額!$D:V,$A8,金額!V:V)/1000 -> 0 | S8: =SUMIF(金額!$D:W,$A8,金額!W:W)/1000 -> 4806.835 | T8: =SUM(B8:S8) -> 32010.33 | U8: =T8/$T$11 -> 0.06350604
A9: VISEE | B9: =SUMIF(金額!D:F,A9,金額!F:F)/1000 -> 2433.31 | C9: =SUMIF(金額!$D:G,$A9,金額!G:G)/1000 -> 1181.395 | D9: =SUMIF(金額!$D:H,$A9,金額!H:H)/1000 -> 1765.46 | E9: =SUMIF(金額!$D:I,$A9,金額!I:I)/1000 -> 3503.357 | F9: =SUMIF(金額!$D:J,$A9,金額!J:J)/1000 -> 4396.183 | G9: =SUMIF(金額!$D:K,$A9,金額!K:K)/1000 -> 1534.335 | H9: =SUMIF(金額!$D:L,$A9,金額!L:L)/1000 -> 6648.114 | I9: =SUMIF(金額!$D:M,$A9,金額!M:M)/1000 -> 6303.387 | J9: =SUMIF(金額!$D:N,$A9,金額!N:N)/1000 -> 3963.825 | K9: =SUMIF(金額!$D:O,$A9,金額!O:O)/1000 -> 3906.064 | L9: =SUMIF(金額!$D:P,$A9,金額!P:P)/1000 -> 3989.314 | M9: =SUMIF(金額!$D:Q,$A9,金額!Q:Q)/1000 -> 2860.205 | N9: =SUMIF(金額!$D:R,$A9,金額!R:R)/1000 -> 3202.838 | O9: =SUMIF(金額!$D:S,$A9,金額!S:S)/1000 -> 2717.37 | P9: =SUMIF(金額!$D:T,$A9,金額!T:T)/1000 -> 11704.744 | Q9: =SUMIF(金額!$D:U,$A9,金額!U:U)/1000 -> 0 | R9: =SUMIF(金額!$D:V,$A9,金額!V:V)/1000 -> 0 | S9: =SUMIF(金額!$D:W,$A9,金額!W:W)/1000 -> 6698.216 | T9: =SUM(B9:S9) -> 66808.117 | U9: =T9/$T$11 -> 0.13254218
A10: INFINITY | B10: =SUMIF(金額!D:F,A10,金額!F:F)/1000 -> 0 | C10: =SUMIF(金額!$D:G,$A10,金額!G:G)/1000 -> 0 | D10: =SUMIF(金額!$D:H,$A10,金額!H:H)/1000 -> 0 | E10: =SUMIF(金額!$D:I,$A10,金額!I:I)/1000 -> 0 | F10: =SUMIF(金額!$D:J,$A10,金額!J:J)/1000 -> 0 | G10: =SUMIF(金額!$D:K,$A10,金額!K:K)/1000 -> 0 | H10: =SUMIF(金額!$D:L,$A10,金額!L:L)/1000 -> 0 | I10: =SUMIF(金額!$D:M,$A10,金額!M:M)/1000 -> 0 | J10: =SUMIF(金額!$D:N,$A10,金額!N:N)/1000 -> 0 | K10: =SUMIF(金額!$D:O,$A10,金額!O:O)/1000 -> 0 | L10: =SUMIF(金額!$D:P,$A10,金額!P:P)/1000 -> 0 | M10: =SUMIF(金額!$D:Q,$A10,金額!Q:Q)/1000 -> 0 | N10: =SUMIF(金額!$D:R,$A10,金額!R:R)/1000 -> 0 | O10: =SUMIF(金額!$D:S,$A10,金額!S:S)/1000 -> 0 | P10: =SUMIF(金額!$D:T,$A10,金額!T:T)/1000 -> 383.35 | Q10: =SUMIF(金額!$D:U,$A10,金額!U:U)/1000 -> 0 | R10: =SUMIF(金額!$D:V,$A10,金額!V:V)/1000 -> 0 | S10: =SUMIF(金額!$D:W,$A10,金額!W:W)/1000 -> 1630.805 | T10: =SUM(B10:S10) -> 2014.155 | U10: =T10/$T$11 -> 0.003995929
A11: TTL | B11: =SUM(B4:B10) -> 2958.89 | C11: =SUM(C4:C10) -> 3926.4 | D11: =SUM(D4:D10) -> 2963.305 | E11: =SUM(E4:E10) -> 5776.537 | F11: =SUM(F4:F10) -> 10656.443 | G11: =SUM(G4:G10) -> 7364.98 | H11: =SUM(H4:H10) -> 30890.606 | I11: =SUM(I4:I10) -> 20628.74 | ... T11: =SUM(T4:T10) -> 504051.74 | U11: =T11/$T$11 -> 1
B13: 2958890 | C13: 3926400 | D13: 2963305 | E13: 5776537 | F13: 10656443 | G13: 7364980 | H13: 30890606 | I13: 20628740 | J13: 17188097 | K13: 28318053 | L13: 66469658 | M13: 21138327 | N13: 50492853 | O13: 50070954 | P13: 165876901 | Q13: 0 | R13: 0 | S13: 19330999
T18: =SUM(C18:N18) -> 0
T19: =SUM(C19:N19) -> 0

Sheet アイテム別売上推移
A1: No. | B1: 商品符号 | C1: 商品名称 | D1: 24年7月～25年12月累計
D2: 数量 | E2: 構成比 | F2: 金額（千円） | G2: 構成比
A3: 1 | B3: DLEA | C3: MAKE KEEP MIST EX + | D3: 181809 | E3: =D3/$D$14 -> 0.35378146 | F3: 119682.42 | G3: =F3/$F$14 -> 0.23744074
A4: 2 | B4: MUSC | C4: ONE BY KOSE SERUM SHIELD | D4: 40625 | E4: =D4/$D$14 -> 0.079052037 | F4: 106884.25 | G4: =F4/$F$14 -> 0.21205015
A5: 3 | B5: MUCI | C5: ONE BY KOSE PORE CLEAR OIL（Refill） | D5: 36263 | E5: =D5/$D$14 -> 0.070564038 | F5: 29235.525 | G5: =F5/$F$14 -> 0.058001039
A6: 4 | B6: DLFP | C6: MAKE KEEP POWDER ＥＸ | D6: 23558 | E6: =D6/$D$14 -> 0.045841425 | F6: 16325.694 | G6: =F6/$F$14 -> 0.032388925
A7: 5 | B7: DLIB | C7: CURL KEEP MAGIC | D7: 21800 | E7: =D7/$D$14 -> 0.042420539 | F7: 9306 | G7: =F7/$F$14 -> 0.01846239
A8: 6 | B8: YNRE001 | C8: VISEE ESSENCE LIP PLUMPER SP001 | D8: 9498 | E8: =D8/$D$14 -> 0.018482123 | F8: 6343.48 | G8: =F8/$F$14 -> 0.012584978
A9: 7 | B9: DLCE | C9: MAKE KEEP PRIMER COOL | D9: 7815 | E9: =D9/$D$14 -> 0.01520718 | F9: 5157.9 | G9: =F9/$F$14 -> 0.010232878
A10: 8 | B10: DLCH | C10: MAKE KEEP MIST EX + SAKURA CHERRY | D10: 6700 | E10: =D10/$D$14 -> 0.013037505 | F10: 4422 | G10: =F10/$F$14 -> 0.0087729089
A11: 9 | B11: DLCC | C11: MAKE KEEP MIST EX + COOL | D11: 6456 | E11: =D11/$D$14 -> 0.012562707 | F11: 4260.96 | G11: =F11/$F$14 -> 0.0084534178
A12: 10 | B12: YNRE300 | C12: VISEE ESSENCE LIP PLUMPER BE300 | D12: 6288 | E12: =D12/$D$14 -> 0.012235796 | F12: 3903.9 | G12: =F12/$F$14 -> 0.0077450382
A13: 11 | B13: 11位以下 | D13: =D14-SUM(D3:D12) -> 173090 | E13: =D13/$D$14 -> 0.33681519 | F13: =F14-SUM(F3:F12) -> 198529.61 | G13: =F13/$F$14 -> 0.39386753
A14: TTL | C14: 合計 | D14: 513902 | E14: =D14/$D$14 -> 1 | F14: 504051.74 | G14: =F14/$F$14 -> 1

Sheet top10
A1: 累計
A2: No. | B2: 商品符号 | C2: 商品名称 | D2: 合計
D3: 数量 | E3: 金額
A4: 1 | B4: DLEA | C4: MAKE KEEP MIST EX + | D4: 181809 | E4: 119682420 | F4: =E4/1000 -> 119682.42
A5: 2 | B5: MUSC | C5: ONE BY KOSE SERUM SHIELD | D5: 40625 | E5: 106884250 | F5: =E5/1000 -> 106884.25
A6: 3 | B6: MUCI | C6: ONE BY KOSE PORE CLEAR OIL（Refill） | D6: 36263 | E6: 29235525 | F6: =E6/1000 -> 29235.525
A7: 4 | B7: DLFP | C7: MAKE KEEP POWDER ＥＸ | D7: 23558 | E7: 16325694 | F7: =E7/1000 -> 16325.694
A8: 5 | B8: DLIB | C8: CURL KEEP MAGIC | D8: 21800 | E8: 9306000 | F8: =E8/1000 -> 9306
A9: 6 | B9: YNRE001 | C9: VISEE ESSENCE LIP PLUMPER SP001 | D9: 9498 | E9: 6343480 | F9: =E9/1000 -> 6343.48
