Workbook

Sheet 2026累計
A1: No. | B1: JANコード | C1: 商品符号 | D1: ブランド | E1: 商品名称 | F1: 2601 | H1: 2602 | J1: 2603 | L1: 2604 | N1: 2605 | P1: 2606 | R1: 2607 | T1: 2608 | V1: 2609 | X1: 2610 | Z1: 2611 | AB1: 2612 | AD1: 合計
F2: 数量 | G2: 金額 | H2: 数量 | I2: 金額 | J2: 数量 | K2: 金額 | L2: 数量 | M2: 金額 | N2: 数量 | O2: 金額 | P2: 数量 | Q2: 金額 | R2: 数量 | S2: 金額 | T2: 数量 | U2: 金額 | V2: 数量 | W2: 金額 | X2: 数量 | Y2: 金額 | Z2: 数量 | AA2: 金額 | AB2: 数量 | AC2: 金額 | AD2: 数量 | AE2: 金額
A3: 472 | B3: 4971710631739 | C3: DLCN | D3: MKM | E3: MAKE KEEP MIST EX + COOL S | N3: =VLOOKUP(C3,'[4]レポート 3'!$D:$E,2,0) -> 59472 | O3: =VLOOKUP(C3,'[4]レポート 3'!$D:$F,3,0) -> 42522480 | AD3: =F3+H3+J3+L3+N3+P3+R3+T3+V3+X3+Z3+AB3 -> 59472 | AE3: =G3+I3+K3+M3+O3+Q3+S3+U3+W3+Y3+AA3+AC3 -> 42522480
A4: 2 | B4: 4971710576306 | C4: DLEA | D4: MKM | E4: MAKE KEEP MIST EX + | F4: 20808 | G4: 14877720 | H4: 9000 | I4: 6435000 | J4: =VLOOKUP(C4,[1]Sheet2!$A:$B,2,0 ) -> 7500 | K4: =VLOOKUP(C4,[1]Sheet2!$A:$C,3,0) -> 5362500 | L4: 17640 | M4: 12612600 | N4: 15924 | O4: 11385660 | AD4: =F4+H4+J4+L4+N4+P4+R4+T4+V4+X4+Z4+AB4 -> 70872 | AE4: =G4+I4+K4+M4+O4+Q4+S4+U4+W4+Y4+AA4+AC4 -> 50673480
A5: 473 | B5: 4971710631746 | C5: DLCQ | D5: MKM | E5: MAKE KEEP POWDER EX COOL | N5: =VLOOKUP(C5,'[4]レポート 3'!$D:$E,2,0) -> 7647 | O5: =VLOOKUP(C5,'[4]レポート 3'!$D:$F,3,0) -> 5467605 | AD5: =F5+H5+J5+L5+N5+P5+R5+T5+V5+X5+Z5+AB5 -> 7647 | AE5: =G5+I5+K5+M5+O5+Q5+S5+U5+W5+Y5+AA5+AC5 -> 5467605
A6: 474 | B6: 4971710631951 | C6: DLCR | D6: MKM | E6: MAKE KEEP PRIMER UV COOL | N6: =VLOOKUP(C6,'[4]レポート 3'!$D:$E,2,0) -> 3600 | O6: =VLOOKUP(C6,'[4]レポート 3'!$D:$F,3,0) -> 2574000 | AD6: =F6+H6+J6+L6+N6+P6+R6+T6+V6+X6+Z6+AB6 -> 3600 | AE6: =G6+I6+K6+M6+O6+Q6+S6+U6+W6+Y6+AA6+AC6 -> 2574000
A7: 11 | B7: 4971710598711 | C7: DLFP | D7: MKM | E7: MAKE KEEP POWDER ＥＸ | H7: 606 | I7: 419958 | J7: =VLOOKUP(C7,[1]Sheet2!$A:$B,2,0 ) -> 1128 | K7: =VLOOKUP(C7,[1]Sheet2!$A:$C,3,0) -> 781704 | L7: 5790 | M7: 4012470 | N7: 1344 | O7: 931392 | AD7: =F7+H7+J7+L7+N7+P7+R7+T7+V7+X7+Z7+AB7 -> 8868 | AE7: =G7+I7+K7+M7+O7+Q7+S7+U7+W7+Y7+AA7+AC7 -> 6145524
A8: 6 | B8: 4971710511505 | C8: DLIB | D8: CCS | E8: CURL KEEP MAGIC | F8: 6960 | G8: 3445200 | H8: 1000 | I8: 495000 | J8: =VLOOKUP(C8,[1]Sheet2!$A:$B,2,0 ) -> 1050 | K8: =VLOOKUP(C8,[1]Sheet2!$A:$C,3,0) -> 519750 | L8: 1500 | M8: 742500 | N8: 1050 | O8: 519750 | AD8: =F8+H8+J8+L8+N8+P8+R8+T8+V8+X8+Z8+AB8 -> 11560 | AE8: =G8+I8+K8+M8+O8+Q8+S8+U8+W8+Y8+AA8+AC8 -> 5722200
A9: 7 | B9: 4971710580600 | C9: MTSW | D9: SEKKISEI | E9: SEKKISEI BRIGHTENING ESSENCE LOTION | F9: 480 | G9: 1293600 | H9: 1590 | I9: 4285050 | J9: =VLOOKUP(C9,[1]Sheet2!$A:$B,2,0 ) -> 2144 | K9: =VLOOKUP(C9,[1]Sheet2!$A:$C,3,0) -> 5778080 | L9: 890 | M9: 2398550 | N9: 1020 | O9: 2748900 | AD9: =F9+H9+J9+L9+N9+P9+R9+T9+V9+X9+Z9+AB9 -> 6124 | AE9: =G9+I9+K9+M9+O9+Q9+S9+U9+W9+Y9+AA9+AC9 -> 16504180
A10: 78 | B10: 4971710597707 | C10: DLCA | D10: MKM | E10: MAKE KEEP POWDER EX | H10: 100 | I10: 24700 | J10: =VLOOKUP(C10,[1]Sheet2!$A:$B,2,0 ) -> 0 | K10: =VLOOKUP(C10,[1]Sheet2!$A:$C,3,0) -> 0 | L10: 74 | M10: 18315 | N10: 1000 | O10: 247500 | AD10: =F10+H10+J10+L10+N10+P10+R10+T10+V10+X10+Z10+AB10 -> 1174 | AE10: =G10+I10+K10+M10+O10+Q10+S10+U10+W10+Y10+AA10+AC10 -> 290515
A11: 5 | B11: 4971710565065 | C11: MUSC | D11: ONE BY KOSE | E11: ONE BY KOSE SERUM SHIELD | F11: 1680 | G11: 4989600 | H11: 5000 | I11: 14850000 | J11: =VLOOKUP(C11,[1]Sheet2!$A:$B,2,0 ) -> 4172 | K11: =VLOOKUP(C11,[1]Sheet2!$A:$C,3,0) -> 12390840 | L11: 3248 | M11: 9646560 | N11: 840 | O11: 2494800 | AD11: =F11+H11+J11+L11+N11+P11+R11+T11+V11+X11+Z11+AB11 -> 14940 | AE11: =G11+I11+K11+M11+O11+Q11+S11+U11+W11+Y11+AA11+AC11 -> 44371800
A12: 14 | B12: 4971710576573 | C12: DLEB | D12: MKM | E12: MAKE KEEP MIST EX +＜35mL＞ | F12: 200 | G12: 94600 | H12: 189 | I12: 89397 | J12: =VLOOKUP(C12,[1]Sheet2!$A:$B,2,0 ) -> 678 | K12: =VLOOKUP(C12,[1]Sheet2!$A:$C,3,0) -> 320694 | N12: 690 | O12: 326370 | AD12: =F12+H12+J12+L12+N12+P12+R12+T12+V12+X12+Z12+AB12 -> 1757 | AE12: =G12+I12+K12+M12+O12+Q12+S12+U12+W12+Y12+AA12+AC12 -> 831061
A13: 52 | B13: 4971710522839 | C13: DLID | D13: CCS | E13: CURL KEEP MAGIC ESSENCE REMOVER | F13: 192 | G13: 84480 | N13: 500 | O13: 220000 | AD13: =F13+H13+J13+L13+N13+P13+R13+T13+V13+X13+Z13+AB13 -> 692 | AE13: =G13+I13+K13+M13+O13+Q13+S13+U13+W13+Y13+AA13+AC13 -> 304480
A14: 26 | B14: 4971710622164 | C14: MSYC | D14: ONE BY KOSE | E14: ONE BY KOSE MELANOSHOT P | F14: 50 | G14: 156750 | H14: 216 | I14: 677160 | J14: =VLOOKUP(C14,[1]Sheet2!$A:$B,2,0 ) -> 237 | K14: =VLOOKUP(C14,[1]Sheet2!$A:$C,3,0) -> 742995 | L14: 688 | M14: 2156880 | N14: 476 | O14: 1492260 | AD14: =F14+H14+J14+L14+N14+P14+R14+T14+V14+X14+Z14+AB14 -> 1667 | AE14: =G14+I14+K14+M14+O14+Q14+S14+U14+W14+Y14+AA14+AC14 -> 5226045
A15: 23 | B15: 4971710551006 | C15: YNRE001 | D15: VISEE | E15: VISEE ESSENCE LIP PLUMPER SP001 | H15: 330 | I15: 235950 | J15: =VLOOKUP(C15,[1]Sheet2!$A:$B,2,0 ) -> 252 | K15: =VLOOKUP(C15,[1]Sheet2!$A:$C,3,0) -> 180180 | L15: 80 | M15: 57200 | N15: 470 | O15: 336050 | AD15: =F15+H15+J15+L15+N15+P15+R15+T15+V15+X15+Z15+AB15 -> 1132 | AE15: =G15+I15+K15+M15+O15+Q15+S15+U15+W15+Y15+AA15+AC15 -> 809380
A16: 8 | B16: 4971710561395 | C16: MUCH | D16: ONE BY KOSE | E16: ONE BY KOSE PORE CLEAR OIL | F16: 1606 | G16: 1589940 | H16: 986 | I16: 976140 | J16: =VLOOKUP(C16,[1]Sheet2!$A:$B,2,0 ) -> 292 | K16: =VLOOKUP(C16,[1]Sheet2!$A:$C,3,0) -> 289080 | N16: 432 | O16: 427680 | AD16: =F16+H16+J16+L16+N16+P16+R16+T16+V16+X16+Z16+AB16 -> 3316 | AE16: =G16+I16+K16+M16+O16+Q16+S16+U16+W16+Y16+AA16+AC16 -> 3282840
A17: 41 | B17: 4971710595543 | C17: YNXX006 | D17: VISEE | E17: VISEE W MOOD EYES BL-6 | F17: 30 | G17: 23100 | H17: 120 | I17: 92400 | J17: =VLOOKUP(C17,[1]Sheet2!$A:$B,2,0 ) -> 190 | K17: =VLOOKUP(C17,[1]Sheet2!$A:$C,3,0) -> 146300 | L17: 240 | M17: 184800 | N17: 400 | O17: 308000 | AD17: =F17+H17+J17+L17+N17+P17+R17+T17+V17+X17+Z17+AB17 -> 980 | AE17: =G17+I17+K17+M17+O17+Q17+S17+U17+W17+Y17+AA17+AC17 -> 754600
A18: 22 | B18: 4971710571868 | C18: MTSD | D18: SEKKISEI | E18: SEKKISEI BRIGHTENING EMULSION | H18: 180 | I18: 405900 | J18: =VLOOKUP(C18,[1]Sheet2!$A:$B,2,0 ) -> 473 | K18: =VLOOKUP(C18,[1]Sheet2!$A:$C,3,0) -> 1066615 | L18: 127 | M18: 286385 | N18: 377 | O18: 850135 | AD18: =F18+H18+J18+L18+N18+P18+R18+T18+V18+X18+Z18+AB18 -> 1157 | AE18: =G18+I18+K18+M18+O18+Q18+S18+U18+W18+Y18+AA18+AC18 -> 2609035
A19: 10 | B19: 4971710580396 | C19: MUXD | D19: ONE BY KOSE | E19: ONE BY KOSE SERUM VEIL DEEP REPAIR | F19: 572 | G19: 2831400 | H19: 440 | I19: 2178000 | J19: =VLOOKUP(C19,[1]Sheet2!$A:$B,2,0 ) -> 744 | K19: =VLOOKUP(C19,[1]Sheet2!$A:$C,3,0) -> 3682800 | L19: 320 | M19: 1584000 | N19: 366 | O19: 1811700 | AD19: =F19+H19+J19+L19+N19+P19+R19+T19+V19+X19+Z19+AB19 -> 2442 | AE19: =G19+I19+K19+M19+O19+Q19+S19+U19+W19+Y19+AA19+AC19 -> 12087900
A20: 16 | B20: 4971710592955 | C20: YNGC001 | D20: VISEE | E20: VISEE COLOR DUO TRICK CONCEALER 01 | F20: 20 | G20: 12100 | H20: 610 | I20: 369050 | J20: =VLOOKUP(C20,[1]Sheet2!$A:$B,2,0 ) -> 306 | K20: =VLOOKUP(C20,[1]Sheet2!$A:$C,3,0) -> 185130 | L20: 1518 | M20: 918390 | N20: 362 | O20: 219010 | AD20: =F20+H20+J20+L20+N20+P20+R20+T20+V20+X20+Z20+AB20 -> 2816 | AE20: =G20+I20+K20+M20+O20+Q20+S20+U20+W20+Y20+AA20+AC20 -> 1703680
A21: 28 | B21: 4971710577341 | C21: MUXA | D21: ONE BY KOSE | E21: ONE BY KOSE SERUM VEIL DEEP REPAIR | F21: 112 | G21: 332640 | H21: 388 | I21: 1152360 | L21: 700 | M21: 2079000 | N21: 342 | O21: 1015740 | AD21: =F21+H21+J21+L21+N21+P21+R21+T21+V21+X21+Z21+AB21 -> 1542 | AE21: =G21+I21+K21+M21+O21+Q21+S21+U21+W21+Y21+AA21+AC21 -> 4579740
A22: 42 | B22: 4971710585278 | C22: MTOL | D22: SEKKISEI | E22: SEKKISEI BRIGHTENING FOAM CLEANSER | F22: 120 | G22: 151800 | J22: =VLOOKUP(C22,[1]Sheet2!$A:$B,2,0 ) -> 210 | K22: =VLOOKUP(C22,[1]Sheet2!$A:$C,3,0) -> 265650 | L22: 72 | M22: 91080 | N22: 330 | O22: 417450 | AD22: =F22+H22+J22+L22+N22+P22+R22+T22+V22+X22+Z22+AB22 -> 732 | AE22: =G22+I22+K22+M22+O22+Q22+S22+U22+W22+Y22+AA22+AC22 -> 925980
A23: 29 | B23: 4971710613285 | C23: MUVF | D23: ONE BY KOSE | E23: ONE BY KOSE THE WRINKLESS W | F23: 100 | G23: 412500 | H23: 100 | I23: 412500 | J23: =VLOOKUP(C23,[1]Sheet2!$A:$B,2,0 ) -> 297 | K23: =VLOOKUP(C23,[1]Sheet2!$A:$C,3,0) -> 1225125 | L23: 420 | M23: 1732500 | N23: 314 | O23: 1295250 | AD23: =F23+H23+J23+L23+N23+P23+R23+T23+V23+X23+Z23+AB23 -> 1231 | AE23: =G23+I23+K23+M23+O23+Q23+S23+U23+W23+Y23+AA23+AC23 -> 5077875
A24: 75 | B24: 4971710563238 | C24: DLBK | D24: MKM | E24: MAKE KEEP PRIMER | H24: 30 | I24: 19800 | J24: =VLOOKUP(C24,[1]Sheet2!$A:$B,2,0 ) -> 78 | K24: =VLOOKUP(C24,[1]Sheet2!$A:$C,3,0) -> 51480 | N24: 312 | O24: 205920 | AD24: =F24+H24+J24+L24+N24+P24+R24+T24+V24+X24+Z24+AB24 -> 420 | AE24: =G24+I24+K24+M24+O24+Q24+S24+U24+W24+Y24+AA24+AC24 -> 277200
A25: 38 | B25: 4971710619867 | C25: YNXX007 | D25: VISEE | E25: VISEE W MOOD EYES BE-7 | H25: 360 | I25: 277200 | L25: 813 | M25: 626010 | N25: 306 | O25: 235620 | AD25: =F25+H25+J25+L25+N25+P25+R25+T25+V25+X25+Z25+AB25 -> 1479 | AE25: =G25+I25+K25+M25+O25+Q25+S25+U25+W25+Y25+AA25+AC25 -> 1138830
A26: 30 | B26: 4971710557787 | C26: DXPO000 | D26: FASIO | E26: FASIO PORE SMOOTH PRIMER 00 | F26: 220 | G26: 108900 | H26: 200 | I26: 99000 | J26: =VLOOKUP(C26,[1]Sheet2!$A:$B,2,0 ) -> 50 | K26: =VLOOKUP(C26,[1]Sheet2!$A:$C,3,0) -> 24750 | L26: 42 | M26: 20790 | N26: 300 | O26: 148500 | AD26: =F26+H26+J26+L26+N26+P26+R26+T26+V26+X26+Z26+AB26 -> 812 | AE26: =G26+I26+K26+M26+O26+Q26+S26+U26+W26+Y26+AA26+AC26 -> 401940
A27: 216 | B27: 4971710494914 | C27: YNUR002 | D27: VISEE | E27: VISEE AVANT LIP & EYE COLOR PENCIL 002 | F27: 12 | G27: 7920 | L27: 165 | M27: 108900 | N27: 282 | O27: 186120 | AD27: =F27+H27+J27+L27+N27+P27+R27+T27+V27+X27+Z27+AB27 -> 459 | AE27: =G27+I27+K27+M27+O27+Q27+S27+U27+W27+Y27+AA27+AC27 -> 302940
A28: 13 | B28: 4971710546071 | C28: MUZU | D28: ONE BY KOSE | E28: ONE BY KOSE DEEP HYDRATOR | F28: 132 | G28: 210540 | H28: 620 | I28: 988900 | J28: =VLOOKUP(C28,[1]Sheet2!$A:$B,2,0 ) -> 474 | K28: =VLOOKUP(C28,[1]Sheet2!$A:$C,3,0) -> 756030 | L28: 400 | M28: 638000 | N28: 256 | O28: 408320 | AD28: =F28+H28+J28+L28+N28+P28+R28+T28+V28+X28+Z28+AB28 -> 1882 | AE28: =G28+I28+K28+M28+O28+Q28+S28+U28+W28+Y28+AA28+AC28 -> 3001790
A29: 9 | B29: 4971710581928 | C29: MTSX | D29: SEKKISEI | E29: SEKKISEI BRIGHTENING EMULSION | F29: 120 | G29: 224400 | H29: 1010 | I29: 1888700 | J29: =VLOOKUP(C29,[1]Sheet2!$A:$B,2,0 ) -> 1440 | K29: =VLOOKUP(C29,[1]Sheet2!$A:$C,3,0) -> 2692800 | L29: 372 | M29: 695640 | N29: 240 | O29: 448800 | AD29: =F29+H29+J29+L29+N29+P29+R29+T29+V29+X29+Z29+AB29 -> 3182 | AE29: =G29+I29+K29+M29+O29+Q29+S29+U29+W29+Y29+AA29+AC29 -> 5950340
A30: 33 | B30: 4971710585261 | C30: MTOK | D30: SEKKISEI | E30: SEKKISEI BRIGHTENING CLEANSING OIL | F30: 120 | G30: 145200 | H30: 80 | I30: 96800 | J30: =VLOOKUP(C30,[1]Sheet2!$A:$B,2,0 ) -> 240 | K30: =VLOOKUP(C30,[1]Sheet2!$A:$C,3,0) -> 290400 | L30: 27 | M30: 32670 | N30: 240 | O30: 290400 | AD30: =F30+H30+J30+L30+N30+P30+R30+T30+V30+X30+Z30+AB30 -> 707 | AE30: =G30+I30+K30+M30+O30+Q30+S30+U30+W30+Y30+AA30+AC30 -> 855470
A31: 12 | B31: 4971710573855 | C31: MTSC | D31: SEKKISEI | E31: SEKKISEI BRIGHTENING ESSENCE LOTION | H31: 200 | I31: 418000 | J31: =VLOOKUP(C31,[1]Sheet2!$A:$B,2,0 ) -> 1173 | K31: =VLOOKUP(C31,[1]Sheet2!$A:$C,3,0) -> 2451570 | L31: 24 | M31: 50160 | N31: 234 | O31: 489060 | AD31: =F31+H31+J31+L31+N31+P31+R31+T31+V31+X31+Z31+AB31 -> 1631 | AE31: =G31+I31+K31+M31+O31+Q31+S31+U31+W31+Y31+AA31+AC31 -> 3408790
A32: 24 | B32: 4971710582338 | C32: MTSY | D32: SEKKISEI | E32: SEKKISEI BRIGHTENING CREAM | F32: 192 | G32: 411840 | J32: =VLOOKUP(C32,[1]Sheet2!$A:$B,2,0 ) -> 372 | K32: =VLOOKUP(C32,[1]Sheet2!$A:$C,3,0) -> 797940 | L32: 108 | M32: 231660 | N32: 216 | O32: 463320 | AD32: =F32+H32+J32+L32+N32+P32+R32+T32+V32+X32+Z32+AB32 -> 888 | AE32: =G32+I32+K32+M32+O32+Q32+S32+U32+W32+Y32+AA32+AC32 -> 1904760
A33: 31 | B33: 4971710622201 | C33: MSYF | D33: ONE BY KOSE | E33: ONE BY KOSE MELANOSHOT P | H33: 316 | I33: 1286120 | J33: =VLOOKUP(C33,[1]Sheet2!$A:$B,2,0 ) -> 152 | K33: =VLOOKUP(C33,[1]Sheet2!$A:$C,3,0) -> 618640 | N33: 200 | O33: 814000 | AD33: =F33+H33+J33+L33+N33+P33+R33+T33+V33+X33+Z33+AB33 -> 668 | AE33: =G33+I33+K33+M33+O33+Q33+S33+U33+W33+Y33+AA33+AC33 -> 2718760
A34: 32 | B34: 4971710622188 | C34: MSYD | D34: ONE BY KOSE | E34: ONE BY KOSE MELANOSHOT P | F34: 50 | G34: 148500 | H34: 216 | I34: 641520 | J34: =VLOOKUP(C34,[1]Sheet2!$A:$B,2,0 ) -> 187 | K34: =VLOOKUP(C34,[1]Sheet2!$A:$C,3,0) -> 555390 | N34: 200 | O34: 594000 | AD34: =F34+H34+J34+L34+N34+P34+R34+T34+V34+X34+Z34+AB34 -> 653 | AE34: =G34+I34+K34+M34+O34+Q34+S34+U34+W34+Y34+AA34+AC34 -> 1939410
A35: 19 | B35: 4971710599954 | C35: MUSH | D35: ONE BY KOSE | E35: ONE BY KOSE SERUM VEIL LOTION | F35: 126 | G35: 180180 | H35: 275 | I35: 393250 | J35: =VLOOKUP(C35,[1]Sheet2!$A:$B,2,0 ) -> 488 | K35: =VLOOKUP(C35,[1]Sheet2!$A:$C,3,0) -> 697840 | L35: 650 | M35: 929500 | N35: 182 | O35: 260260 | AD35: =F35+H35+J35+L35+N35+P35+R35+T35+V35+X35+Z35+AB35 -> 1721 | AE35: =G35+I35+K35+M35+O35+Q35+S35+U35+W35+Y35+AA35+AC35 -> 2461030
A36: 91 | B36: 4971710556865 | C36: YNST300 | D36: VISEE | E36: VISEE SHADE TRICK BR300 | H36: 70 | I36: 61600 | J36: =VLOOKUP(C36,[1]Sheet2!$A:$B,2,0 ) -> 15 | K36: =VLOOKUP(C36,[1]Sheet2!$A:$C,3,0) -> 13200 | L36: 15 | M36: 13200 | N36: 180 | O36: 158400 | AD36: =F36+H36+J36+L36+N36+P36+R36+T36+V36+X36+Z36+AB36 -> 280 | AE36: =G36+I36+K36+M36+O36+Q36+S36+U36+W36+Y36+AA36+AC36 -> 246400
A37: 489 | B37: 4971710633009 | C37: YNRJ681 | D37: VISEE | E37: VISEE ESSENCE PLUMP BALM RO681 | N37: =VLOOKUP(C37,'[4]レポート 3'!$D:$E,2,0) -> 180 | O37: =VLOOKUP(C37,'[4]レポート 3'!$D:$F,3,0) -> 148500 | AD37: =F37+H37+J37+L37+N37+P37+R37+T37+V37+X37+Z37+AB37 -> 180 | AE37: =G37+I37+K37+M37+O37+Q37+S37+U37+W37+Y37+AA37+AC37 -> 148500
A38: 490 | B38: 4971710633078 | C38: YNRJ882 | D38: VISEE | E38: VISEE ESSENCE PLUMP BALM PK882 | N38: =VLOOKUP(C38,'[4]レポート 3'!$D:$E,2,0) -> 180 | O38: =VLOOKUP(C38,'[4]レポート 3'!$D:$F,3,0) -> 148500 | AD38: =F38+H38+J38+L38+N38+P38+R38+T38+V38+X38+Z38+AB38 -> 180 | AE38: =G38+I38+K38+M38+O38+Q38+S38+U38+W38+Y38+AA38+AC38 -> 148500
A39: 68 | B39: 4971710588163 | C39: DLSC | D39: CCS | E39: SUPER UV PROTECTOR | H39: 30 | I39: 21450 | J39: =VLOOKUP(C39,[1]Sheet2!$A:$B,2,0 ) -> 93 | K39: =VLOOKUP(C39,[1]Sheet2!$A:$C,3,0) -> 66495 | L39: 2570 | M39: 1837550 | N39: 170 | O39: 121550 | AD39: =F39+H39+J39+L39+N39+P39+R39+T39+V39+X39+Z39+AB39 -> 2863 | AE39: =G39+I39+K39+M39+O39+Q39+S39+U39+W39+Y39+AA39+AC39 -> 2047045
A40: 61 | B40: 4971710599985 | C40: MUSO | D40: ONE BY KOSE | E40: ONE BY KOSE SERUM VEIL EMULSION | H40: 5 | I40: 7975 | J40: =VLOOKUP(C40,[1]Sheet2!$A:$B,2,0 ) -> 162 | K40: =VLOOKUP(C40,[1]Sheet2!$A:$C,3,0) -> 258390 | L40: 400 | M40: 638000 | N40: 170 | O40: 271150 | AD40: =F40+H40+J40+L40+N40+P40+R40+T40+V40+X40+Z40+AB40 -> 737 | AE40: =G40+I40+K40+M40+O40+Q40+S40+U40+W40+Y40+AA40+AC40 -> 1175515
...

Sheet ブランド別実績
A1: 1月 | G1: 年間トータル
A2: ブランド | B2: 数量 | C2: 構成比 | D2: 金額 | E2: 構成比 | G2: ブランド | H2: 数量 | I2: 構成比 | J2: 金額 | K2: 構成比
A3: VISEE | B3: =SUMIF('2026累計'!D:D,ブランド別実績!A3,'2026累計'!F:F) -> 870 | C3: =B3/$B$10 -> 0.011272642 | D3: =SUMIF('2026累計'!D:D,ブランド別実績!A3,'2026累計'!G:G) -> 622875 | E3: =D3/$D$10 -> 0.0093848672 | G3: VISEE | H3: =SUMIF('2026累計'!D:D,ブランド別実績!G3,'2026累計'!AD:AD) -> 25748 | I3: =H3/$B$10 -> 0.33361839 | J3: =SUMIF('2026累計'!D:D,ブランド別実績!G3,'2026累計'!AE:AE) -> 18220170 | K3: =J3/$D$10 -> 0.27452358
A4: FASIO | B4: =SUMIF('2026累計'!D:D,ブランド別実績!A4,'2026累計'!F:F) -> 1290 | C4: =B4/$B$10 -> 0.016714608 | D4: =SUMIF('2026累計'!D:D,ブランド別実績!A4,'2026累計'!G:G) -> 806180 | E4: =D4/$D$10 -> 0.012146727 | G4: FASIO | H4: =SUMIF('2026累計'!D:D,ブランド別実績!G4,'2026累計'!AD:AD) -> 7962 | I4: =H4/$B$10 -> 0.10316411 | J4: =SUMIF('2026累計'!D:D,ブランド別実績!G4,'2026累計'!AE:AE) -> 5071117 | K4: =J4/$D$10 -> 0.076406598
A5: ONE BY KOSE | B5: =SUMIF('2026累計'!D:D,ブランド別実績!A5,'2026累計'!F:F) -> 16674 | C5: =B5/$B$10 -> 0.21604602 | D5: =SUMIF('2026累計'!D:D,ブランド別実績!A5,'2026累計'!G:G) -> 23078830 | E5: =D5/$D$10 -> 0.34772909 | G5: ONE BY KOSE | H5: =SUMIF('2026累計'!D:D,ブランド別実績!G5,'2026累計'!AD:AD) -> 71109 | I5: =H5/$B$10 -> 0.9213636 | J5: =SUMIF('2026累計'!D:D,ブランド別実績!G5,'2026累計'!AE:AE) -> 131816910 | K5: =J5/$D$10 -> 1.9860874
A6: MKM | B6: =SUMIF('2026累計'!D:D,ブランド別実績!A6,'2026累計'!F:F) -> 49808 | C6: =B6/$B$10 -> 0.64536526 | D6: =SUMIF('2026累計'!D:D,ブランド別実績!A6,'2026累計'!G:G) -> 35564320 | E6: =D6/$D$10 -> 0.53584816 | G6: MKM | H6: =SUMIF('2026累計'!D:D,ブランド別実績!G6,'2026累計'!AD:AD) -> 206601 | I6: =H6/$B$10 -> 2.6769416 | J6: =SUMIF('2026累計'!D:D,ブランド別実績!G6,'2026累計'!AE:AE) -> 146527430 | K6: =J6/$D$10 -> 2.2077311
A7: CCS | B7: =SUMIF('2026累計'!D:D,ブランド別実績!A7,'2026累計'!F:F) -> 7152 | C7: =B7/$B$10 -> 0.092668895 | D7: =SUMIF('2026累計'!D:D,ブランド別実績!A7,'2026累計'!G:G) -> 3529680 | E7: =D7/$D$10 -> 0.053181743 | G7: CCS | H7: =SUMIF('2026累計'!D:D,ブランド別実績!G7,'2026累計'!AD:AD) -> 15115 | I7: =H7/$B$10 -> 0.19584597 | J7: =SUMIF('2026累計'!D:D,ブランド別実績!G7,'2026累計'!AE:AE) -> 8073725 | K7: =J7/$D$10 -> 0.12164694
A8: SEKKISEI | B8: =SUMIF('2026累計'!D:D,ブランド別実績!A8,'2026累計'!F:F) -> 1284 | C8: =B8/$B$10 -> 0.016636865 | D8: =SUMIF('2026累計'!D:D,ブランド別実績!A8,'2026累計'!G:G) -> 2680260 | E8: =D8/$D$10 -> 0.040383519 | G8: SEKKISEI | H8: =SUMIF('2026累計'!D:D,ブランド別実績!G8,'2026累計'!AD:AD) -> 16532 | I8: =H8/$B$10 -> 0.21420612 | J8: =SUMIF('2026累計'!D:D,ブランド別実績!G8,'2026累計'!AE:AE) -> 36130567 | K8: =J8/$D$10 -> 0.54437981
A9: INFINITY | B9: =SUMIF('2026累計'!D:D,ブランド別実績!A9,'2026累計'!F:F) -> 100 | C9: =B9/$B$10 -> 0.001295706 | D9: =SUMIF('2026累計'!D:D,ブランド別実績!A9,'2026累計'!G:G) -> 88000 | E9: =D9/$D$10 -> 0.0013258974 | G9: INFINITY | H9: =SUMIF('2026累計'!D:D,ブランド別実績!G9,'2026累計'!AD:AD) -> 1395 | I9: =H9/$B$10 -> 0.018075099 | J9: =SUMIF('2026累計'!D:D,ブランド別実績!G9,'2026累計'!AE:AE) -> 2930345 | K9: =J9/$D$10 -> 0.044151553
A10: 合計 | B10: =SUM(B3:B9) -> 77178 | C10: =B10/$B$10 -> 1 | D10: =SUM(D3:D9) -> 66370145 | E10: =D10/$D$10 -> 1 | G10: 合計 | H10: =SUM(H3:H9) -> 344462 | I10: =H10/$B$10 -> 4.4632149 | J10: =SUM(J3:J9) -> 348770264 | K10: =J10/$D$10 -> 5.254927
A12: 2月
A13: ブランド | B13: 数量 | C13: 構成比 | D13: 金額 | E13: 構成比
A14: VISEE | B14: =SUMIF('2026累計'!D:D,ブランド別実績!A14,'2026累計'!H:H) -> 6580 | C14: =B14/$B$10 -> 0.085257457 | D14: =SUMIF('2026累計'!D:D,ブランド別実績!A14,'2026累計'!I:I) -> 4788422 | E14: =D14/$D$10 -> 0.072147228
A15: FASIO | B15: =SUMIF('2026累計'!D:D,ブランド別実績!A15,'2026累計'!H:H) -> 1230 | C15: =B15/$B$10 -> 0.015937184 | D15: =SUMIF('2026累計'!D:D,ブランド別実績!A15,'2026累計'!I:I) -> 752920 | E15: =D15/$D$10 -> 0.011344257
A16: ONE BY KOSE | B16: =SUMIF('2026累計'!D:D,ブランド別実績!A16,'2026累計'!H:H) -> 24412 | C16: =B16/$B$10 -> 0.31630776 | D16: =SUMIF('2026累計'!D:D,ブランド別実績!A16,'2026累計'!I:I) -> 41886680 | E16: =D16/$D$10 -> 0.63110725
A17: MKM | B17: =SUMIF('2026累計'!D:D,ブランド別実績!A17,'2026累計'!H:H) -> 10141 | C17: =B17/$B$10 -> 0.13139755 | D17: =SUMIF('2026累計'!D:D,ブランド別実績!A17,'2026累計'!I:I) -> 7143295 | E17: =D17/$D$10 -> 0.10762814
A18: CCS | B18: =SUMIF('2026累計'!D:D,ブランド別実績!A18,'2026累計'!H:H) -> 1030 | C18: =B18/$B$10 -> 0.013345772 | D18: =SUMIF('2026累計'!D:D,ブランド別実績!A18,'2026累計'!I:I) -> 516450 | E18: =D18/$D$10 -> 0.0077813601
A19: SEKKISEI | B19: =SUMIF('2026累計'!D:D,ブランド別実績!A19,'2026累計'!H:H) -> 3233 | C19: =B19/$B$10 -> 0.041890176 | D19: =SUMIF('2026累計'!D:D,ブランド別実績!A19,'2026累計'!I:I) -> 7390570 | E19: =D19/$D$10 -> 0.11135383
A20: INFINITY | B20: =SUMIF('2026累計'!D:D,ブランド別実績!A20,'2026累計'!H:H) -> 506 | C20: =B20/$B$10 -> 0.0065562725 | D20: =SUMIF('2026累計'!D:D,ブランド別実績!A20,'2026累計'!I:I) -> 1157915 | E20: =D20/$D$10 -> 0.017446323
A21: 合計 | B21: =SUM(B14:B20) -> 47132 | C21: =B21/$B$10 -> 0.61069217 | D21: =SUM(D14:D20) -> 63636252 | E21: =D21/$D$10 -> 0.95880839
A23: 3月
A24: ブランド | B24: 数量 | C24: 構成比 | D24: 金額 | E24: 構成比
A25: VISEE | B25: =SUMIF('2026累計'!D:D,ブランド別実績!A25,'2026累計'!J:J) -> 5264 | C25: =B25/$B$10 -> 0.068205965 | D25: =SUMIF('2026累計'!D:D,ブランド別実績!A25,'2026累計'!K:K) -> 3778390 | E25: =D25/$D$10 -> 0.05692906
A26: FASIO | B26: =SUMIF('2026累計'!D:D,ブランド別実績!A26,'2026累計'!J:J) -> 1616 | C26: =B26/$B$10 -> 0.020938609 | D26: =SUMIF('2026累計'!D:D,ブランド別実績!A26,'2026累計'!K:K) -> 1076870 | E26: =D26/$D$10 -> 0.016225217
A27: MKM | B27: =SUMIF('2026累計'!D:D,ブランド別実績!A27,'2026累計'!J:J) -> 18816 | C27: =B27/$B$10 -> 0.24380005 | D27: =SUMIF('2026累計'!D:D,ブランド別実績!A27,'2026累計'!K:K) -> 13260258 | E27: =D27/$D$10 -> 0.19979251
A28: CCS | B28: =SUMIF('2026累計'!D:D,ブランド別実績!A28,'2026累計'!J:J) -> 1143 | C28: =B28/$B$10 -> 0.01480992 | D28: =SUMIF('2026累計'!D:D,ブランド別実績!A28,'2026累計'!K:K) -> 586245 | E28: =D28/$D$10 -> 0.0088329625
A29: ONE BY KOSE | B29: =SUMIF('2026累計'!D:D,ブランド別実績!A29,'2026累計'!J:J) -> 13421 | C29: =B29/$B$10 -> 0.17389671 | D29: =SUMIF('2026累計'!D:D,ブランド別実績!A29,'2026累計'!K:K) -> 27736940 | E29: =D29/$D$10 -> 0.4179129
A30: SEKKISEI | B30: =SUMIF('2026累計'!D:D,ブランド別実績!A30,'2026累計'!J:J) -> 6740 | C30: =B30/$B$10 -> 0.087330586 | D30: =SUMIF('2026累計'!D:D,ブランド別実績!A30,'2026累計'!K:K) -> 14504193 | E30: =D30/$D$10 -> 0.2185349
A31: INFINITY | B31: =SUMIF('2026累計'!D:D,ブランド別実績!A31,'2026累計'!J:J) -> 349 | C31: =B31/$B$10 -> 0.004522014 | D31: =SUMIF('2026累計'!D:D,ブランド別実績!A31,'2026累計'!K:K) -> 679140 | E31: =D31/$D$10 -> 0.010232613
A32: 合計 | B32: =SUM(B25:B31) -> 47349 | C32: =B32/$B$10 -> 0.61350385 | D32: =SUM(D25:D31) -> 61622036 | E32: =D32/$D$10 -> 0.92846017
A34: 4月
A35: ブランド | B35: 数量 | C35: 構成比 | D35: 金額 | E35: 構成比
A36: VISEE | B36: =SUMIF('2026累計'!D:D,ブランド別実績!A36,'2026累計'!L:L) -> 7106 | C36: =B36/$B$10 -> 0.092072871 | D36: =SUMIF('2026累計'!D:D,ブランド別実績!A36,'2026累計'!M:M) -> 4816768 | E36: =D36/$D$10 -> 0.072574318
A37: FASIO | B37: =SUMIF('2026累計'!D:D,ブランド別実績!A37,'2026累計'!L:L) -> 1675 | C37: =B37/$B$10 -> 0.021703076 | D37: =SUMIF('2026累計'!D:D,ブランド別実績!A37,'2026累計'!M:M) -> 1126367 | E37: =D37/$D$10 -> 0.016970989
A38: MKM | B38: =SUMIF('2026累計'!D:D,ブランド別実績!A38,'2026累計'!L:L) -> 37847 | C38: =B38/$B$10 -> 0.49038586 | D38: =SUMIF('2026累計'!D:D,ブランド別実績!A38,'2026累計'!M:M) -> 26898630 | E38: =D38/$D$10 -> 0.40528207
A39: CCS | B39: =SUMIF('2026累計'!D:D,ブランド別実績!A39,'2026累計'!L:L) -> 4070 | C39: =B39/$B$10 -> 0.052735235 | D39: =SUMIF('2026累計'!D:D,ブランド別実績!A39,'2026累計'!M:M) -> 2580050 | E39: =D39/$D$10 -> 0.038873653
A40: ONE BY KOSE | B40: =SUMIF('2026累計'!D:D,ブランド別実績!A40,'2026累計'!L:L) -> 12206 | C40: =B40/$B$10 -> 0.15815388 | D40: =SUMIF('2026累計'!D:D,ブランド別実績!A40,'2026累計'!M:M) -> 26945490 | E40: =D40/$D$10 -> 0.40598811
A41: SEKKISEI | B41: =SUMIF('2026累計'!D:D,ブランド別実績!A41,'2026累計'!L:L) -> 2066 | C41: =B41/$B$10 -> 0.026769287 | D41: =SUMIF('2026累計'!D:D,ブランド別実績!A41,'2026累計'!M:M) -> 4831761 | E41: =D41/$D$10 -> 0.072800218
A42: INFINITY | B42: =SUMIF('2026累計'!D:D,ブランド別実績!A42,'2026累計'!L:L) -> 36 | C42: =B42/$B$10 -> 0.00046645417 | D42: =SUMIF('2026累計'!D:D,ブランド別実績!A42,'2026累計'!M:M) -> 87450 | E42: =D42/$D$10 -> 0.0013176105
A43: 合計 | B43: =SUM(B36:B42) -> 65006 | C43: =B43/$B$10 -> 0.84228666 | D43: =SUM(D36:D42) -> 67286516 | E43: =D43/$D$10 -> 1.013807
...

Sheet ブランド別売上推移
O1: 単位：千円
A2: ブランド | B2: 2024 | H2: 2025 | O2: 合計
B3: 7月 | C3: 8月 | D3: 9月 | E3: 10月 | F3: 11月 | G3: 12月 | H3: 1月 | I3: 2月 | J3: 3月 | K3: 4月 | L3: 5月 | M3: 6月 | N3: 7月 | O3: 金額 | P3: 構成比
A4: MAKE KEEP | B4: 0 | C4: 501.6 | D4: 128.7 | E4: 120.34 | F4: 729.96 | G4: 126.5 | H4: 2071.08 | I4: 2502.94 | J4: 5663.68 | K4: 11088.88 | L4: 21080.84 | M4: 11433.306 | N4: 29359.902 | O4: =SUM(B4:N4) -> 84807.728 | P4: =O4/$O$10 -> 0.3121872
A5: CURL KEEP | B5: 0 | C5: 20.35 | D5: 14.85 | E5: 0 | F5: 273.24 | G5: 0 | H5: 1438.8 | I5: 1485 | J5: 70.4 | K5: 1078 | L5: 24.75 | M5: 0 | N5: 1889.25 | O5: =SUM(B5:N5) -> 6294.64 | P5: =O5/$O$10 -> 0.023171308
A6: FASIO | B6: 73.48 | C6: 451.78 | D6: 290.895 | E6: 564.44 | F6: 967.005 | G6: 324.65 | H6: 2021.557 | I6: 474.813 | J6: 420.932 | K6: 955.094 | L6: 1416.264 | M6: 230.406 | N6: 1344.808 | O6: =SUM(B6:N6) -> 9536.124 | P6: =O6/$O$10 -> 0.035103591
A7: ONE BY KOSE | B7: 528 | C7: 1771.275 | D7: 953.15 | E7: 1702.25 | F7: 4365.955 | G7: 5857.665 | H7: 19166.455 | I7: 12896.51 | J7: 7596.765 | K7: 11935.165 | L7: 34265.88 | M7: 6872.69 | N7: 13735.425 | O7: =SUM(B7:N7) -> 121647.19 | P7: =O7/$O$10 -> 0.44779756
A8: SEK BRIGHTENING | B8: 0 | C8: 0 | D8: 0 | E8: 0 | F8: 0 | G8: 0 | H8: 0 | I8: 0 | J8: 0 | K8: 0 | L8: 6288.425 | M8: 136.4 | N8: 1681.68 | O8: =SUM(B8:N8) -> 8106.505 | P8: =O8/$O$10 -> 0.029840996
A9: VISEE | B9: 2357.41 | C9: 1181.395 | D9: 1575.71 | E9: 3389.507 | F9: 4320.283 | G9: 1056.165 | H9: 6192.714 | I9: 6153.237 | J9: 3436.32 | K9: 3260.914 | L9: 3393.499 | M9: 2465.525 | N9: 2481.788 | O9: =SUM(B9:N9) -> 41264.467 | P9: =O9/$O$10 -> 0.15189934
A10: TTL | B10: =SUM(B4:B9) -> 2958.89 | C10: =SUM(C4:C9) -> 3926.4 | D10: =SUM(D4:D9) -> 2963.305 | E10: =SUM(E4:E9) -> 5776.537 | F10: =SUM(F4:F9) -> 10656.443 | G10: =SUM(G4:G9) -> 7364.98 | H10: =SUM(H4:H9) -> 30890.606 | I10: =SUM(I4:I9) -> 23512.5 | ... O10: =SUM(O4:O9) -> 271656.65 | P10: =O10/$O$10 -> 1
C14: 501600 | D14: 128700 | E14: 120340 | F14: 729960 | G14: 126500 | H14: 2071080 | I14: 2502940 | J14: 5663680 | K14: 11088880 | L14: 21080840 | M14: 11433306 | N14: 29359902
C15: 20350 | D15: 14850 | F15: 273240 | H15: 1438800 | I15: 1485000 | J15: 70400 | K15: 1078000 | L15: 24750 | N15: 1889250
C17: =C14/1000 -> 501.6 | D17: =D14/1000 -> 128.7 | E17: =E14/1000 -> 120.34 | F17: =F14/1000 -> 729.96 | G17: =G14/1000 -> 126.5 | H17: =H14/1000 -> 2071.08 | I17: =I14/1000 -> 2502.94 | J17: =J14/1000 -> 5663.68 | ... N17: =N14/1000 -> 29359.902 | O17: =SUM(C17:N17) -> 84807.728
C18: =C15/1000 -> 20.35 | D18: =D15/1000 -> 14.85 | E18: =E15/1000 -> 0 | F18: =F15/1000 -> 273.24 | G18: =G15/1000 -> 0 | H18: =H15/1000 -> 1438.8 | I18: =I15/1000 -> 1485 | J18: =J15/1000 -> 70.4 | ... N18: =N15/1000 -> 1889.25 | O18: =SUM(C18:N18) -> 6294.64

Sheet アイテム別売上推移
A1: No. | B1: 商品符号 | C1: 商品名称 | D1: 2025年1~9月累計
D2: 数量 | E2: 構成比 | F2: 金額（千円） | G2: 構成比
A3: 1 | B3: DLEA | C3: MAKE KEEP MIST EX + | D3: 165812 | E3: =D3/$D$14 -> 0.38453529 | F3: 109435.92 | G3: =F3/$F$14 -> 0.24681197
A4: 2 | B4: MUSC | C4: ONE BY KOSE SERUM SHIELD | D4: 37000 | E4: =D4/$D$14 -> 0.085806851 | F4: 101750 | G4: =F4/$F$14 -> 0.22947783
A5: 3 | B5: MUCI | C5: ONE BY KOSE PORE CLEAR OIL（Refill） | D5: 34332 | E5: =D5/$D$14 -> 0.079619481 | F5: 28323.9 | G5: =F5/$F$14 -> 0.063879186
A6: 4 | B6: DLFP | C6: MAKE KEEP POWDER ＥＸ | D6: 23462 | E6: =D6/$D$14 -> 0.05441082 | F6: 16259.166 | G6: =F6/$F$14 -> 0.036669466
A7: 5 | B7: DLIB | C7: CURL KEEP MAGIC | D7: 18400 | E7: =D7/$D$14 -> 0.042671515 | F7: 9108 | G7: =F7/$F$14 -> 0.020541367
A8: 6 | B8: DLCE | C8: MAKE KEEP PRIMER COOL | D8: 7800 | E8: =D8/$D$14 -> 0.018089012 | F8: 5148 | G8: =F8/$F$14 -> 0.011610338
A9: 7 | B9: DLCH | C9: MAKE KEEP MIST EX + SAKURA CHERRY | D9: 6700 | E9: =D9/$D$14 -> 0.015537997 | F9: 4422 | G9: =F9/$F$14 -> 0.0099729825
A10: 8 | B10: DLCC | C10: MAKE KEEP MIST EX + COOL | D10: 6456 | E10: =D10/$D$14 -> 0.014972136 | F10: 4260.96 | G10: =F10/$F$14 -> 0.0096097873
A11: 9 | B11: YNRE001 | C11: VISEE ESSENCE LIP PLUMPER SP001 | D11: 6357 | E11: =D11/$D$14 -> 0.014742545 | F11: 4545.255 | G11: =F11/$F$14 -> 0.010250961
A12: 10 | B12: MUCF | C12: ONE BY KOSE PORE CLEAR SCRUB WASH | D12: 5698 | E12: =D12/$D$14 -> 0.013214255 | F12: 5641.02 | G12: =F12/$F$14 -> 0.012722251
A13: 11 | B13: 11位以下 | D13: =D14-SUM(D3:D12) -> 119184 | E13: =D13/$D$14 -> 0.2764001 | F13: =F14-SUM(F3:F12) -> 154503.73 | G13: =F13/$F$14 -> 0.34845386
A14: TTL | C14: 合計 | D14: 431201 | E14: =D14/$D$14 -> 1 | F14: 443397.95 | G14: =F14/$F$14 -> 1

Sheet 月別実績
A2: 単位：千円 | B2: 2024 | H2: 2025 | O2: 合計
B3: 7月 | C3: 8月 | D3: 9月 | E3: 10月 | F3: 11月 | G3: 12月 | H3: 1月 | I3: 2月 | J3: 3月 | K3: 4月 | L3: 5月 | M3: 6月 | N3: 7月
A4: UNQ売上 TTL | B4: 6619.635 | C4: 5543.895 | D4: 5423.895 | E4: 12794.087 | F4: 15671.343 | G4: 7639.98 | H4: 30890.61 | I4: 23512.5 | J4: 17188.097 | K4: 28318.053 | L4: 68893.673 | M4: 29626.972 | N4: 50492.853 | O4: =SUM(B4:N4) -> 302615.59
A5: WeChat売上 | B5: 2958.89 | C5: 3926.4 | D5: 2963.305 | E5: 5776.537 | F5: 10656.443 | G5: 7364.98 | H5: 30890.606 | I5: 23512.5 | J5: 17188.097 | K5: 28318.053 | L5: 66469.658 | M5: 21138.327 | N5: 50492.853 | O5: 292863.28
A6: その他 | B6: =B4-B5 -> 3660.745 | C6: =C4-C5 -> 1617.495 | D6: =D4-D5 -> 2460.59 | E6: =E4-E5 -> 7017.55 | F6: =F4-F5 -> 5014.9 | G6: =G4-G5 -> 275 | H6: =H4-H5 -> 0.004 | I6: =I4-I5 -> 0 | ... O6: =O4-O5 -> 9752.309
A7: WeChat構成比 | B7: =B5/B4 -> 0.44698688 | C7: =C5/C4 -> 0.70823852 | D7: =D5/D4 -> 0.54634262 | E7: =E5/E4 -> 0.45150053 | F7: =F5/F4 -> 0.67999552 | G7: =G5/G4 -> 0.96400514 | H7: =H5/H4 -> 0.99999987 | I7: =I5/I4 -> 1 | ... O7: =O5/O4 -> 0.96777328

Sheet top10
A1: 1月 | G1: 累計
A2: No. | B2: 商品符号 | C2: 商品名称 | D2: 合計 | G2: No. | H2: 商品符号 | I2: 商品名称 | J2: 合計
D3: 数量 | E3: 金額 | J3: 数量 | K3: 金額
A4: 1 | B4: DLCK | C4: MAKE KEEP MIST EX + FF | D4: 28800 | E4: 20592000 | G4: 1 | H4: DLCK | I4: MAKE KEEP MIST EX + FF | J4: 28800 | K4: 20592000
A5: 2 | B5: DLEA | C5: MAKE KEEP MIST EX + | D5: 20808 | E5: 14877720 | G5: 2 | H5: DLEA | I5: MAKE KEEP MIST EX + | J5: 20808 | K5: 14877720
A6: 3 | B6: DLIB | C6: CURL KEEP MAGIC | D6: 6960 | E6: 3445200 | G6: 3 | H6: DLIB | I6: CURL KEEP MAGIC | J6: 6960 | K6: 3445200
A7: 4 | B7: MUCI | C7: ONE BY KOSE PORE CLEAR OIL（Refill） | D7: 6000 | E7: 4950000 | G7: 4 | H7: MUCI | I7: ONE BY KOSE PORE CLEAR OIL（Refill） | J7: 6000 | K7: 4950000
A8: 5 | B8: MUCF | C8: ONE BY KOSE PORE CLEAR SCRUB WASH | D8: 5500 | E8: 5445000 | G8: 5 | H8: MUCF | I8: ONE BY KOSE PORE CLEAR SCRUB WASH | J8: 5500 | K8: 5445000
A9: 6 | B9: MUSC | C9: ONE BY KOSE SERUM SHIELD | D9: 1680 | E9: 4989600 | G9: 6 | H9: MUSC | I9: ONE BY KOSE SERUM SHIELD | J9: 1680 | K9: 4989600
A10: 7 | B10: MUCH | C10: ONE BY KOSE PORE CLEAR OIL | D10: 1606 | E10: 1589940 | G10: 7 | H10: MUCH | I10: ONE BY KOSE PORE CLEAR OIL | J10: 1606 | K10: 1589940
A11: 8 | B11: MUXD | C11: ONE BY KOSE SERUM VEIL DEEP REPAIR | D11: 572 | E11: 2831400 | G11: 8 | H11: MUXD | I11: ONE BY KOSE SERUM VEIL DEEP REPAIR | J11: 572 | K11: 2831400
A12: 9 | B12: MTSW | C12: SEKKISEI BRIGHTENING ESSENCE LOTION | D12: 480 | E12: 1293600 | G12: 9 | H12: MTSW | I12: SEKKISEI BRIGHTENING ESSENCE LOTION | J12: 480 | K12: 1293600
A13: 10 | B13: DXPO000 | C13: FASIO PORE SMOOTH PRIMER 00 | D13: 220 | E13: 108900 | G13: 10 | H13: DXPO000 | I13: FASIO PORE SMOOTH PRIMER 00 | J13: 220 | K13: 108900
A15: ２月 | G15: 累計
A16: No. | B16: 商品符号 | C16: 商品名称 | D16: 合計 | G16: No. | H16: 商品符号 | I16: 商品名称 | J16: 合計
D17: 数量 | E17: 金額 | J17: 数量 | K17: 金額
A18: 1 | B18: MUCF | C18: ONE BY KOSE PORE CLEAR SCRUB WASH | D18: 14008 | E18: 13867920 | G18: 1 | H18: DLEA | I18: MAKE KEEP MIST EX + | J18: 29808 | K18: 21312720
A19: 2 | B19: DLEA | C19: MAKE KEEP MIST EX + | D19: 9000 | E19: 6435000 | G19: 2 | H19: DLCK | I19: MAKE KEEP MIST EX + FF | J19: 28800 | K19: 20592000
A20: 3 | B20: MUSC | C20: ONE BY KOSE SERUM SHIELD | D20: 5000 | E20: 14850000 | G20: 3 | H20: MUCF | I20: ONE BY KOSE PORE CLEAR SCRUB WASH | J20: 19508 | K20: 19312920
A21: 4 | B21: MTSW | C21: SEKKISEI BRIGHTENING ESSENCE LOTION | D21: 1590 | E21: 4285050 | G21: 4 | H21: DLIB | I21: CURL KEEP MAGIC | J21: 7960 | K21: 3940200
A22: 5 | B22: MTSX | C22: SEKKISEI BRIGHTENING EMULSION | D22: 1010 | E22: 1888700 | G22: 5 | H22: MUSC | I22: ONE BY KOSE SERUM SHIELD | J22: 6680 | K22: 19839600
A23: 6 | B23: DLIB | C23: CURL KEEP MAGIC | D23: 1000 | E23: 495000 | G23: 6 | H23: MUCI | I23: ONE BY KOSE PORE CLEAR OIL（Refill） | J23: 6000 | K23: 4950000
A24: 7 | B24: MUCH | C24: ONE BY KOSE PORE CLEAR OIL | D24: 986 | E24: 976140 | G24: 7 | H24: MUCH | I24: ONE BY KOSE PORE CLEAR OIL | J24: 2592 | K24: 2566080
A25: 8 | B25: MUZU | C25: ONE BY KOSE DEEP HYDRATOR | D25: 620 | E25: 988900 | G25: 8 | H25: MTSW | I25: SEKKISEI BRIGHTENING ESSENCE LOTION | J25: 2070 | K25: 5578650
A26: 9 | B26: YNGC001 | C26: VISEE COLOR DUO TRICK CONCEALER 01 | D26: 610 | E26: 369050 | G26: 9 | H26: MTSX | I26: SEKKISEI BRIGHTENING EMULSION | J26: 1130 | K26: 2113100
A27: 10 | B27: DLFP | C27: MAKE KEEP POWDER ＥＸ | D27: 606 | E27: 419958 | G27: 10 | H27: MUXD | I27: ONE BY KOSE SERUM VEIL DEEP REPAIR | J27: 1012 | K27: 5009400
A29: 3月 | G29: 累計
A30: No. | B30: 商品符号 | C30: 商品名称 | D30: 合計 | G30: No. | H30: 商品符号 | I30: 商品名称 | J30: 合計
D31: 数量 | E31: 金額 | J31: 数量 | K31: 金額
A32: 1 | B32: DLCK | C32: MAKE KEEP MIST EX + FF | D32: 9360 | E32: 6692400 | G32: 1 | H32: DLCK | I32: MAKE KEEP MIST EX + FF | J32: 38160 | K32: 27284400
A33: 2 | B33: DLEA | C33: MAKE KEEP MIST EX + | D33: 7500 | E33: 5362500 | G33: 2 | H33: DLEA | I33: MAKE KEEP MIST EX + | J33: 37308 | K33: 26675220
A34: 3 | B34: MUCI | C34: ONE BY KOSE PORE CLEAR OIL（Refill） | D34: 5000 | E34: 4125000 | G34: 3 | H34: MUCF | I34: ONE BY KOSE PORE CLEAR SCRUB WASH | J34: 19508 | K34: 19312920
A35: 4 | B35: MUSC | C35: ONE BY KOSE SERUM SHIELD | D35: 4172 | E35: 12390840 | G35: 4 | H35: MUCI | I35: ONE BY KOSE PORE CLEAR OIL（Refill） | J35: 11000 | K35: 9075000
A36: 5 | B36: MTSW | C36: SEKKISEI BRIGHTENING ESSENCE LOTION | D36: 2144 | E36: 5778080 | G36: 5 | H36: MUSC | I36: ONE BY KOSE SERUM SHIELD | J36: 10852 | K36: 32230440
A37: 6 | B37: MTSX | C37: SEKKISEI BRIGHTENING EMULSION | D37: 1440 | E37: 2692800 | G37: 6 | H37: DLIB | I37: CURL KEEP MAGIC | J37: 9010 | K37: 4459950
A38: 7 | B38: MTSC | C38: SEKKISEI BRIGHTENING ESSENCE LOTION | D38: 1173 | E38: 2451570 | G38: 7 | H38: MTSW | I38: SEKKISEI BRIGHTENING ESSENCE LOTION | J38: 4214 | K38: 11356730
A39: 8 | B39: DLFP | C39: MAKE KEEP POWDER ＥＸ | D39: 1128 | E39: 781704 | G39: 8 | H39: MUCH | I39: ONE BY KOSE PORE CLEAR OIL | J39: 2884 | K39: 2855160
A40: 9 | B40: DLIB | C40: CURL KEEP MAGIC | D40: 1050 | E40: 519750 | G40: 9 | H40: MTSX | I40: SEKKISEI BRIGHTENING EMULSION | J40: 2570 | K40: 4805900
A41: 10 | B41: MUXD | C41: ONE BY KOSE SERUM VEIL DEEP REPAIR | D41: 744 | E41: 3682800 | G41: 10 | H41: MUXD | I41: ONE BY KOSE SERUM VEIL DEEP REPAIR | J41: 1756 | K41: 8692200
A43: 4月 | G43: 累計
...

Sheet Sheet5
A1: No. | B1: JANコード | C1: 商品符号 | D1: ブランド | E1: 商品名称 | F1: 2407 | G1: 2408 | H1: 2409 | I1: 2410 | J1: 2411 | K1: 2412 | L1: 2501 | M1: 2502 | N1: 2503 | O1: 2504 | P1: 2505 | Q1: 2506 | R1: 2507 | S1: 合計
F2: 金額 | G2: 金額 | H2: 金額 | I2: 金額 | J2: 金額 | K2: 金額 | L2: 金額 | M2: 金額 | N2: 金額 | O2: 金額 | P2: 金額 | Q2: 金額 | R2: 金額 | S2: 金額
A3: 1 | B3: 4971710576306 | C3: DLEA | D3: MAKE KEEP | E3: MAKE KEEP MIST EX + | G3: 85800 | H3: 26400 | I3: 93720 | J3: 209880 | L3: 1333200 | M3: 2360820 | N3: 5488560 | O3: 8102160 | P3: 13332660 | Q3: 9139680 | R3: 20606520 | S3: =F3+G3+H3+I3+J3+K3+L3+M3+N3+ O3+P3+Q3+R3 -> 60779400
A4: 2 | B4: 4971710565065 | C4: MUSC | D4: ONE BY KOSE | E4: ONE BY KOSE SERUM SHIELD | F4: 110000 | G4: 453750 | H4: 82500 | I4: 522500 | J4: 2483250 | K4: 3080000 | L4: 9190500 | M4: 7312250 | N4: 2546500 | O4: 6083000 | P4: 16464250 | Q4: 3080000 | R4: 7144500 | S4: =F4+G4+H4+I4+J4+K4+L4+M4+N4+ O4+P4+Q4+R4 -> 58553000
A5: 3 | B5: 4971710574852 | C5: MUCI | D5: ONE BY KOSE | E5: ONE BY KOSE PORE CLEAR OIL（Refill） | G5: 49500 | I5: 37125 | J5: 264000 | K5: 561000 | L5: 503250 | M5: 740850 | N5: 394350 | O5: 2103750 | P5: 3836250 | Q5: 297000 | R5: 3387450 | S5: =F5+G5+H5+I5+J5+K5+L5+M5+N5+ O5+P5+Q5+R5 -> 12174525
A6: 4 | B6: 4971710511505 | C6: DLIB | D6: CURL KEEP | E6: CURL KEEP MAGIC | G6: 4950 | H6: 14850 | J6: 178200 | L6: 1386000 | M6: 1485000 | O6: 990000 | P6: 24750 | R6: 1757250 | S6: =F6+G6+H6+I6+J6+K6+L6+M6+N6+ O6+P6+Q6+R6 -> 5841000
A7: 5 | B7: 4971710598711 | C7: DLFP | D7: MAKE KEEP | E7: MAKE KEEP OIL BLOCK POWDER PAPER | Q7: 798336 | R7: 5345802 | S7: =F7+G7+H7+I7+J7+K7+L7+M7+N7+ O7+P7+Q7+R7 -> 6144138
A8: 6 | B8: 4971710590500 | C8: DLCH | D8: MAKE KEEP | E8: MAKE KEEP MIST EX + SAKURA CHERRY | O8: 2376000 | P8: 1980000 | R8: 66000 | S8: =F8+G8+H8+I8+J8+K8+L8+M8+N8+ O8+P8+Q8+R8 -> 4422000
A9: 7 | B9: 4971710579291 | C9: DLCC | D9: MAKE KEEP | E9: MAKE KEEP MIST EX + COOL | H9: 0 | I9: 0 | P9: 3769920 | Q9: 491040 | S9: =F9+G9+H9+I9+J9+K9+L9+M9+N9+ O9+P9+Q9+R9 -> 4260960
A10: 8 | B10: 4971710551006 | C10: YNRE001 | D10: VISEE | E10: VISEE ESSENCE LIP PLUMPER SP001 | F10: 1079650 | G10: 38610 | H10: 17160 | I10: 47190 | J10: 579150 | K10: 64350 | L10: 926640 | M10: 475475 | N10: 602030 | O10: 25740 | P10: 370370 | Q10: 51480 | R10: 253110 | S10: =F10+G10+H10+I10+J10+K10+L10+M10+N10+ O10+P10+Q10+R10 -> 4530955
A11: 9 | B11: 4971710580044 | C11: DLCE | D11: MAKE KEEP | E11: MAKE KEEP PRIMER COOL | G11: 9900 | K11: 0 | P11: 39600 | Q11: 818400 | R11: 2640000 | S11: =F11+G11+H11+I11+J11+K11+L11+M11+N11+ O11+P11+Q11+R11 -> 3507900
A12: 10 | B12: 4971710539189 | C12: YNCF | D12: VISEE | E12: VISEE RED TRICK EYE CONCEALER | F12: 441650 | G12: 180895 | H12: 14520 | I12: 7260 | J12: 235950 | K12: 142175 | L12: 804045 | M12: 273460 | N12: 182710 | O12: 14520 | P12: 485210 | Q12: 32065 | S12: =F12+G12+H12+I12+J12+K12+L12+M12+N12+ O12+P12+Q12+R12 -> 2814460
A13: 11 | B13: 4971710571837 | C13: YNRE300 | D13: VISEE | E13: VISEE ESSENCE LIP PLUMPER BE300 | F13: 364650 | G13: 24310 | H13: 17160 | I13: 329615 | J13: 193050 | K13: 135850 | L13: 657800 | M13: 619905 | N13: 530530 | O13: 17160 | Q13: 35750 | R13: 8580 | S13: =F13+G13+H13+I13+J13+K13+L13+M13+N13+ O13+P13+Q13+R13 -> 2934360
A14: 12 | B14: 4971710590524 | C14: DLCJ | D14: MAKE KEEP | E14: MAKE KEEP POWDER SAKURA CHERRY | O14: 234960 | P14: 1782000 | R14: 462000 | S14: =F14+G14+H14+I14+J14+K14+L14+M14+N14+ O14+P14+Q14+R14 -> 2478960
A15: 13 | B15: 4971710561395 | C15: MUCH | D15: ONE BY KOSE | E15: ONE BY KOSE PORE CLEAR OIL | F15: 19800 | G15: 297000 | H15: 39600 | I15: 118800 | J15: 49500 | K15: 59400 | L15: 390060 | M15: 314820 | N15: 247500 | O15: 669240 | Q15: 129690 | S15: =F15+G15+H15+I15+J15+K15+L15+M15+N15+ O15+P15+Q15+R15 -> 2335410
A16: 14 | B16: 4971710576573 | C16: DLEB | D16: MAKE KEEP | E16: MAKE KEEP MIST EX +＜35mL＞ | G16: 165000 | H16: 13200 | J16: 31680 | K16: 4400 | L16: 388080 | M16: 51040 | N16: 4840 | O16: 220880 | P16: 12320 | Q16: 73920 | R16: 66880 | S16: =F16+G16+H16+I16+J16+K16+L16+M16+N16+ O16+P16+Q16+R16 -> 1032240
A17: 15 | B17: 4971710595543 | C17: YNXX006 | D17: VISEE | E17: VISEE W MOOD EYES BL-6 | M17: 415800 | N17: 308000 | O17: 377300 | P17: 281050 | Q17: 275660 | R17: 69300 | S17: =F17+G17+H17+I17+J17+K17+L17+M17+N17+ O17+P17+Q17+R17 -> 1727110
A18: 16 | B18: 4971710595789 | C18: MUCF | D18: ONE BY KOSE | E18: ONE BY KOSE PORE CLEAR SCRUB WASH | P18: 740520 | R18: 1138500 | S18: =F18+G18+H18+I18+J18+K18+L18+M18+N18+ O18+P18+Q18+R18 -> 1879020
A19: 17 | B19: 4971710556766 | C19: DLEP | D19: MAKE KEEP | E19: MAKE KEEP POWDER | G19: 221100 | H19: 75900 | I19: 21120 | J19: 377520 | K19: 79200 | L19: 270600 | M19: 91080 | N19: 11880 | O19: 79200 | S19: =F19+G19+H19+I19+J19+K19+L19+M19+N19+ O19+P19+Q19+R19 -> 1227600
A20: 18 | B20: 4971710577341 | C20: MUXA | D20: ONE BY KOSE | E20: ONE BY KOSE SERUM VEIL DEEP REPAIR | H20: 27500 | I20: 13750 | J20: 82500 | L20: 1067000 | M20: 574750 | N20: 544500 | O20: 220000 | P20: 2128500 | Q20: 148500 | R20: 121000 | S20: =F20+G20+H20+I20+J20+K20+L20+M20+N20+ O20+P20+Q20+R20 -> 4928000
A21: 19 | B21: 4971710546071 | C21: =VLOOKUP(B21,[2]OBK!$E:$F,2,0) -> MUZU | D21: ONE BY KOSE | E21: ONE BY KOSE DEEP HYDRATOR | G21: 63800 | I21: 79750 | J21: 47850 | K21: 162690 | L21: 778360 | M21: 236060 | N21: 245630 | O21: 194590 | P21: 957000 | Q21: 47850 | R21: 9570 | S21: =F21+G21+H21+I21+J21+K21+L21+M21+N21+ O21+P21+Q21+R21 -> 2823150
A22: 20 | B22: 4971710580396 | C22: MUXD | D22: ONE BY KOSE | E22: ONE BY KOSE SERUM VEIL DEEP REPAIR | G22: 91300 | H22: 45650 | I22: 159775 | J22: 136950 | L22: 1460800 | M22: 1168640 | N22: 1415150 | O22: 547800 | P22: 2424015 | Q22: 365200 | R22: 27390 | S22: =F22+G22+H22+I22+J22+K22+L22+M22+N22+ O22+P22+Q22+R22 -> 7842670
A23: 21 | B23: 4971710471991 | C23: YNYK005 | D23: VISEE | E23: VISEE GEMMY RICH EYES BL-5 | I23: 460680 | J23: 539880 | K23: 0 | S23: =F23+G23+H23+I23+J23+K23+L23+M23+N23+ O23+P23+Q23+R23 -> 1000560
A24: 22 | B24: 4971710576641 | C24: MUPE | D24: ONE BY KOSE | E24: ONE BY KOSE CLEAR PEEL SERUM | F24: 36300 | G24: 81675 | H24: 72600 | I24: 45375 | J24: 181500 | K24: 87120 | L24: 235950 | M24: 123420 | N24: 134310 | O24: 245025 | P24: 1150710 | Q24: 145200 | R24: 3630 | S24: =F24+G24+H24+I24+J24+K24+L24+M24+N24+ O24+P24+Q24+R24 -> 2542815
A25: 23 | B25: 4971710557787 | C25: DXPO000 | D25: FASIO | E25: FASIO PORE SMOOTH PRIMER 00 | G25: 14850 | H25: 14850 | I25: 9900 | J25: 42570 | K25: 49500 | L25: 110880 | M25: 2970 | N25: 74250 | O25: 139590 | P25: 74250 | Q25: 30690 | R25: 111870 | S25: =F25+G25+H25+I25+J25+K25+L25+M25+N25+ O25+P25+Q25+R25 -> 676170
A26: 24 | B26: 4971710580372 | C26: MUXC | D26: ONE BY KOSE | E26: ONE BY KOSE SERUM VEIL DEEP REPAIR | H26: 26400 | I26: 13200 | J26: 26400 | L26: 844800 | M26: 359040 | N26: 179520 | O26: 132000 | Q26: 1657920 | R26: 179520 | S26: =F26+G26+H26+I26+J26+K26+L26+M26+N26+ O26+P26+Q26+R26 -> 3418800
A27: 25 | B27: 4971710576634 | C27: MUPD | D27: ONE BY KOSE | E27: ONE BY KOSE CLEAR PEEL SERUM | F27: 57750 | G27: 115500 | H27: 279125 | I27: 21175 | J27: 96250 | K27: 9625 | L27: 375375 | M27: 157850 | N27: 11550 | O27: 134750 | P27: 1149225 | Q27: 34650 | R27: 30800 | S27: =F27+G27+H27+I27+J27+K27+L27+M27+N27+ O27+P27+Q27+R27 -> 2473625
A28: 26 | B28: 4971710592955 | C28: YNGC001 | D28: VISEE | E28: VISEE COLOR DUO TRICK CONCEALER 01 | L28: 39325 | M28: 196625 | N28: 23595 | O28: 206305 | P28: 19360 | R28: 263780 | S28: =F28+G28+H28+I28+J28+K28+L28+M28+N28+ O28+P28+Q28+R28 -> 748990
A29: 27 | B29: 4971710549812 | C29: MSYN | D29: ONE BY KOSE | E29: ONE BY KOSE MELANOSHOT W | F29: 75900 | H29: 189750 | I29: 113850 | J29: 75900 | K29: 478170 | L29: 455400 | M29: 409860 | N29: 527505 | O29: 645150 | P29: 595815 | Q29: 394680 | R29: 721050 | S29: =F29+G29+H29+I29+J29+K29+L29+M29+N29+ O29+P29+Q29+R29 -> 4683030
A30: 28 | B30: 4971710568899 | C30: MUWI | D30: ONE BY KOSE | E30: ONE BY KOSE WRINKLE DOUBLE REPAIR | F30: 29700 | G30: 14850 | H30: 14850 | I30: 7425 | J30: 170775 | L30: 44550 | M30: 124740 | N30: 166320 | O30: 68310 | P30: 929610 | Q30: 89100 | R30: 2970 | S30: =F30+G30+H30+I30+J30+K30+L30+M30+N30+ O30+P30+Q30+R30 -> 1663200
A31: 29 | B31: 4971710549782 | C31: MSYJ | D31: ONE BY KOSE | E31: ONE BY KOSE MELANOSHOT W | F31: 87450 | G31: 174900 | H31: 72875 | I31: 87450 | J31: 122430 | K31: 227370 | L31: 670450 | M31: 145750 | N31: 343970 | O31: 291500 | P31: 174900 | Q31: 256520 | R31: 574255 | S31: =F31+G31+H31+I31+J31+K31+L31+M31+N31+ O31+P31+Q31+R31 -> 3229820
A32: 30 | B32: 4971710524055 | C32: YNBX | D32: VISEE | E32: VISEE EYEBROW ENHANCER | I32: 60500 | J32: 9075 | K32: 72600 | L32: 176055 | M32: 73810 | N32: 151250 | O32: 3630 | P32: 24200 | Q32: 60500 | R32: 24200 | S32: =F32+G32+H32+I32+J32+K32+L32+M32+N32+ O32+P32+Q32+R32 -> 655820
A33: 31 | B33: 4971710549805 | C33: MSYK | D33: ONE BY KOSE | E33: ONE BY KOSE MELANOSHOT W | G33: 192500 | H33: 55000 | I33: 68750 | J33: 68750 | K33: 198000 | L33: 871750 | M33: 203500 | N33: 192500 | O33: 82500 | P33: 855250 | Q33: 16500 | R33: 129250 | S33: =F33+G33+H33+I33+J33+K33+L33+M33+N33+ O33+P33+Q33+R33 -> 2934250
A34: 32 | B34: 4971710522839 | C34: DLID | D34: CURL KEEP | E34: CURL KEEP MAGIC ESSENCE REMOVER | G34: 15400 | J34: 95040 | L34: 52800 | N34: 70400 | O34: 88000 | R34: 132000 | S34: =F34+G34+H34+I34+J34+K34+L34+M34+N34+ O34+P34+Q34+R34 -> 453640
A35: 33 | B35: 4971710557718 | C35: DXJC002 | D35: FASIO | E35: FASIO AIRY STAY BB TINT UV 02 | F35: 6600 | G35: 23100 | H35: 23100 | I35: 3300 | J35: 39600 | K35: 3300 | L35: 93720 | M35: 101640 | N35: 15840 | O35: 113520 | P35: 73920 | R35: 155760 | S35: =F35+G35+H35+I35+J35+K35+L35+M35+N35+ O35+P35+Q35+R35 -> 653400
A36: 34 | B36: 4971710556865 | C36: YNST300 | D36: VISEE | E36: VISEE SHADE TRICK BR300 | F36: 70400 | G36: 30800 | H36: 18480 | I36: 44000 | J36: 58960 | L36: 151360 | M36: 200640 | N36: 52800 | O36: 59840 | P36: 63360 | Q36: 13200 | R36: 95040 | S36: =F36+G36+H36+I36+J36+K36+L36+M36+N36+ O36+P36+Q36+R36 -> 858880
A37: 35 | B37: 4971710580600 | C37: =VLOOKUP(B37,[3]SEK!$E:$F,2,0) -> MTSW | D37: SEK BRIGHTENING | E37: SEKKISEI BRIGHTENING ESSENCE LOTION | P37: 1706100 | R37: 780670 | S37: =F37+G37+H37+I37+J37+K37+L37+M37+N37+ O37+P37+Q37+R37 -> 2486770
A38: 36 | B38: 4971710556827 | C38: YNFB001 | D38: VISEE | E38: VISEE GLOW BALM FOUNDATION 01 | H38: 94050 | I38: 128700 | J38: 59400 | K38: 74250 | L38: 64350 | M38: 198990 | N38: 227700 | O38: 29700 | P38: 61380 | Q38: 8910 | R38: 3960 | S38: =F38+G38+H38+I38+J38+K38+L38+M38+N38+ O38+P38+Q38+R38 -> 951390
A39: 37 | B39: 4971710295252 | C39: =VLOOKUP(B39,[2]OBK!$E:$F,2,0) -> MUZP | D39: ONE BY KOSE | E39: ONE BY KOSE THE WATER MATE | G39: 34650 | I39: 17325 | J39: 173250 | K39: 265650 | L39: 138600 | M39: 106260 | N39: 71610 | O39: 99330 | P39: 184800 | S39: =F39+G39+H39+I39+J39+K39+L39+M39+N39+ O39+P39+Q39+R39 -> 1091475
A40: 38 | B40: 4971710595529 | C40: YNXX004 | D40: VISEE | E40: VISEE W MOOD EYES OR-4 | M40: 22330 | N40: 104720 | O40: 133980 | P40: 127050 | Q40: 186340 | R40: 149380 | S40: =F40+G40+H40+I40+J40+K40+L40+M40+N40+ O40+P40+Q40+R40 -> 723800
...

Sheet グラフ作成用
A1: No. | B1: JANコード | C1: 商品符号 | D1: 商品名称 | E1: 45658 | F1: 45690 | G1: 45722 | H1: 45754 | I1: 45786 | J1: 45818 | K1: 45848 | L1: 45880 | M1: 45912
A2: 合計 | D2: 合計 | E2: 30890.606 | F2: 20628.74 | G2: 17188.097 | H2: 28318.053 | I2: 66469.658 | J2: 21138.327 | K2: 50492.853 | L2: 39510.954 | M2: 165876.9
A3: 1 | B3: 4971710576306 | C3: DLEA | D3: MAKE KEEP MIST EX + | E3: 1333.2 | F3: 2360.82 | G3: 5488.56 | H3: 8102.16 | I3: 13332.66 | J3: 9139.68 | K3: 20606.52 | L3: 6600 | M3: 42472.32
A4: 2 | B4: 4971710565065 | C4: MUSC | D4: ONE BY KOSE SERUM SHIELD | E4: 9190.5 | F4: 7312.25 | G4: 2546.5 | H4: 6083 | I4: 16464.25 | J4: 3080 | K4: 7144.5 | L4: 4675 | M4: 45254

Sheet 価格設定
K1: 単位：元
A2: No. | B2: 商品符号 | C2: 商品名称 | D2: 日本定価 （円） | E2: 中国KOSE | G2: Tmall旗艦店 | I2: Douyin旗艦店 | K2: WeChat
E3: 定価 | F3: 最低 | G3: 定価 | H3: 最低 | I3: 定価 | J3: 最低 | K3: 最高 | L3: 最低
A4: 1 | B4: DLEA | C4: MAKE KEEP MIST EX + | D4: 1200 | E4: 89 | F4: 55 | G4: 89 | H4: 69 | I4: 89 | J4: 69 | K4: 82 | L4: 69
A5: 2 | B5: MUSC | C5: ONE BY KOSE SERUM SHIELD | D5: 5000 | E5: 280 | F5: Online未導入 | G5: 279 | H5: 199 | I5: 279 | J5: 199 | K5: 259 | L5: 239
